Workbook

Sheet 0. ГИРА
A1: Кадастр | B1: 1006 | C1: Месяц | D1: 45962 | E1: 45992 | F1: Потребл. | G1: 45962 | H1: 46023 | I1: Потребл. | J1: 45992 | K1: 46054 | L1: Потребл. | M1: 46023 | N1: 46082 | O1: Потребл. | P1: 46054 | Q1: 46113 | R1: Потребл. | S1: 46082 | T1: 46143 | U1: Потребл. | V1: 46113 | W1: 46174 | X1: Потребл. | Y1: 46143 | Z1: 46204 | AA1: Потребл. | AB1: 46174 | AC1: 46235 | AD1: Потребл. | AE1: 46204 | AF1: 46266 | AG1: Потребл. | AH1: 46235 | AI1: 46296 | AJ1: Потребл. | AK1: 46266 | AL1: 46327 | AM1: Потребл. | AN1: 46296 | AO1: 46357 | AP1: Потребл. | AQ1: 46327 | AR1: 46388 | AS1: Потребл. | AT1: 46357 | AU1: 46419 | AV1: Потребл. | AW1: 46388 | AX1: 46447 | AY1: Потребл. | AZ1: 46419 | BA1: 46478 | BB1: Потребл. | BC1: 46447 | BD1: 46508 | BE1: Потребл. | BF1: 46478 | BG1: 46539 | BH1: Потребл. | BI1: 46508 | BJ1: 46569 | BK1: Потребл. | BL1: 46539 | BM1: 46600 | BN1: Потребл. | BO1: 46569 | BP1: 46631 | BQ1: Потребл. | BR1: 46600 | BS1: 46661 | BT1: Потребл. | BU1: 46631 | BV1: 46692 | BW1: Потребл. | BX1: 46661 | BY1: 46722 | BZ1: Потребл. | CA1: 46692
A2: Потребитель | B2: ГИРА | D2: знач. | E2: знач. | F2: знач. | G2: руб. | H2: знач. | I2: знач. | J2: руб. | K2: знач. | L2: знач. | M2: руб. | N2: знач. | O2: знач. | P2: руб. | Q2: знач. | R2: знач. | S2: руб. | T2: знач. | U2: знач. | V2: руб. | W2: знач. | X2: знач. | Y2: руб. | Z2: знач. | AA2: знач. | AB2: руб. | AC2: знач. | AD2: знач. | AE2: руб. | AF2: знач. | AG2: знач. | AH2: руб. | AI2: знач. | AJ2: знач. | AK2: руб. | AL2: знач. | AM2: знач. | AN2: руб. | AO2: знач. | AP2: знач. | AQ2: руб. | AR2: знач. | AS2: знач. | AT2: руб. | AU2: знач. | AV2: знач. | AW2: руб. | AX2: знач. | AY2: знач. | AZ2: руб. | BA2: знач. | BB2: знач. | BC2: руб. | BD2: знач. | BE2: знач. | BF2: руб. | BG2: знач. | BH2: знач. | BI2: руб. | BJ2: знач. | BK2: знач. | BL2: руб. | BM2: знач. | BN2: знач. | BO2: руб. | BP2: знач. | BQ2: знач. | BR2: руб. | BS2: знач. | BT2: знач. | BU2: руб. | BV2: знач. | BW2: знач. | BX2: руб. | BY2: знач. | BZ2: знач. | CA2: руб.
A3: Площадь | B3: 487.45 | C3: Электричество | D3: 115000 | E3: 120000 | F3: 222222 | G3: 10000 | H3: 222222 | I3: =H3-E3 | J3: 20000 | K3: 350 | L3: =K3-H3 | M3: 10000 | N3: 245 | O3: =N3-K3 | P3: 21 | R3: =Q3-N3 | U3: =T3-Q3 | X3: =W3-T3 | AA3: =Z3-W3 | AD3: =AC3-Z3 | AG3: =AF3-AC3 | AJ3: =AI3-AF3 | AM3: =AL3-AI3 | AP3: =AO3-AL3 | AS3: =AR3-AO3 | AV3: =AU3-AR3 | AY3: =AX3-AU3 | BB3: =BA3-AX3 | BE3: =BD3-BA3 | BH3: =BG3-BD3 | BK3: =BJ3-BG3 | BN3: =BM3-BJ3 | BQ3: =BP3-BM3 | BT3: =BS3-BP3 | BW3: =BV3-BS3 | BZ3: =BY3-BV3
A4: ИНН | C4: Электричество тариф | G4: =G3/F3 | J4: =J3/I3 | M4: =M3/L3 | P4: =P3/O3 | S4: =S3/R3 | V4: =V3/U3 | Y4: =Y3/X3 | AB4: =AB3/AA3 | AE4: =AE3/AD3 | AH4: =AH3/AG3 | AK4: =AK3/AJ3 | AN4: =AN3/AM3 | AQ4: =AQ3/AP3 | AT4: =AT3/AS3 | AW4: =AW3/AV3 | AZ4: =AZ3/AY3 | BC4: =BC3/BB3 | BF4: =BF3/BE3 | BI4: =BI3/BH3 | BL4: =BL3/BK3 | BO4: =BO3/BN3 | BR4: =BR3/BQ3 | BU4: =BU3/BT3 | BX4: =BX3/BW3 | CA4: =CA3/BZ3
A5: Кол-во помещ | B5: 7 | C5: Водоканал холодная вода | D5: 115000 | E5: 120000 | F5: 222222 | G5: 15000 | H5: 222222 | I5: =H5-E5 | J5: 15000 | K5: 17912 | L5: =K5-H5 | M5: 212 | O5: =N5-K5 | R5: =Q5-N5 | U5: =T5-Q5 | X5: =W5-T5 | AA5: =Z5-W5 | AD5: =AC5-Z5 | AG5: =AF5-AC5 | AJ5: =AI5-AF5 | AM5: =AL5-AI5 | AP5: =AO5-AL5 | AS5: =AR5-AO5 | AV5: =AU5-AR5 | AY5: =AX5-AU5 | BB5: =BA5-AX5 | BE5: =BD5-BA5 | BH5: =BG5-BD5 | BK5: =BJ5-BG5 | BN5: =BM5-BJ5 | BQ5: =BP5-BM5 | BT5: =BS5-BP5 | BW5: =BV5-BS5 | BZ5: =BY5-BV5
C6: Водоканал холодная Тариф | G6: =G5/F5 | J6: =J5/I5 | M6: =M5/L5 | P6: 21 | S6: 30 | V6: =V5/U5 | Y6: =Y5/X5 | AB6: =AB5/AA5 | AE6: =AE5/AD5 | AH6: =AH5/AG5 | AK6: =AK5/AJ5 | AN6: =AN5/AM5 | AQ6: =AQ5/AP5 | AT6: =AT5/AS5 | AW6: =AW5/AV5 | AZ6: =AZ5/AY5 | BC6: =BC5/BB5 | BF6: =BF5/BE5 | BI6: =BI5/BH5 | BL6: =BL5/BK5 | BO6: =BO5/BN5 | BR6: =BR5/BQ5 | BU6: =BU5/BT5 | BX6: =BX5/BW5 | CA6: =CA5/BZ5
C7: Водоканал горячая вода | D7: 115000 | E7: 120000 | F7: 222222 | G7: 20000 | H7: 222222 | I7: =H7-E7 | J7: 20000 | K7: 17912 | L7: =K7-H7 | M7: 12 | O7: =N7-K7 | R7: =Q7-N7 | U7: =T7-Q7 | X7: =W7-T7 | AA7: =Z7-W7 | AD7: =AC7-Z7 | AG7: =AF7-AC7 | AJ7: =AI7-AF7 | AM7: =AL7-AI7 | AP7: =AO7-AL7 | AS7: =AR7-AO7 | AV7: =AU7-AR7 | AY7: =AX7-AU7 | BB7: =BA7-AX7 | BE7: =BD7-BA7 | BH7: =BG7-BD7 | BK7: =BJ7-BG7 | BN7: =BM7-BJ7 | BQ7: =BP7-BM7 | BT7: =BS7-BP7 | BW7: =BV7-BS7 | BZ7: =BY7-BV7
C8: Водоканал горячая Тариф | G8: =G7/F7 | J8: =J7/I7 | M8: =M7/L7 | P8: 21 | S8: 30 | V8: =V7/U7 | Y8: =Y7/X7 | AB8: =AB7/AA7 | AE8: =AE7/AD7 | AH8: =AH7/AG7 | AK8: =AK7/AJ7 | AN8: =AN7/AM7 | AQ8: =AQ7/AP7 | AT8: =AT7/AS7 | AW8: =AW7/AV7 | AZ8: =AZ7/AY7 | BC8: =BC7/BB7 | BF8: =BF7/BE7 | BI8: =BI7/BH7 | BL8: =BL7/BK7 | BO8: =BO7/BN7 | BR8: =BR7/BQ7 | BU8: =BU7/BT7 | BX8: =BX7/BW7 | CA8: =CA7/BZ7
C9: Тепло | F9: 222222 | G9: 12000 | H9: 222222 | I9: 1000 | J9: 12000 | K9: 2000 | M9: 10000
C10: Тепло тариф | G10: =G9/$B3 | J10: =J9/$B3 | M10: =M9/$B3 | P10: =P9/$B3 | S10: =S9/$B3 | V10: =V9/$B3 | Y10: =Y9/$B3 | AB10: =AB9/$B3 | AE10: =AE9/$B3 | AH10: =AH9/$B3 | AK10: =AK9/$B3 | AN10: =AN9/$B3 | AQ10: =AQ9/$B3 | AT10: =AT9/$B3 | AW10: =AW9/$B3 | AZ10: =AZ9/$B3 | BC10: =BC9/$B3 | BF10: =BF9/$B3 | BI10: =BI9/$B3 | BL10: =BL9/$B3 | BO10: =BO9/$B3 | BR10: =BR9/$B3 | BU10: =BU9/$B3 | BX10: =BX9/$B3 | CA10: =CA9/$B3
C11: Экспл. Услуги от УК | G11: 85000 | H11: 222222 | I11: =J11/(Реестр!A20) | J11: 85000 | L11: =M11/(Реестр!$A20) | M11: 50000 | O11: =P11/(Реестр!$A20) | P11: 23 | R11: =S11/(Реестр!$A20) | U11: =V11/(Реестр!$A20) | X11: =Y11/(Реестр!$A20) | AA11: =AB11/(Реестр!$A20) | AD11: =AE11/(Реестр!$A20) | AG11: =AH11/(Реестр!$A20)
C12: Экспл. Услуги от УК тариф | G12: =G11/B5 | J12: =J11/$B3 | M12: =M11/$B3 | P12: =P11/$B3 | S12: =S11/$B3 | V12: =V11/$B3 | Y12: =Y11/$B3 | AB12: =AB11/$B3 | AE12: =AE11/$B3 | AH12: =AH11/$B3 | AK12: =AK11/$B3 | AN12: =AN11/$B3 | AQ12: =AQ11/$B3 | AT12: =AT11/$B3 | AW12: =AW11/$B3 | AZ12: =AZ11/$B3 | BC12: =BC11/$B3 | BF12: =BF11/$B3 | BI12: =BI11/$B3 | BL12: =BL11/$B3 | BO12: =BO11/$B3 | BR12: =BR11/$B3 | BU12: =BU11/$B3 | BX12: =BX11/$B3 | CA12: =CA11/$B3
B14: Физическое снятие показаний
B15: Из счёт фактуры должно подгятиваться
B16: Расчётные ячейки

Sheet К123,40
A1: ИНН | B1: =Реестр!D2 | C1: Месяц | D1: 45962 | E1: 45992 | F1: Потребл. | G1: 45962 | H1: 46023 | I1: Потребл. | J1: 45992 | K1: 46054 | L1: Потребл. | M1: 46023 | N1: 46082 | O1: Потребл. | P1: 46054 | Q1: 46113 | R1: Потребл. | S1: 46082 | T1: 46143 | U1: Потребл. | V1: 46113 | W1: 46174 | X1: Потребл. | Y1: 46143 | Z1: 46204 | AA1: Потребл. | AB1: 46174 | AC1: 46235 | AD1: Потребл. | AE1: 46204 | AF1: 46266 | AG1: Потребл. | AH1: 46235 | AI1: 46296 | AJ1: Потребл. | AK1: 46266 | AL1: 46327 | AM1: Потребл. | AN1: 46296 | AO1: 46357 | AP1: Потребл. | AQ1: 46327 | AR1: 46388 | AS1: Потребл. | AT1: 46357 | AU1: 46419 | AV1: Потребл. | AW1: 46388 | AX1: 46447 | AY1: Потребл. | AZ1: 46419 | BA1: 46478 | BB1: Потребл. | BC1: 46447 | BD1: 46508 | BE1: Потребл. | BF1: 46478 | BG1: 46539 | BH1: Потребл. | BI1: 46508 | BJ1: 46569 | BK1: Потребл. | BL1: 46539 | BM1: 46600 | BN1: Потребл. | BO1: 46569 | BP1: 46631 | BQ1: Потребл. | BR1: 46600 | BS1: 46661 | BT1: Потребл. | BU1: 46631 | BV1: 46692 | BW1: Потребл. | BX1: 46661 | BY1: 46722 | BZ1: Потребл. | CA1: 46692 | CB1: 46753 | CC1: Потребл. | CD1: 46722
A2: Кадастр | B2: =Реестр!B2 | D2: знач. | E2: знач. | F2: знач. | G2: руб. | H2: знач. | I2: знач. | J2: руб. | K2: знач. | L2: знач. | M2: руб. | N2: знач. | O2: знач | P2: руб. | Q2: знач. | R2: знач. | S2: руб. | T2: знач. | U2: знач. | V2: руб. | W2: знач. | X2: знач. | Y2: руб. | Z2: знач. | AA2: знач. | AB2: руб. | AC2: знач. | AD2: знач. | AE2: руб. | AF2: знач. | AG2: знач. | AH2: руб. | AI2: знач. | AJ2: знач. | AK2: руб. | AL2: знач. | AM2: знач. | AN2: руб. | AO2: знач. | AP2: знач. | AQ2: руб. | AR2: знач. | AS2: знач. | AT2: руб. | AU2: знач. | AV2: знач. | AW2: руб. | AX2: знач. | AY2: знач. | AZ2: руб. | BA2: знач. | BB2: знач. | BC2: руб. | BD2: знач. | BE2: знач. | BF2: руб. | BG2: знач. | BH2: знач. | BI2: руб. | BJ2: знач. | BK2: знач. | BL2: руб. | BM2: знач. | BN2: знач. | BO2: руб. | BP2: знач. | BQ2: знач. | BR2: руб. | BS2: знач. | BT2: знач. | BU2: руб. | BV2: знач. | BW2: знач. | BX2: руб. | BY2: знач. | BZ2: знач. | CA2: руб. | CB2: знач. | CC2: знач. | CD2: руб.
A3: Арендатор | B3: =Реестр!F2 | C3: Электричество | F3: =E3-D3 | G3: =F3*G4 | I3: =H3-E3 | J3: =I3*J4 | K3: 333333 | L3: =K3-H3 | M3: =L3*M4 | O3: =N3-K3 | P3: =O3*P4 | R3: =Q3-N3 | S3: =R3*S4 | U3: =T3-Q3 | V3: =U3*V4 | X3: =W3-T3 | Y3: =X3*Y4 | AA3: =Z3-W3 | AB3: =AA3*AB4 | AD3: =AC3-Z3 | AE3: =AD3*AE4 | AG3: =AF3-AC3 | AH3: =AG3*AH4 | AJ3: =AI3-AF3 | AK3: =AJ3*AK4 | AM3: =AL3-AI3 | AN3: =AM3*AN4 | AP3: =AO3-AL3 | AQ3: =AP3*AQ4 | AS3: =AR3-AO3 | AT3: =AS3*AT4 | AV3: =AU3-AR3 | AW3: =AV3*AW4 | AY3: =AX3-AU3 | AZ3: =AY3*AZ4 | BB3: =BA3-AX3 | BC3: =BB3*BC4 | BE3: =BD3-BA3 | BF3: =BE3*BF4 | BH3: =BG3-BD3 | BI3: =BH3*BI4 | BK3: =BJ3-BG3 | BL3: =BK3*BL4 | BN3: =BM3-BJ3 | BO3: =BN3*BO4 | BQ3: =BP3-BM3 | BR3: =BQ3*BR4 | BT3: =BS3-BP3 | BU3: =BT3*BU4 | BW3: =BV3-BS3 | BX3: =BW3*BX4 | BZ3: =BY3-BV3 | CA3: =BZ3*CA4 | CC3: =CB3-BY3 | CD3: =CC3*CD4
A4: Площадь | B4: =Реестр!H2 | C4: Электричество тариф | G4: ='0. ГИРА'!G4 | J4: ='0. ГИРА'!J4 | M4: ='0. ГИРА'!M4 | P4: ='0. ГИРА'!P4 | S4: ='0. ГИРА'!S4 | V4: ='0. ГИРА'!V4 | Y4: ='0. ГИРА'!Y4 | AB4: ='0. ГИРА'!AB4 | AE4: ='0. ГИРА'!AE4 | AH4: ='0. ГИРА'!AH4 | AK4: ='0. ГИРА'!AK4 | AN4: ='0. ГИРА'!AN4 | AQ4: ='0. ГИРА'!AQ4 | AT4: ='0. ГИРА'!AT4 | AW4: ='0. ГИРА'!AW4 | AZ4: ='0. ГИРА'!AZ4 | BC4: ='0. ГИРА'!BC4 | BF4: ='0. ГИРА'!BF4 | BI4: ='0. ГИРА'!BI4 | BL4: ='0. ГИРА'!BL4 | BO4: ='0. ГИРА'!BO4 | BR4: ='0. ГИРА'!BR4 | BU4: ='0. ГИРА'!BU4 | BX4: ='0. ГИРА'!BX4 | CA4: ='0. ГИРА'!CA4 | CD4: ='0. ГИРА'!CD4
C5: Водоканал холодная вода | F5: =E5-D5 | I5: =H5-E5 | K5: 11111 | L5: =K5-H5 | O5: =N5-K5 | R5: =Q5-N5 | U5: =T5-Q5 | X5: =W5-T5 | AA5: =Z5-W5 | AD5: =AC5-Z5 | AG5: =AF5-AC5 | AJ5: =AI5-AF5 | AM5: =AL5-AI5 | AP5: =AO5-AL5 | AS5: =AR5-AO5 | AV5: =AU5-AR5 | AY5: =AX5-AU5 | BB5: =BA5-AX5 | BE5: =BD5-BA5 | BH5: =BG5-BD5 | BK5: =BJ5-BG5 | BN5: =BM5-BJ5 | BQ5: =BP5-BM5 | BT5: =BS5-BP5 | BW5: =BV5-BS5 | BZ5: =BY5-BV5 | CC5: =CB5-BY5
A6: Имя 1 | B6: =Реестр!M2 | C6: Водоканал холодная Тариф | G6: ='0. ГИРА'!G6 | J6: ='0. ГИРА'!J6 | M6: ='0. ГИРА'!M6 | P6: ='0. ГИРА'!P6 | S6: ='0. ГИРА'!S6 | V6: ='0. ГИРА'!V6 | Y6: ='0. ГИРА'!Y6 | AB6: ='0. ГИРА'!AB6 | AE6: ='0. ГИРА'!AE6 | AH6: ='0. ГИРА'!AH6 | AK6: ='0. ГИРА'!AK6 | AN6: ='0. ГИРА'!AN6 | AQ6: ='0. ГИРА'!AQ6 | AT6: ='0. ГИРА'!AT6 | AW6: ='0. ГИРА'!AW6 | AZ6: ='0. ГИРА'!AZ6 | BC6: ='0. ГИРА'!BC6 | BF6: ='0. ГИРА'!BF6 | BI6: ='0. ГИРА'!BI6 | BL6: ='0. ГИРА'!BL6 | BO6: ='0. ГИРА'!BO6 | BR6: ='0. ГИРА'!BR6 | BU6: ='0. ГИРА'!BU6 | BX6: ='0. ГИРА'!BX6 | CA6: ='0. ГИРА'!CA6 | CD6: ='0. ГИРА'!CD6
A7: Контакт 1 | B7: =Реестр!N2 | C7: Водоканал горячая вода | F7: =E7-D7 | G7: =G8*F7 | I7: =H7-E7 | J7: =J8*I7 | K7: 22222 | L7: =K7-H7 | M7: =M8*L7 | O7: =N7-K7 | P7: =P8*O7 | R7: =Q7-N7 | S7: =S8*R7 | U7: =T7-Q7 | V7: =V8*U7 | X7: =W7-T7 | Y7: =Y8*X7 | AA7: =Z7-W7 | AB7: =AB8*AA7 | AD7: =AC7-Z7 | AE7: =AE8*AD7 | AG7: =AF7-AC7 | AH7: =AH8*AG7 | AJ7: =AI7-AF7 | AK7: =AK8*AJ7 | AM7: =AL7-AI7 | AN7: =AN8*AM7 | AP7: =AO7-AL7 | AQ7: =AQ8*AP7 | AS7: =AR7-AO7 | AT7: =AT8*AS7 | AV7: =AU7-AR7 | AW7: =AW8*AV7 | AY7: =AX7-AU7 | AZ7: =AZ8*AY7 | BB7: =BA7-AX7 | BC7: =BC8*BB7 | BE7: =BD7-BA7 | BF7: =BF8*BE7 | BH7: =BG7-BD7 | BI7: =BI8*BH7 | BK7: =BJ7-BG7 | BL7: =BL8*BK7 | BN7: =BM7-BJ7 | BO7: =BO8*BN7 | BQ7: =BP7-BM7 | BR7: =BR8*BQ7 | BT7: =BS7-BP7 | BU7: =BU8*BT7 | BW7: =BV7-BS7 | BX7: =BX8*BW7 | BZ7: =BY7-BV7 | CA7: =CA8*BZ7 | CC7: =CB7-BY7 | CD7: =CD8*CC7
A8: Имя 2 | B8: =Реестр!O2 | C8: Водоканал горячая Тариф | G8: ='0. ГИРА'!G8 | J8: ='0. ГИРА'!J8 | M8: ='0. ГИРА'!M8 | P8: ='0. ГИРА'!P8 | S8: ='0. ГИРА'!S8 | V8: ='0. ГИРА'!V8 | Y8: ='0. ГИРА'!Y8 | AB8: ='0. ГИРА'!AB8 | AE8: ='0. ГИРА'!AE8 | AH8: ='0. ГИРА'!AH8 | AK8: ='0. ГИРА'!AK8 | AN8: ='0. ГИРА'!AN8 | AQ8: ='0. ГИРА'!AQ8 | AT8: ='0. ГИРА'!AT8 | AW8: ='0. ГИРА'!AW8 | AZ8: ='0. ГИРА'!AZ8 | BC8: ='0. ГИРА'!BC8 | BF8: ='0. ГИРА'!BF8 | BI8: ='0. ГИРА'!BI8 | BL8: ='0. ГИРА'!BL8 | BO8: ='0. ГИРА'!BO8 | BR8: ='0. ГИРА'!BR8 | BU8: ='0. ГИРА'!BU8 | BX8: ='0. ГИРА'!BX8 | CA8: ='0. ГИРА'!CA8 | CD8: ='0. ГИРА'!CD8
A9: Контакт 2 | B9: =Реестр!P2 | C9: Тепло | F9: =E9-D9 | G9: =G10*B4 | I9: =H9-E9 | J9: =J10*E3 | L9: =K9-H9 | M9: =M10*H3 | O9: =N9-K9 | P9: =P10*K3 | R9: =Q9-N9 | S9: =S10*N3 | U9: =T9-Q9 | V9: =V10*Q3 | X9: =W9-T9 | Y9: =Y10*T3 | AA9: =Z9-W9 | AB9: =AB10*W3 | AD9: =AC9-Z9 | AE9: =AE10*Z3 | AG9: =AF9-AC9 | AH9: =AH10*AC3 | AJ9: =AI9-AF9 | AK9: =AK10*AF3 | AM9: =AL9-AI9 | AN9: =AN10*AI3 | AP9: =AO9-AL9 | AQ9: =AQ10*AL3 | AS9: =AR9-AO9 | AT9: =AT10*AO3 | AV9: =AU9-AR9 | AW9: =AW10*AR3 | AY9: =AX9-AU9 | AZ9: =AZ10*AU3 | BB9: =BA9-AX9 | BC9: =BC10*AX3 | BE9: =BD9-BA9 | BF9: =BF10*BA3 | BH9: =BG9-BD9 | BI9: =BI10*BD3 | BK9: =BJ9-BG9 | BL9: =BL10*BG3 | BN9: =BM9-BJ9 | BO9: =BO10*BJ3 | BQ9: =BP9-BM9 | BR9: =BR10*BM3 | BT9: =BS9-BP9 | BU9: =BU10*BP3 | BW9: =BV9-BS9 | BX9: =BX10*BS3 | BZ9: =BY9-BV9 | CA9: =CA10*BV3 | CC9: =CB9-BY9 | CD9: =CD10*BY3
C10: Тепло тариф | G10: ='0. ГИРА'!G10 | J10: ='0. ГИРА'!J10 | M10: ='0. ГИРА'!M10 | P10: ='0. ГИРА'!P10 | S10: ='0. ГИРА'!S10 | V10: ='0. ГИРА'!V10 | Y10: ='0. ГИРА'!Y10 | AB10: ='0. ГИРА'!AB10 | AE10: ='0. ГИРА'!AE10 | AH10: ='0. ГИРА'!AH10 | AK10: ='0. ГИРА'!AK10 | AN10: ='0. ГИРА'!AN10 | AQ10: ='0. ГИРА'!AQ10 | AT10: ='0. ГИРА'!AT10 | AW10: ='0. ГИРА'!AW10 | AZ10: ='0. ГИРА'!AZ10 | BC10: ='0. ГИРА'!BC10 | BF10: ='0. ГИРА'!BF10 | BI10: ='0. ГИРА'!BI10 | BL10: ='0. ГИРА'!BL10 | BO10: ='0. ГИРА'!BO10 | BR10: ='0. ГИРА'!BR10 | BU10: ='0. ГИРА'!BU10 | BX10: ='0. ГИРА'!BX10 | CA10: ='0. ГИРА'!CA10 | CD10: ='0. ГИРА'!CD10
A11: Номер счетчика | C11: Экспл. Услуги от УК | F11: =E11-D11 | I11: =H11-E11 | J11: =J12*E3 | L11: =K11-H11 | M11: =M12*H3 | O11: =N11-K11 | P11: =P12*K3 | R11: =Q11-N11 | S11: =S12*N3 | U11: =T11-Q11 | V11: =V12*Q3 | X11: =W11-T11 | Y11: =Y12*T3 | AA11: =Z11-W11 | AB11: =AB12*W3 | AD11: =AC11-Z11 | AE11: =AE12*Z3 | AG11: =AF11-AC11 | AH11: =AH12*AC3 | AJ11: =AI11-AF11 | AK11: =AK12*AF3 | AM11: =AL11-AI11 | AN11: =AN12*AI3 | AP11: =AO11-AL11 | AQ11: =AQ12*AL3 | AS11: =AR11-AO11 | AT11: =AT12*AO3 | AV11: =AU11-AR11 | AW11: =AW12*AR3 | AY11: =AX11-AU11 | AZ11: =AZ12*AU3 | BB11: =BA11-AX11 | BC11: =BC12*AX3 | BE11: =BD11-BA11 | BF11: =BF12*BA3 | BH11: =BG11-BD11 | BI11: =BI12*BD3 | BK11: =BJ11-BG11 | BL11: =BL12*BG3 | BN11: =BM11-BJ11 | BO11: =BO12*BJ3 | BQ11: =BP11-BM11 | BR11: =BR12*BM3 | BT11: =BS11-BP11 | BU11: =BU12*BP3 | BW11: =BV11-BS11 | BX11: =BX12*BS3 | BZ11: =BY11-BV11 | CA11: =CA12*BV3 | CC11: =CB11-BY11 | CD11: =CD12*BY3
C12: Экспл. Услуги от УК тариф | G12: ='0. ГИРА'!G12 | J12: ='0. ГИРА'!J12 | M12: ='0. ГИРА'!M12 | P12: ='0. ГИРА'!P12 | S12: ='0. ГИРА'!S12 | V12: ='0. ГИРА'!V12 | Y12: ='0. ГИРА'!Y12 | AB12: ='0. ГИРА'!AB12 | AE12: ='0. ГИРА'!AE12 | AH12: ='0. ГИРА'!AH12 | AK12: ='0. ГИРА'!AK12 | AN12: ='0. ГИРА'!AN12 | AQ12: ='0. ГИРА'!AQ12 | AT12: ='0. ГИРА'!AT12 | AW12: ='0. ГИРА'!AW12 | AZ12: ='0. ГИРА'!AZ12 | BC12: ='0. ГИРА'!BC12 | BF12: ='0. ГИРА'!BF12 | BI12: ='0. ГИРА'!BI12 | BL12: ='0. ГИРА'!BL12 | BO12: ='0. ГИРА'!BO12 | BR12: ='0. ГИРА'!BR12 | BU12: ='0. ГИРА'!BU12 | BX12: ='0. ГИРА'!BX12 | CA12: ='0. ГИРА'!CA12 | CD12: ='0. ГИРА'!CD12

Sheet К102,60
A1: ИНН | B1: =Реестр!D3 | C1: Месяц | D1: 45962 | E1: 45992 | F1: Потребл. | G1: 45962 | H1: 46023 | I1: Потребл. | J1: 45992 | K1: 46054 | L1: Потребл. | M1: 46023 | N1: 46082 | O1: Потребл. | P1: 46054 | Q1: 46113 | R1: Потребл. | S1: 46082 | T1: 46143 | U1: Потребл. | V1: 46113 | W1: 46174 | X1: Потребл. | Y1: 46143 | Z1: 46204 | AA1: Потребл. | AB1: 46174 | AC1: 46235 | AD1: Потребл. | AE1: 46204 | AF1: 46266 | AG1: Потребл. | AH1: 46235 | AI1: 46296 | AJ1: Потребл. | AK1: 46266 | AL1: 46327 | AM1: Потребл. | AN1: 46296 | AO1: 46357 | AP1: Потребл. | AQ1: 46327 | AR1: 46388 | AS1: Потребл. | AT1: 46357 | AU1: 46419 | AV1: Потребл. | AW1: 46388 | AX1: 46447 | AY1: Потребл. | AZ1: 46419 | BA1: 46478 | BB1: Потребл. | BC1: 46447 | BD1: 46508 | BE1: Потребл. | BF1: 46478 | BG1: 46539 | BH1: Потребл. | BI1: 46508 | BJ1: 46569 | BK1: Потребл. | BL1: 46539 | BM1: 46600 | BN1: Потребл. | BO1: 46569 | BP1: 46631 | BQ1: Потребл. | BR1: 46600 | BS1: 46661 | BT1: Потребл. | BU1: 46631 | BV1: 46692 | BW1: Потребл. | BX1: 46661 | BY1: 46722 | BZ1: Потребл. | CA1: 46692 | CB1: 46753 | CC1: Потребл. | CD1: 46722
A2: Кадастр | B2: =Реестр!B3 | D2: знач. | E2: знач. | F2: знач. | G2: руб. | H2: знач. | I2: знач. | J2: руб. | K2: знач. | L2: знач. | M2: руб. | N2: знач. | O2: знач | P2: руб. | Q2: знач. | R2: знач. | S2: руб. | T2: знач. | U2: знач. | V2: руб. | W2: знач. | X2: знач. | Y2: руб. | Z2: знач. | AA2: знач. | AB2: руб. | AC2: знач. | AD2: знач. | AE2: руб. | AF2: знач. | AG2: знач. | AH2: руб. | AI2: знач. | AJ2: знач. | AK2: руб. | AL2: знач. | AM2: знач. | AN2: руб. | AO2: знач. | AP2: знач. | AQ2: руб. | AR2: знач. | AS2: знач. | AT2: руб. | AU2: знач. | AV2: знач. | AW2: руб. | AX2: знач. | AY2: знач. | AZ2: руб. | BA2: знач. | BB2: знач. | BC2: руб. | BD2: знач. | BE2: знач. | BF2: руб. | BG2: знач. | BH2: знач. | BI2: руб. | BJ2: знач. | BK2: знач. | BL2: руб. | BM2: знач. | BN2: знач. | BO2: руб. | BP2: знач. | BQ2: знач. | BR2: руб. | BS2: знач. | BT2: знач. | BU2: руб. | BV2: знач. | BW2: знач. | BX2: руб. | BY2: знач. | BZ2: знач. | CA2: руб. | CB2: знач. | CC2: знач. | CD2: руб.
A3: Арендатор | B3: =Реестр!F3 | C3: Электричество | F3: =E3-D3 | G3: =F3*G4 | H3: 200000 | I3: =H3-E3 | J3: =I3*J4 | K3: 678766 | L3: =K3-H3 | M3: =L3*M4 | N3: 777777 | O3: =N3-K3 | P3: =O3*P4 | R3: =Q3-N3 | S3: =R3*S4 | U3: =T3-Q3 | V3: =U3*V4 | X3: =W3-T3 | Y3: =X3*Y4 | AA3: =Z3-W3 | AB3: =AA3*AB4 | AD3: =AC3-Z3 | AE3: =AD3*AE4 | AG3: =AF3-AC3 | AH3: =AG3*AH4 | AJ3: =AI3-AF3 | AK3: =AJ3*AK4 | AM3: =AL3-AI3 | AN3: =AM3*AN4 | AP3: =AO3-AL3 | AQ3: =AP3*AQ4 | AS3: =AR3-AO3 | AT3: =AS3*AT4 | AV3: =AU3-AR3 | AW3: =AV3*AW4 | AY3: =AX3-AU3 | AZ3: =AY3*AZ4 | BB3: =BA3-AX3 | BC3: =BB3*BC4 | BE3: =BD3-BA3 | BF3: =BE3*BF4 | BH3: =BG3-BD3 | BI3: =BH3*BI4 | BK3: =BJ3-BG3 | BL3: =BK3*BL4 | BN3: =BM3-BJ3 | BO3: =BN3*BO4 | BQ3: =BP3-BM3 | BR3: =BQ3*BR4 | BT3: =BS3-BP3 | BU3: =BT3*BU4 | BW3: =BV3-BS3 | BX3: =BW3*BX4 | BZ3: =BY3-BV3 | CA3: =BZ3*CA4 | CC3: =CB3-BY3 | CD3: =CC3*CD4
A4: Площадь | B4: =Реестр!H3 | C4: Электричество тариф | G4: ='0. ГИРА'!G4 | J4: ='0. ГИРА'!J4 | M4: ='0. ГИРА'!M4 | P4: ='0. ГИРА'!P4 | S4: ='0. ГИРА'!S4 | V4: ='0. ГИРА'!V4 | Y4: ='0. ГИРА'!Y4 | AB4: ='0. ГИРА'!AB4 | AE4: ='0. ГИРА'!AE4 | AH4: ='0. ГИРА'!AH4 | AK4: ='0. ГИРА'!AK4 | AN4: ='0. ГИРА'!AN4 | AQ4: ='0. ГИРА'!AQ4 | AT4: ='0. ГИРА'!AT4 | AW4: ='0. ГИРА'!AW4 | AZ4: ='0. ГИРА'!AZ4 | BC4: ='0. ГИРА'!BC4 | BF4: ='0. ГИРА'!BF4 | BI4: ='0. ГИРА'!BI4 | BL4: ='0. ГИРА'!BL4 | BO4: ='0. ГИРА'!BO4 | BR4: ='0. ГИРА'!BR4 | BU4: ='0. ГИРА'!BU4 | BX4: ='0. ГИРА'!BX4 | CA4: ='0. ГИРА'!CA4 | CD4: ='0. ГИРА'!CD4
C5: Водоканал холодная вода | F5: =E5-D5 | H5: 20000 | I5: =H5-E5 | J5: =I5*J6 | K5: 11111 | L5: =K5-H5 | M5: =L5*M6 | N5: 77777 | O5: =N5-K5 | R5: =Q5-N5 | U5: =T5-Q5 | X5: =W5-T5 | AA5: =Z5-W5 | AD5: =AC5-Z5 | AG5: =AF5-AC5 | AJ5: =AI5-AF5 | AM5: =AL5-AI5 | AP5: =AO5-AL5 | AS5: =AR5-AO5 | AV5: =AU5-AR5 | AY5: =AX5-AU5 | BB5: =BA5-AX5 | BE5: =BD5-BA5 | BH5: =BG5-BD5 | BK5: =BJ5-BG5 | BN5: =BM5-BJ5 | BQ5: =BP5-BM5 | BT5: =BS5-BP5 | BW5: =BV5-BS5 | BZ5: =BY5-BV5 | CC5: =CB5-BY5
A6: Имя 1 | B6: =Реестр!M3 | C6: Водоканал холодная Тариф | G6: ='0. ГИРА'!G6 | J6: ='0. ГИРА'!J6 | M6: ='0. ГИРА'!M6 | P6: ='0. ГИРА'!P6 | S6: ='0. ГИРА'!S6 | V6: ='0. ГИРА'!V6 | Y6: ='0. ГИРА'!Y6 | AB6: ='0. ГИРА'!AB6 | AE6: ='0. ГИРА'!AE6 | AH6: ='0. ГИРА'!AH6 | AK6: ='0. ГИРА'!AK6 | AN6: ='0. ГИРА'!AN6 | AQ6: ='0. ГИРА'!AQ6 | AT6: ='0. ГИРА'!AT6 | AW6: ='0. ГИРА'!AW6 | AZ6: ='0. ГИРА'!AZ6 | BC6: ='0. ГИРА'!BC6 | BF6: ='0. ГИРА'!BF6 | BI6: ='0. ГИРА'!BI6 | BL6: ='0. ГИРА'!BL6 | BO6: ='0. ГИРА'!BO6 | BR6: ='0. ГИРА'!BR6 | BU6: ='0. ГИРА'!BU6 | BX6: ='0. ГИРА'!BX6 | CA6: ='0. ГИРА'!CA6 | CD6: ='0. ГИРА'!CD6
A7: Контакт 1 | B7: =Реестр!N3 | C7: Водоканал горячая вода | F7: =E7-D7 | G7: =G8*F7 | H7: 20000 | I7: =H7-E7 | J7: =J8*I7 | K7: 67656 | L7: =K7-H7 | M7: =M8*L7 | N7: 77777 | O7: =N7-K7 | P7: =P8*O7 | R7: =Q7-N7 | S7: =S8*R7 | U7: =T7-Q7 | V7: =V8*U7 | X7: =W7-T7 | Y7: =Y8*X7 | AA7: =Z7-W7 | AB7: =AB8*AA7 | AD7: =AC7-Z7 | AE7: =AE8*AD7 | AG7: =AF7-AC7 | AH7: =AH8*AG7 | AJ7: =AI7-AF7 | AK7: =AK8*AJ7 | AM7: =AL7-AI7 | AN7: =AN8*AM7 | AP7: =AO7-AL7 | AQ7: =AQ8*AP7 | AS7: =AR7-AO7 | AT7: =AT8*AS7 | AV7: =AU7-AR7 | AW7: =AW8*AV7 | AY7: =AX7-AU7 | AZ7: =AZ8*AY7 | BB7: =BA7-AX7 | BC7: =BC8*BB7 | BE7: =BD7-BA7 | BF7: =BF8*BE7 | BH7: =BG7-BD7 | BI7: =BI8*BH7 | BK7: =BJ7-BG7 | BL7: =BL8*BK7 | BN7: =BM7-BJ7 | BO7: =BO8*BN7 | BQ7: =BP7-BM7 | BR7: =BR8*BQ7 | BT7: =BS7-BP7 | BU7: =BU8*BT7 | BW7: =BV7-BS7 | BX7: =BX8*BW7 | BZ7: =BY7-BV7 | CA7: =CA8*BZ7 | CC7: =CB7-BY7 | CD7: =CD8*CC7
A8: Имя 2 | B8: =Реестр!O3 | C8: Водоканал горячая Тариф | G8: ='0. ГИРА'!G8 | J8: ='0. ГИРА'!J8 | M8: ='0. ГИРА'!M8 | P8: ='0. ГИРА'!P8 | S8: ='0. ГИРА'!S8 | V8: ='0. ГИРА'!V8 | Y8: ='0. ГИРА'!Y8 | AB8: ='0. ГИРА'!AB8 | AE8: ='0. ГИРА'!AE8 | AH8: ='0. ГИРА'!AH8 | AK8: ='0. ГИРА'!AK8 | AN8: ='0. ГИРА'!AN8 | AQ8: ='0. ГИРА'!AQ8 | AT8: ='0. ГИРА'!AT8 | AW8: ='0. ГИРА'!AW8 | AZ8: ='0. ГИРА'!AZ8 | BC8: ='0. ГИРА'!BC8 | BF8: ='0. ГИРА'!BF8 | BI8: ='0. ГИРА'!BI8 | BL8: ='0. ГИРА'!BL8 | BO8: ='0. ГИРА'!BO8 | BR8: ='0. ГИРА'!BR8 | BU8: ='0. ГИРА'!BU8 | BX8: ='0. ГИРА'!BX8 | CA8: ='0. ГИРА'!CA8 | CD8: ='0. ГИРА'!CD8
A9: Контакт 2 | B9: =Реестр!P3 | C9: Тепло | F9: =E9-D9 | G9: =G10*B3 | I9: =H9-E9 | J9: =J10*E3 | K9: 1234 | L9: =K9-H9 | M9: 12 | N9: 12345 | O9: =N9-K9 | P9: 112 | R9: =Q9-N9 | S9: =S10*N3 | U9: =T9-Q9 | V9: =V10*Q3 | X9: =W9-T9 | Y9: =Y10*T3 | AA9: =Z9-W9 | AB9: =AB10*W3 | AD9: =AC9-Z9 | AE9: =AE10*Z3 | AG9: =AF9-AC9 | AH9: =AH10*AC3 | AJ9: =AI9-AF9 | AK9: =AK10*AF3 | AM9: =AL9-AI9 | AN9: =AN10*AI3 | AP9: =AO9-AL9 | AQ9: =AQ10*AL3 | AS9: =AR9-AO9 | AT9: =AT10*AO3 | AV9: =AU9-AR9 | AW9: =AW10*AR3 | AY9: =AX9-AU9 | AZ9: =AZ10*AU3 | BB9: =BA9-AX9 | BC9: =BC10*AX3 | BE9: =BD9-BA9 | BF9: =BF10*BA3 | BH9: =BG9-BD9 | BI9: =BI10*BD3 | BK9: =BJ9-BG9 | BL9: =BL10*BG3 | BN9: =BM9-BJ9 | BO9: =BO10*BJ3 | BQ9: =BP9-BM9 | BR9: =BR10*BM3 | BT9: =BS9-BP9 | BU9: =BU10*BP3 | BW9: =BV9-BS9 | BX9: =BX10*BS3 | BZ9: =BY9-BV9 | CA9: =CA10*BV3 | CC9: =CB9-BY9 | CD9: =CD10*BY3
C10: Тепло тариф | G10: ='0. ГИРА'!G10 | J10: ='0. ГИРА'!J10 | M10: ='0. ГИРА'!M10 | P10: ='0. ГИРА'!P10 | S10: ='0. ГИРА'!S10 | V10: ='0. ГИРА'!V10 | Y10: ='0. ГИРА'!Y10 | AB10: ='0. ГИРА'!AB10 | AE10: ='0. ГИРА'!AE10 | AH10: ='0. ГИРА'!AH10 | AK10: ='0. ГИРА'!AK10 | AN10: ='0. ГИРА'!AN10 | AQ10: ='0. ГИРА'!AQ10 | AT10: ='0. ГИРА'!AT10 | AW10: ='0. ГИРА'!AW10 | AZ10: ='0. ГИРА'!AZ10 | BC10: ='0. ГИРА'!BC10 | BF10: ='0. ГИРА'!BF10 | BI10: ='0. ГИРА'!BI10 | BL10: ='0. ГИРА'!BL10 | BO10: ='0. ГИРА'!BO10 | BR10: ='0. ГИРА'!BR10 | BU10: ='0. ГИРА'!BU10 | BX10: ='0. ГИРА'!BX10 | CA10: ='0. ГИРА'!CA10 | CD10: ='0. ГИРА'!CD10
A11: Номер счетчика | B11: 43432,34343 | C11: Экспл. Услуги от УК | F11: =E11-D11 | G11: ='0. ГИРА'!G12 | I11: =H11-G11 | J11: ='0. ГИРА'!J12 | L11: =K11-J11 | M11: ='0. ГИРА'!M12 | O11: =N11-M11 | P11: ='0. ГИРА'!P12 | R11: =Q11-P11 | S11: ='0. ГИРА'!S12 | U11: =T11-S11 | V11: ='0. ГИРА'!V12 | X11: =W11-T11 | Y11: =Y12*T3 | AA11: =Z11-W11 | AB11: =AB12*W3 | AD11: =AC11-Z11 | AE11: =AE12*Z3 | AG11: =AF11-AC11 | AH11: =AH12*AC3 | AJ11: =AI11-AF11 | AK11: =AK12*AF3 | AM11: =AL11-AI11 | AN11: =AN12*AI3 | AP11: =AO11-AL11 | AQ11: =AQ12*AL3 | AS11: =AR11-AO11 | AT11: =AT12*AO3 | AV11: =AU11-AR11 | AW11: =AW12*AR3 | AY11: =AX11-AU11 | AZ11: =AZ12*AU3 | BB11: =BA11-AX11 | BC11: =BC12*AX3 | BE11: =BD11-BA11 | BF11: =BF12*BA3 | BH11: =BG11-BD11 | BI11: =BI12*BD3 | BK11: =BJ11-BG11 | BL11: =BL12*BG3 | BN11: =BM11-BJ11 | BO11: =BO12*BJ3 | BQ11: =BP11-BM11 | BR11: =BR12*BM3 | BT11: =BS11-BP11 | BU11: =BU12*BP3 | BW11: =BV11-BS11 | BX11: =BX12*BS3 | BZ11: =BY11-BV11 | CA11: =CA12*BV3 | CC11: =CB11-BY11 | CD11: =CD12*BY3
C12: Экспл. Услуги от УК тариф | G12: ='0. ГИРА'!G12 | J12: ='0. ГИРА'!J12 | M12: ='0. ГИРА'!M12 | P12: ='0. ГИРА'!P12 | S12: ='0. ГИРА'!S12 | V12: ='0. ГИРА'!V12 | Y12: ='0. ГИРА'!Y12 | AB12: ='0. ГИРА'!AB12 | AE12: ='0. ГИРА'!AE12 | AH12: ='0. ГИРА'!AH12 | AK12: ='0. ГИРА'!AK12 | AN12: ='0. ГИРА'!AN12 | AQ12: ='0. ГИРА'!AQ12 | AT12: ='0. ГИРА'!AT12 | AW12: ='0. ГИРА'!AW12 | AZ12: ='0. ГИРА'!AZ12 | BC12: ='0. ГИРА'!BC12 | BF12: ='0. ГИРА'!BF12 | BI12: ='0. ГИРА'!BI12 | BL12: ='0. ГИРА'!BL12 | BO12: ='0. ГИРА'!BO12 | BR12: ='0. ГИРА'!BR12 | BU12: ='0. ГИРА'!BU12 | BX12: ='0. ГИРА'!BX12 | CA12: ='0. ГИРА'!CA12 | CD12: ='0. ГИРА'!CD12

Sheet К45,20
A1: ИНН | B1: =Реестр!D4 | C1: Месяц | D1: 45962 | E1: 45992 | F1: Потребл. | G1: 45962 | H1: 46023 | I1: Потребл. | J1: 45992 | K1: 46054 | L1: Потребл. | M1: 46023 | N1: 46082 | O1: Потребл. | P1: 46054 | Q1: 46113 | R1: Потребл. | S1: 46082 | T1: 46143 | U1: Потребл. | V1: 46113 | W1: 46174 | X1: Потребл. | Y1: 46143 | Z1: 46204 | AA1: Потребл. | AB1: 46174 | AC1: 46235 | AD1: Потребл. | AE1: 46204 | AF1: 46266 | AG1: Потребл. | AH1: 46235 | AI1: 46296 | AJ1: Потребл. | AK1: 46266 | AL1: 46327 | AM1: Потребл. | AN1: 46296 | AO1: 46357 | AP1: Потребл. | AQ1: 46327 | AR1: 46388 | AS1: Потребл. | AT1: 46357 | AU1: 46419 | AV1: Потребл. | AW1: 46388 | AX1: 46447 | AY1: Потребл. | AZ1: 46419 | BA1: 46478 | BB1: Потребл. | BC1: 46447 | BD1: 46508 | BE1: Потребл. | BF1: 46478 | BG1: 46539 | BH1: Потребл. | BI1: 46508 | BJ1: 46569 | BK1: Потребл. | BL1: 46539 | BM1: 46600 | BN1: Потребл. | BO1: 46569 | BP1: 46631 | BQ1: Потребл. | BR1: 46600 | BS1: 46661 | BT1: Потребл. | BU1: 46631 | BV1: 46692 | BW1: Потребл. | BX1: 46661 | BY1: 46722 | BZ1: Потребл. | CA1: 46692 | CB1: 46753 | CC1: Потребл. | CD1: 46722
A2: Кадастр | B2: =Реестр!B4 | D2: знач. | E2: знач. | F2: знач. | G2: руб. | H2: знач. | I2: знач. | J2: руб. | K2: знач. | L2: знач. | M2: руб. | N2: знач. | O2: знач | P2: руб. | Q2: знач. | R2: знач. | S2: руб. | T2: знач. | U2: знач. | V2: руб. | W2: знач. | X2: знач. | Y2: руб. | Z2: знач. | AA2: знач. | AB2: руб. | AC2: знач. | AD2: знач. | AE2: руб. | AF2: знач. | AG2: знач. | AH2: руб. | AI2: знач. | AJ2: знач. | AK2: руб. | AL2: знач. | AM2: знач. | AN2: руб. | AO2: знач. | AP2: знач. | AQ2: руб. | AR2: знач. | AS2: знач. | AT2: руб. | AU2: знач. | AV2: знач. | AW2: руб. | AX2: знач. | AY2: знач. | AZ2: руб. | BA2: знач. | BB2: знач. | BC2: руб. | BD2: знач. | BE2: знач. | BF2: руб. | BG2: знач. | BH2: знач. | BI2: руб. | BJ2: знач. | BK2: знач. | BL2: руб. | BM2: знач. | BN2: знач. | BO2: руб. | BP2: знач. | BQ2: знач. | BR2: руб. | BS2: знач. | BT2: знач. | BU2: руб. | BV2: знач. | BW2: знач. | BX2: руб. | BY2: знач. | BZ2: знач. | CA2: руб. | CB2: знач. | CC2: знач. | CD2: руб.
A3: Арендатор | B3: =Реестр!F4 | C3: Электричество | F3: =E3-D3 | G3: =F3*G4 | I3: =H3-E3 | J3: =I3*J4 | K3: 345678 | L3: =K3-H3 | M3: =L3*M4 | O3: =N3-K3 | P3: =O3*P4 | R3: =Q3-N3 | S3: =R3*S4 | U3: =T3-Q3 | V3: =U3*V4 | X3: =W3-T3 | Y3: =X3*Y4 | AA3: =Z3-W3 | AB3: =AA3*AB4 | AD3: =AC3-Z3 | AE3: =AD3*AE4 | AG3: =AF3-AC3 | AH3: =AG3*AH4 | AJ3: =AI3-AF3 | AK3: =AJ3*AK4 | AM3: =AL3-AI3 | AN3: =AM3*AN4 | AP3: =AO3-AL3 | AQ3: =AP3*AQ4 | AS3: =AR3-AO3 | AT3: =AS3*AT4 | AV3: =AU3-AR3 | AW3: =AV3*AW4 | AY3: =AX3-AU3 | AZ3: =AY3*AZ4 | BB3: =BA3-AX3 | BC3: =BB3*BC4 | BE3: =BD3-BA3 | BF3: =BE3*BF4 | BH3: =BG3-BD3 | BI3: =BH3*BI4 | BK3: =BJ3-BG3 | BL3: =BK3*BL4 | BN3: =BM3-BJ3 | BO3: =BN3*BO4 | BQ3: =BP3-BM3 | BR3: =BQ3*BR4 | BT3: =BS3-BP3 | BU3: =BT3*BU4 | BW3: =BV3-BS3 | BX3: =BW3*BX4 | BZ3: =BY3-BV3 | CA3: =BZ3*CA4 | CC3: =CB3-BY3 | CD3: =CC3*CD4
A4: Площадь | B4: =Реестр!H4 | C4: Электричество тариф | G4: ='0. ГИРА'!G4 | J4: ='0. ГИРА'!J4 | M4: ='0. ГИРА'!M4 | P4: ='0. ГИРА'!P4 | S4: ='0. ГИРА'!S4 | V4: ='0. ГИРА'!V4 | Y4: ='0. ГИРА'!Y4 | AB4: ='0. ГИРА'!AB4 | AE4: ='0. ГИРА'!AE4 | AH4: ='0. ГИРА'!AH4 | AK4: ='0. ГИРА'!AK4 | AN4: ='0. ГИРА'!AN4 | AQ4: ='0. ГИРА'!AQ4 | AT4: ='0. ГИРА'!AT4 | AW4: ='0. ГИРА'!AW4 | AZ4: ='0. ГИРА'!AZ4 | BC4: ='0. ГИРА'!BC4 | BF4: ='0. ГИРА'!BF4 | BI4: ='0. ГИРА'!BI4 | BL4: ='0. ГИРА'!BL4 | BO4: ='0. ГИРА'!BO4 | BR4: ='0. ГИРА'!BR4 | BU4: ='0. ГИРА'!BU4 | BX4: ='0. ГИРА'!BX4 | CA4: ='0. ГИРА'!CA4 | CD4: ='0. ГИРА'!CD4
C5: Водоканал холодная вода | F5: =E5-D5 | I5: =H5-E5 | K5: 579 | L5: =K5-H5 | O5: =N5-K5 | R5: =Q5-N5 | U5: =T5-Q5 | X5: =W5-T5 | AA5: =Z5-W5 | AD5: =AC5-Z5 | AG5: =AF5-AC5 | AJ5: =AI5-AF5 | AM5: =AL5-AI5 | AP5: =AO5-AL5 | AS5: =AR5-AO5 | AV5: =AU5-AR5 | AY5: =AX5-AU5 | BB5: =BA5-AX5 | BE5: =BD5-BA5 | BH5: =BG5-BD5 | BK5: =BJ5-BG5 | BN5: =BM5-BJ5 | BQ5: =BP5-BM5 | BT5: =BS5-BP5 | BW5: =BV5-BS5 | BZ5: =BY5-BV5 | CC5: =CB5-BY5
A6: Имя 1 | B6: =Реестр!M4 | C6: Водоканал холодная Тариф | G6: ='0. ГИРА'!G6 | J6: ='0. ГИРА'!J6 | M6: ='0. ГИРА'!M6 | P6: ='0. ГИРА'!P6 | S6: ='0. ГИРА'!S6 | V6: ='0. ГИРА'!V6 | Y6: ='0. ГИРА'!Y6 | AB6: ='0. ГИРА'!AB6 | AE6: ='0. ГИРА'!AE6 | AH6: ='0. ГИРА'!AH6 | AK6: ='0. ГИРА'!AK6 | AN6: ='0. ГИРА'!AN6 | AQ6: ='0. ГИРА'!AQ6 | AT6: ='0. ГИРА'!AT6 | AW6: ='0. ГИРА'!AW6 | AZ6: ='0. ГИРА'!AZ6 | BC6: ='0. ГИРА'!BC6 | BF6: ='0. ГИРА'!BF6 | BI6: ='0. ГИРА'!BI6 | BL6: ='0. ГИРА'!BL6 | BO6: ='0. ГИРА'!BO6 | BR6: ='0. ГИРА'!BR6 | BU6: ='0. ГИРА'!BU6 | BX6: ='0. ГИРА'!BX6 | CA6: ='0. ГИРА'!CA6 | CD6: ='0. ГИРА'!CD6
A7: Контакт 1 | B7: =Реестр!N4 | C7: Водоканал горячая вода | F7: =E7-D7 | G7: =G8*F7 | I7: =H7-E7 | J7: =J8*I7 | L7: =K7-H7 | M7: =M8*L7 | O7: =N7-K7 | P7: =P8*O7 | R7: =Q7-N7 | S7: =S8*R7 | U7: =T7-Q7 | V7: =V8*U7 | X7: =W7-T7 | Y7: =Y8*X7 | AA7: =Z7-W7 | AB7: =AB8*AA7 | AD7: =AC7-Z7 | AE7: =AE8*AD7 | AG7: =AF7-AC7 | AH7: =AH8*AG7 | AJ7: =AI7-AF7 | AK7: =AK8*AJ7 | AM7: =AL7-AI7 | AN7: =AN8*AM7 | AP7: =AO7-AL7 | AQ7: =AQ8*AP7 | AS7: =AR7-AO7 | AT7: =AT8*AS7 | AV7: =AU7-AR7 | AW7: =AW8*AV7 | AY7: =AX7-AU7 | AZ7: =AZ8*AY7 | BB7: =BA7-AX7 | BC7: =BC8*BB7 | BE7: =BD7-BA7 | BF7: =BF8*BE7 | BH7: =BG7-BD7 | BI7: =BI8*BH7 | BK7: =BJ7-BG7 | BL7: =BL8*BK7 | BN7: =BM7-BJ7 | BO7: =BO8*BN7 | BQ7: =BP7-BM7 | BR7: =BR8*BQ7 | BT7: =BS7-BP7 | BU7: =BU8*BT7 | BW7: =BV7-BS7 | BX7: =BX8*BW7 | BZ7: =BY7-BV7 | CA7: =CA8*BZ7 | CC7: =CB7-BY7 | CD7: =CD8*CC7
A8: Имя 2 | B8: =Реестр!O4 | C8: Водоканал горячая Тариф | G8: ='0. ГИРА'!G8 | J8: ='0. ГИРА'!J8 | M8: ='0. ГИРА'!M8 | P8: ='0. ГИРА'!P8 | S8: ='0. ГИРА'!S8 | V8: ='0. ГИРА'!V8 | Y8: ='0. ГИРА'!Y8 | AB8: ='0. ГИРА'!AB8 | AE8: ='0. ГИРА'!AE8 | AH8: ='0. ГИРА'!AH8 | AK8: ='0. ГИРА'!AK8 | AN8: ='0. ГИРА'!AN8 | AQ8: ='0. ГИРА'!AQ8 | AT8: ='0. ГИРА'!AT8 | AW8: ='0. ГИРА'!AW8 | AZ8: ='0. ГИРА'!AZ8 | BC8: ='0. ГИРА'!BC8 | BF8: ='0. ГИРА'!BF8 | BI8: ='0. ГИРА'!BI8 | BL8: ='0. ГИРА'!BL8 | BO8: ='0. ГИРА'!BO8 | BR8: ='0. ГИРА'!BR8 | BU8: ='0. ГИРА'!BU8 | BX8: ='0. ГИРА'!BX8 | CA8: ='0. ГИРА'!CA8 | CD8: ='0. ГИРА'!CD8
A9: Контакт 2 | B9: =Реестр!P4 | C9: Тепло | F9: =E9-D9 | G9: =G10*B3 | I9: =H9-E9 | J9: =J10*E3 | K9: 1234 | L9: =K9-H9 | M9: 12 | N9: 143134 | O9: =N9-K9 | P9: 4132 | R9: =Q9-N9 | S9: =S10*N3 | U9: =T9-Q9 | V9: =V10*Q3 | X9: =W9-T9 | Y9: =Y10*T3 | AA9: =Z9-W9 | AB9: =AB10*W3 | AD9: =AC9-Z9 | AE9: =AE10*Z3 | AG9: =AF9-AC9 | AH9: =AH10*AC3 | AJ9: =AI9-AF9 | AK9: =AK10*AF3 | AM9: =AL9-AI9 | AN9: =AN10*AI3 | AP9: =AO9-AL9 | AQ9: =AQ10*AL3 | AS9: =AR9-AO9 | AT9: =AT10*AO3 | AV9: =AU9-AR9 | AW9: =AW10*AR3 | AY9: =AX9-AU9 | AZ9: =AZ10*AU3 | BB9: =BA9-AX9 | BC9: =BC10*AX3 | BE9: =BD9-BA9 | BF9: =BF10*BA3 | BH9: =BG9-BD9 | BI9: =BI10*BD3 | BK9: =BJ9-BG9 | BL9: =BL10*BG3 | BN9: =BM9-BJ9 | BO9: =BO10*BJ3 | BQ9: =BP9-BM9 | BR9: =BR10*BM3 | BT9: =BS9-BP9 | BU9: =BU10*BP3 | BW9: =BV9-BS9 | BX9: =BX10*BS3 | BZ9: =BY9-BV9 | CA9: =CA10*BV3 | CC9: =CB9-BY9 | CD9: =CD10*BY3
C10: Тепло тариф | G10: ='0. ГИРА'!G10 | J10: ='0. ГИРА'!J10 | M10: ='0. ГИРА'!M10 | P10: ='0. ГИРА'!P10 | S10: ='0. ГИРА'!S10 | V10: ='0. ГИРА'!V10 | Y10: ='0. ГИРА'!Y10 | AB10: ='0. ГИРА'!AB10 | AE10: ='0. ГИРА'!AE10 | AH10: ='0. ГИРА'!AH10 | AK10: ='0. ГИРА'!AK10 | AN10: ='0. ГИРА'!AN10 | AQ10: ='0. ГИРА'!AQ10 | AT10: ='0. ГИРА'!AT10 | AW10: ='0. ГИРА'!AW10 | AZ10: ='0. ГИРА'!AZ10 | BC10: ='0. ГИРА'!BC10 | BF10: ='0. ГИРА'!BF10 | BI10: ='0. ГИРА'!BI10 | BL10: ='0. ГИРА'!BL10 | BO10: ='0. ГИРА'!BO10 | BR10: ='0. ГИРА'!BR10 | BU10: ='0. ГИРА'!BU10 | BX10: ='0. ГИРА'!BX10 | CA10: ='0. ГИРА'!CA10 | CD10: ='0. ГИРА'!CD10
A11: Номер счетчика | B11: 677890 | C11: Экспл. Услуги от УК | F11: =E11-D11 | I11: =H11-E11 | J11: =J12*E3 | L11: =K11-H11 | M11: =M12*H3 | O11: =N11-K11 | P11: =P12*K3 | R11: =Q11-N11 | S11: =S12*N3 | U11: =T11-Q11 | V11: =V12*Q3 | X11: =W11-T11 | Y11: =Y12*T3 | AA11: =Z11-W11 | AB11: =AB12*W3 | AD11: =AC11-Z11 | AE11: =AE12*Z3 | AG11: =AF11-AC11 | AH11: =AH12*AC3 | AJ11: =AI11-AF11 | AK11: =AK12*AF3 | AM11: =AL11-AI11 | AN11: =AN12*AI3 | AP11: =AO11-AL11 | AQ11: =AQ12*AL3 | AS11: =AR11-AO11 | AT11: =AT12*AO3 | AV11: =AU11-AR11 | AW11: =AW12*AR3 | AY11: =AX11-AU11 | AZ11: =AZ12*AU3 | BB11: =BA11-AX11 | BC11: =BC12*AX3 | BE11: =BD11-BA11 | BF11: =BF12*BA3 | BH11: =BG11-BD11 | BI11: =BI12*BD3 | BK11: =BJ11-BG11 | BL11: =BL12*BG3 | BN11: =BM11-BJ11 | BO11: =BO12*BJ3 | BQ11: =BP11-BM11 | BR11: =BR12*BM3 | BT11: =BS11-BP11 | BU11: =BU12*BP3 | BW11: =BV11-BS11 | BX11: =BX12*BS3 | BZ11: =BY11-BV11 | CA11: =CA12*BV3 | CC11: =CB11-BY11 | CD11: =CD12*BY3
C12: Экспл. Услуги от УК тариф | G12: ='0. ГИРА'!G12 | J12: ='0. ГИРА'!J12 | M12: ='0. ГИРА'!M12 | P12: ='0. ГИРА'!P12 | S12: ='0. ГИРА'!S12 | V12: ='0. ГИРА'!V12 | Y12: ='0. ГИРА'!Y12 | AB12: ='0. ГИРА'!AB12 | AE12: ='0. ГИРА'!AE12 | AH12: ='0. ГИРА'!AH12 | AK12: ='0. ГИРА'!AK12 | AN12: ='0. ГИРА'!AN12 | AQ12: ='0. ГИРА'!AQ12 | AT12: ='0. ГИРА'!AT12 | AW12: ='0. ГИРА'!AW12 | AZ12: ='0. ГИРА'!AZ12 | BC12: ='0. ГИРА'!BC12 | BF12: ='0. ГИРА'!BF12 | BI12: ='0. ГИРА'!BI12 | BL12: ='0. ГИРА'!BL12 | BO12: ='0. ГИРА'!BO12 | BR12: ='0. ГИРА'!BR12 | BU12: ='0. ГИРА'!BU12 | BX12: ='0. ГИРА'!BX12 | CA12: ='0. ГИРА'!CA12 | CD12: ='0. ГИРА'!CD12

Sheet К43,30
A1: ИНН | B1: =Реестр!D5 | C1: Месяц | D1: 45962 | E1: 45992 | F1: Потребл. | G1: 45962 | H1: 46023 | I1: Потребл. | J1: 45992 | K1: 46054 | L1: Потребл. | M1: 46023 | N1: 46082 | O1: Потребл. | P1: 46054 | Q1: 46113 | R1: Потребл. | S1: 46082 | T1: 46143 | U1: Потребл. | V1: 46113 | W1: 46174 | X1: Потребл. | Y1: 46143 | Z1: 46204 | AA1: Потребл. | AB1: 46174 | AC1: 46235 | AD1: Потребл. | AE1: 46204 | AF1: 46266 | AG1: Потребл. | AH1: 46235 | AI1: 46296 | AJ1: Потребл. | AK1: 46266 | AL1: 46327 | AM1: Потребл. | AN1: 46296 | AO1: 46357 | AP1: Потребл. | AQ1: 46327 | AR1: 46388 | AS1: Потребл. | AT1: 46357 | AU1: 46419 | AV1: Потребл. | AW1: 46388 | AX1: 46447 | AY1: Потребл. | AZ1: 46419 | BA1: 46478 | BB1: Потребл. | BC1: 46447 | BD1: 46508 | BE1: Потребл. | BF1: 46478 | BG1: 46539 | BH1: Потребл. | BI1: 46508 | BJ1: 46569 | BK1: Потребл. | BL1: 46539 | BM1: 46600 | BN1: Потребл. | BO1: 46569 | BP1: 46631 | BQ1: Потребл. | BR1: 46600 | BS1: 46661 | BT1: Потребл. | BU1: 46631 | BV1: 46692 | BW1: Потребл. | BX1: 46661 | BY1: 46722 | BZ1: Потребл. | CA1: 46692 | CB1: 46753 | CC1: Потребл. | CD1: 46722
A2: Кадастр | B2: =Реестр!B5 | D2: знач. | E2: знач. | F2: знач. | G2: руб. | H2: знач. | I2: знач. | J2: руб. | K2: знач. | L2: знач. | M2: руб. | N2: знач. | O2: знач | P2: руб. | Q2: знач. | R2: знач. | S2: руб. | T2: знач. | U2: знач. | V2: руб. | W2: знач. | X2: знач. | Y2: руб. | Z2: знач. | AA2: знач. | AB2: руб. | AC2: знач. | AD2: знач. | AE2: руб. | AF2: знач. | AG2: знач. | AH2: руб. | AI2: знач. | AJ2: знач. | AK2: руб. | AL2: знач. | AM2: знач. | AN2: руб. | AO2: знач. | AP2: знач. | AQ2: руб. | AR2: знач. | AS2: знач. | AT2: руб. | AU2: знач. | AV2: знач. | AW2: руб. | AX2: знач. | AY2: знач. | AZ2: руб. | BA2: знач. | BB2: знач. | BC2: руб. | BD2: знач. | BE2: знач. | BF2: руб. | BG2: знач. | BH2: знач. | BI2: руб. | BJ2: знач. | BK2: знач. | BL2: руб. | BM2: знач. | BN2: знач. | BO2: руб. | BP2: знач. | BQ2: знач. | BR2: руб. | BS2: знач. | BT2: знач. | BU2: руб. | BV2: знач. | BW2: знач. | BX2: руб. | BY2: знач. | BZ2: знач. | CA2: руб. | CB2: знач. | CC2: знач. | CD2: руб.
A3: Арендатор | B3: =Реестр!F5 | C3: Электричество | F3: =E3-D3 | G3: =F3*G4 | I3: =H3-E3 | J3: =I3*J4 | L3: =K3-H3 | M3: =L3*M4 | O3: =N3-K3 | P3: =O3*P4 | R3: =Q3-N3 | S3: =R3*S4 | U3: =T3-Q3 | V3: =U3*V4 | X3: =W3-T3 | Y3: =X3*Y4 | AA3: =Z3-W3 | AB3: =AA3*AB4 | AD3: =AC3-Z3 | AE3: =AD3*AE4 | AG3: =AF3-AC3 | AH3: =AG3*AH4 | AJ3: =AI3-AF3 | AK3: =AJ3*AK4 | AM3: =AL3-AI3 | AN3: =AM3*AN4 | AP3: =AO3-AL3 | AQ3: =AP3*AQ4 | AS3: =AR3-AO3 | AT3: =AS3*AT4 | AV3: =AU3-AR3 | AW3: =AV3*AW4 | AY3: =AX3-AU3 | AZ3: =AY3*AZ4 | BB3: =BA3-AX3 | BC3: =BB3*BC4 | BE3: =BD3-BA3 | BF3: =BE3*BF4 | BH3: =BG3-BD3 | BI3: =BH3*BI4 | BK3: =BJ3-BG3 | BL3: =BK3*BL4 | BN3: =BM3-BJ3 | BO3: =BN3*BO4 | BQ3: =BP3-BM3 | BR3: =BQ3*BR4 | BT3: =BS3-BP3 | BU3: =BT3*BU4 | BW3: =BV3-BS3 | BX3: =BW3*BX4 | BZ3: =BY3-BV3 | CA3: =BZ3*CA4 | CC3: =CB3-BY3 | CD3: =CC3*CD4
A4: Площадь | B4: =Реестр!H5 | C4: Электричество тариф | G4: ='0. ГИРА'!G4 | J4: ='0. ГИРА'!J4 | M4: ='0. ГИРА'!M4 | P4: ='0. ГИРА'!P4 | S4: ='0. ГИРА'!S4 | V4: ='0. ГИРА'!V4 | Y4: ='0. ГИРА'!Y4 | AB4: ='0. ГИРА'!AB4 | AE4: ='0. ГИРА'!AE4 | AH4: ='0. ГИРА'!AH4 | AK4: ='0. ГИРА'!AK4 | AN4: ='0. ГИРА'!AN4 | AQ4: ='0. ГИРА'!AQ4 | AT4: ='0. ГИРА'!AT4 | AW4: ='0. ГИРА'!AW4 | AZ4: ='0. ГИРА'!AZ4 | BC4: ='0. ГИРА'!BC4 | BF4: ='0. ГИРА'!BF4 | BI4: ='0. ГИРА'!BI4 | BL4: ='0. ГИРА'!BL4 | BO4: ='0. ГИРА'!BO4 | BR4: ='0. ГИРА'!BR4 | BU4: ='0. ГИРА'!BU4 | BX4: ='0. ГИРА'!BX4 | CA4: ='0. ГИРА'!CA4 | CD4: ='0. ГИРА'!CD4
C5: Водоканал холодная вода | F5: =E5-D5 | I5: =H5-E5 | L5: =K5-H5 | O5: =N5-K5 | R5: =Q5-N5 | U5: =T5-Q5 | X5: =W5-T5 | AA5: =Z5-W5 | AD5: =AC5-Z5 | AG5: =AF5-AC5 | AJ5: =AI5-AF5 | AM5: =AL5-AI5 | AP5: =AO5-AL5 | AS5: =AR5-AO5 | AV5: =AU5-AR5 | AY5: =AX5-AU5 | BB5: =BA5-AX5 | BE5: =BD5-BA5 | BH5: =BG5-BD5 | BK5: =BJ5-BG5 | BN5: =BM5-BJ5 | BQ5: =BP5-BM5 | BT5: =BS5-BP5 | BW5: =BV5-BS5 | BZ5: =BY5-BV5 | CC5: =CB5-BY5
A6: Имя 1 | B6: =Реестр!M5 | C6: Водоканал холодная Тариф | G6: ='0. ГИРА'!G6 | J6: ='0. ГИРА'!J6 | M6: ='0. ГИРА'!M6 | P6: ='0. ГИРА'!P6 | S6: ='0. ГИРА'!S6 | V6: ='0. ГИРА'!V6 | Y6: ='0. ГИРА'!Y6 | AB6: ='0. ГИРА'!AB6 | AE6: ='0. ГИРА'!AE6 | AH6: ='0. ГИРА'!AH6 | AK6: ='0. ГИРА'!AK6 | AN6: ='0. ГИРА'!AN6 | AQ6: ='0. ГИРА'!AQ6 | AT6: ='0. ГИРА'!AT6 | AW6: ='0. ГИРА'!AW6 | AZ6: ='0. ГИРА'!AZ6 | BC6: ='0. ГИРА'!BC6 | BF6: ='0. ГИРА'!BF6 | BI6: ='0. ГИРА'!BI6 | BL6: ='0. ГИРА'!BL6 | BO6: ='0. ГИРА'!BO6 | BR6: ='0. ГИРА'!BR6 | BU6: ='0. ГИРА'!BU6 | BX6: ='0. ГИРА'!BX6 | CA6: ='0. ГИРА'!CA6 | CD6: ='0. ГИРА'!CD6
A7: Контакт 1 | B7: =Реестр!N5 | C7: Водоканал горячая вода | F7: =E7-D7 | G7: =G8*F7 | I7: =H7-E7 | J7: =J8*I7 | L7: =K7-H7 | M7: =M8*L7 | O7: =N7-K7 | P7: =P8*O7 | R7: =Q7-N7 | S7: =S8*R7 | U7: =T7-Q7 | V7: =V8*U7 | X7: =W7-T7 | Y7: =Y8*X7 | AA7: =Z7-W7 | AB7: =AB8*AA7 | AD7: =AC7-Z7 | AE7: =AE8*AD7 | AG7: =AF7-AC7 | AH7: =AH8*AG7 | AJ7: =AI7-AF7 | AK7: =AK8*AJ7 | AM7: =AL7-AI7 | AN7: =AN8*AM7 | AP7: =AO7-AL7 | AQ7: =AQ8*AP7 | AS7: =AR7-AO7 | AT7: =AT8*AS7 | AV7: =AU7-AR7 | AW7: =AW8*AV7 | AY7: =AX7-AU7 | AZ7: =AZ8*AY7 | BB7: =BA7-AX7 | BC7: =BC8*BB7 | BE7: =BD7-BA7 | BF7: =BF8*BE7 | BH7: =BG7-BD7 | BI7: =BI8*BH7 | BK7: =BJ7-BG7 | BL7: =BL8*BK7 | BN7: =BM7-BJ7 | BO7: =BO8*BN7 | BQ7: =BP7-BM7 | BR7: =BR8*BQ7 | BT7: =BS7-BP7 | BU7: =BU8*BT7 | BW7: =BV7-BS7 | BX7: =BX8*BW7 | BZ7: =BY7-BV7 | CA7: =CA8*BZ7 | CC7: =CB7-BY7 | CD7: =CD8*CC7
A8: Имя 2 | B8: =Реестр!O5 | C8: Водоканал горячая Тариф | G8: ='0. ГИРА'!G8 | J8: ='0. ГИРА'!J8 | M8: ='0. ГИРА'!M8 | P8: ='0. ГИРА'!P8 | S8: ='0. ГИРА'!S8 | V8: ='0. ГИРА'!V8 | Y8: ='0. ГИРА'!Y8 | AB8: ='0. ГИРА'!AB8 | AE8: ='0. ГИРА'!AE8 | AH8: ='0. ГИРА'!AH8 | AK8: ='0. ГИРА'!AK8 | AN8: ='0. ГИРА'!AN8 | AQ8: ='0. ГИРА'!AQ8 | AT8: ='0. ГИРА'!AT8 | AW8: ='0. ГИРА'!AW8 | AZ8: ='0. ГИРА'!AZ8 | BC8: ='0. ГИРА'!BC8 | BF8: ='0. ГИРА'!BF8 | BI8: ='0. ГИРА'!BI8 | BL8: ='0. ГИРА'!BL8 | BO8: ='0. ГИРА'!BO8 | BR8: ='0. ГИРА'!BR8 | BU8: ='0. ГИРА'!BU8 | BX8: ='0. ГИРА'!BX8 | CA8: ='0. ГИРА'!CA8 | CD8: ='0. ГИРА'!CD8
A9: Контакт 2 | B9: =Реестр!P5 | C9: Тепло | F9: =E9-D9 | G9: =G10*B3 | I9: =H9-E9 | J9: =J10*E3 | K9: 1234 | L9: =K9-H9 | M9: 12 | O9: =N9-K9 | P9: =P10*K3 | R9: =Q9-N9 | S9: =S10*N3 | U9: =T9-Q9 | V9: =V10*Q3 | X9: =W9-T9 | Y9: =Y10*T3 | AA9: =Z9-W9 | AB9: =AB10*W3 | AD9: =AC9-Z9 | AE9: =AE10*Z3 | AG9: =AF9-AC9 | AH9: =AH10*AC3 | AJ9: =AI9-AF9 | AK9: =AK10*AF3 | AM9: =AL9-AI9 | AN9: =AN10*AI3 | AP9: =AO9-AL9 | AQ9: =AQ10*AL3 | AS9: =AR9-AO9 | AT9: =AT10*AO3 | AV9: =AU9-AR9 | AW9: =AW10*AR3 | AY9: =AX9-AU9 | AZ9: =AZ10*AU3 | BB9: =BA9-AX9 | BC9: =BC10*AX3 | BE9: =BD9-BA9 | BF9: =BF10*BA3 | BH9: =BG9-BD9 | BI9: =BI10*BD3 | BK9: =BJ9-BG9 | BL9: =BL10*BG3 | BN9: =BM9-BJ9 | BO9: =BO10*BJ3 | BQ9: =BP9-BM9 | BR9: =BR10*BM3 | BT9: =BS9-BP9 | BU9: =BU10*BP3 | BW9: =BV9-BS9 | BX9: =BX10*BS3 | BZ9: =BY9-BV9 | CA9: =CA10*BV3 | CC9: =CB9-BY9 | CD9: =CD10*BY3
C10: Тепло тариф | G10: ='0. ГИРА'!G10 | J10: ='0. ГИРА'!J10 | M10: ='0. ГИРА'!M10 | P10: ='0. ГИРА'!P10 | S10: ='0. ГИРА'!S10 | V10: ='0. ГИРА'!V10 | Y10: ='0. ГИРА'!Y10 | AB10: ='0. ГИРА'!AB10 | AE10: ='0. ГИРА'!AE10 | AH10: ='0. ГИРА'!AH10 | AK10: ='0. ГИРА'!AK10 | AN10: ='0. ГИРА'!AN10 | AQ10: ='0. ГИРА'!AQ10 | AT10: ='0. ГИРА'!AT10 | AW10: ='0. ГИРА'!AW10 | AZ10: ='0. ГИРА'!AZ10 | BC10: ='0. ГИРА'!BC10 | BF10: ='0. ГИРА'!BF10 | BI10: ='0. ГИРА'!BI10 | BL10: ='0. ГИРА'!BL10 | BO10: ='0. ГИРА'!BO10 | BR10: ='0. ГИРА'!BR10 | BU10: ='0. ГИРА'!BU10 | BX10: ='0. ГИРА'!BX10 | CA10: ='0. ГИРА'!CA10 | CD10: ='0. ГИРА'!CD10
A11: Номер счетчика | B11: =Реестр!J5 | C11: Экспл. Услуги от УК | F11: =E11-D11 | I11: =H11-E11 | J11: =J12*E3 | L11: =K11-H11 | M11: =M12*H3 | O11: =N11-K11 | P11: =P12*K3 | R11: =Q11-N11 | S11: =S12*N3 | U11: =T11-Q11 | V11: =V12*Q3 | X11: =W11-T11 | Y11: =Y12*T3 | AA11: =Z11-W11 | AB11: =AB12*W3 | AD11: =AC11-Z11 | AE11: =AE12*Z3 | AG11: =AF11-AC11 | AH11: =AH12*AC3 | AJ11: =AI11-AF11 | AK11: =AK12*AF3 | AM11: =AL11-AI11 | AN11: =AN12*AI3 | AP11: =AO11-AL11 | AQ11: =AQ12*AL3 | AS11: =AR11-AO11 | AT11: =AT12*AO3 | AV11: =AU11-AR11 | AW11: =AW12*AR3 | AY11: =AX11-AU11 | AZ11: =AZ12*AU3 | BB11: =BA11-AX11 | BC11: =BC12*AX3 | BE11: =BD11-BA11 | BF11: =BF12*BA3 | BH11: =BG11-BD11 | BI11: =BI12*BD3 | BK11: =BJ11-BG11 | BL11: =BL12*BG3 | BN11: =BM11-BJ11 | BO11: =BO12*BJ3 | BQ11: =BP11-BM11 | BR11: =BR12*BM3 | BT11: =BS11-BP11 | BU11: =BU12*BP3 | BW11: =BV11-BS11 | BX11: =BX12*BS3 | BZ11: =BY11-BV11 | CA11: =CA12*BV3 | CC11: =CB11-BY11 | CD11: =CD12*BY3
C12: Экспл. Услуги от УК тариф | G12: ='0. ГИРА'!G12 | J12: ='0. ГИРА'!J12 | M12: ='0. ГИРА'!M12 | P12: ='0. ГИРА'!P12 | S12: ='0. ГИРА'!S12 | V12: ='0. ГИРА'!V12 | Y12: ='0. ГИРА'!Y12 | AB12: ='0. ГИРА'!AB12 | AE12: ='0. ГИРА'!AE12 | AH12: ='0. ГИРА'!AH12 | AK12: ='0. ГИРА'!AK12 | AN12: ='0. ГИРА'!AN12 | AQ12: ='0. ГИРА'!AQ12 | AT12: ='0. ГИРА'!AT12 | AW12: ='0. ГИРА'!AW12 | AZ12: ='0. ГИРА'!AZ12 | BC12: ='0. ГИРА'!BC12 | BF12: ='0. ГИРА'!BF12 | BI12: ='0. ГИРА'!BI12 | BL12: ='0. ГИРА'!BL12 | BO12: ='0. ГИРА'!BO12 | BR12: ='0. ГИРА'!BR12 | BU12: ='0. ГИРА'!BU12 | BX12: ='0. ГИРА'!BX12 | CA12: ='0. ГИРА'!CA12 | CD12: ='0. ГИРА'!CD12

Sheet К36,00
A1: ИНН | B1: =Реестр!D6 | C1: Месяц | D1: 45962 | E1: 45992 | F1: Потребл. | G1: 45962 | H1: 46023 | I1: Потребл. | J1: 45992 | K1: 46054 | L1: Потребл. | M1: 46023 | N1: 46082 | O1: Потребл. | P1: 46054 | Q1: 46113 | R1: Потребл. | S1: 46082 | T1: 46143 | U1: Потребл. | V1: 46113 | W1: 46174 | X1: Потребл. | Y1: 46143 | Z1: 46204 | AA1: Потребл. | AB1: 46174 | AC1: 46235 | AD1: Потребл. | AE1: 46204 | AF1: 46266 | AG1: Потребл. | AH1: 46235 | AI1: 46296 | AJ1: Потребл. | AK1: 46266 | AL1: 46327 | AM1: Потребл. | AN1: 46296 | AO1: 46357 | AP1: Потребл. | AQ1: 46327 | AR1: 46388 | AS1: Потребл. | AT1: 46357 | AU1: 46419 | AV1: Потребл. | AW1: 46388 | AX1: 46447 | AY1: Потребл. | AZ1: 46419 | BA1: 46478 | BB1: Потребл. | BC1: 46447 | BD1: 46508 | BE1: Потребл. | BF1: 46478 | BG1: 46539 | BH1: Потребл. | BI1: 46508 | BJ1: 46569 | BK1: Потребл. | BL1: 46539 | BM1: 46600 | BN1: Потребл. | BO1: 46569 | BP1: 46631 | BQ1: Потребл. | BR1: 46600 | BS1: 46661 | BT1: Потребл. | BU1: 46631 | BV1: 46692 | BW1: Потребл. | BX1: 46661 | BY1: 46722 | BZ1: Потребл. | CA1: 46692 | CB1: 46753 | CC1: Потребл. | CD1: 46722
A2: Кадастр | B2: =Реестр!B6 | D2: знач. | E2: знач. | F2: знач. | G2: руб. | H2: знач. | I2: знач. | J2: руб. | K2: знач. | L2: знач. | M2: руб. | N2: знач. | O2: знач | P2: руб. | Q2: знач. | R2: знач. | S2: руб. | T2: знач. | U2: знач. | V2: руб. | W2: знач. | X2: знач. | Y2: руб. | Z2: знач. | AA2: знач. | AB2: руб. | AC2: знач. | AD2: знач. | AE2: руб. | AF2: знач. | AG2: знач. | AH2: руб. | AI2: знач. | AJ2: знач. | AK2: руб. | AL2: знач. | AM2: знач. | AN2: руб. | AO2: знач. | AP2: знач. | AQ2: руб. | AR2: знач. | AS2: знач. | AT2: руб. | AU2: знач. | AV2: знач. | AW2: руб. | AX2: знач. | AY2: знач. | AZ2: руб. | BA2: знач. | BB2: знач. | BC2: руб. | BD2: знач. | BE2: знач. | BF2: руб. | BG2: знач. | BH2: знач. | BI2: руб. | BJ2: знач. | BK2: знач. | BL2: руб. | BM2: знач. | BN2: знач. | BO2: руб. | BP2: знач. | BQ2: знач. | BR2: руб. | BS2: знач. | BT2: знач. | BU2: руб. | BV2: знач. | BW2: знач. | BX2: руб. | BY2: знач. | BZ2: знач. | CA2: руб. | CB2: знач. | CC2: знач. | CD2: руб.
A3: Арендатор | B3: =Реестр!F6 | C3: Электричество | F3: =E3-D3 | G3: =F3*G4 | I3: =H3-E3 | J3: =I3*J4 | L3: =K3-H3 | M3: =L3*M4 | O3: =N3-K3 | P3: =O3*P4 | R3: =Q3-N3 | S3: =R3*S4 | U3: =T3-Q3 | V3: =U3*V4 | X3: =W3-T3 | Y3: =X3*Y4 | AA3: =Z3-W3 | AB3: =AA3*AB4 | AD3: =AC3-Z3 | AE3: =AD3*AE4 | AG3: =AF3-AC3 | AH3: =AG3*AH4 | AJ3: =AI3-AF3 | AK3: =AJ3*AK4 | AM3: =AL3-AI3 | AN3: =AM3*AN4 | AP3: =AO3-AL3 | AQ3: =AP3*AQ4 | AS3: =AR3-AO3 | AT3: =AS3*AT4 | AV3: =AU3-AR3 | AW3: =AV3*AW4 | AY3: =AX3-AU3 | AZ3: =AY3*AZ4 | BB3: =BA3-AX3 | BC3: =BB3*BC4 | BE3: =BD3-BA3 | BF3: =BE3*BF4 | BH3: =BG3-BD3 | BI3: =BH3*BI4 | BK3: =BJ3-BG3 | BL3: =BK3*BL4 | BN3: =BM3-BJ3 | BO3: =BN3*BO4 | BQ3: =BP3-BM3 | BR3: =BQ3*BR4 | BT3: =BS3-BP3 | BU3: =BT3*BU4 | BW3: =BV3-BS3 | BX3: =BW3*BX4 | BZ3: =BY3-BV3 | CA3: =BZ3*CA4 | CC3: =CB3-BY3 | CD3: =CC3*CD4
A4: Площадь | B4: =Реестр!H6 | C4: Электричество тариф | G4: ='0. ГИРА'!G4 | J4: ='0. ГИРА'!J4 | M4: ='0. ГИРА'!M4 | P4: ='0. ГИРА'!P4 | S4: ='0. ГИРА'!S4 | V4: ='0. ГИРА'!V4 | Y4: ='0. ГИРА'!Y4 | AB4: ='0. ГИРА'!AB4 | AE4: ='0. ГИРА'!AE4 | AH4: ='0. ГИРА'!AH4 | AK4: ='0. ГИРА'!AK4 | AN4: ='0. ГИРА'!AN4 | AQ4: ='0. ГИРА'!AQ4 | AT4: ='0. ГИРА'!AT4 | AW4: ='0. ГИРА'!AW4 | AZ4: ='0. ГИРА'!AZ4 | BC4: ='0. ГИРА'!BC4 | BF4: ='0. ГИРА'!BF4 | BI4: ='0. ГИРА'!BI4 | BL4: ='0. ГИРА'!BL4 | BO4: ='0. ГИРА'!BO4 | BR4: ='0. ГИРА'!BR4 | BU4: ='0. ГИРА'!BU4 | BX4: ='0. ГИРА'!BX4 | CA4: ='0. ГИРА'!CA4 | CD4: ='0. ГИРА'!CD4
C5: Водоканал холодная вода | F5: =E5-D5 | I5: =H5-E5 | L5: =K5-H5 | O5: =N5-K5 | R5: =Q5-N5 | U5: =T5-Q5 | X5: =W5-T5 | AA5: =Z5-W5 | AD5: =AC5-Z5 | AG5: =AF5-AC5 | AJ5: =AI5-AF5 | AM5: =AL5-AI5 | AP5: =AO5-AL5 | AS5: =AR5-AO5 | AV5: =AU5-AR5 | AY5: =AX5-AU5 | BB5: =BA5-AX5 | BE5: =BD5-BA5 | BH5: =BG5-BD5 | BK5: =BJ5-BG5 | BN5: =BM5-BJ5 | BQ5: =BP5-BM5 | BT5: =BS5-BP5 | BW5: =BV5-BS5 | BZ5: =BY5-BV5 | CC5: =CB5-BY5
A6: Имя 1 | B6: =Реестр!M6 | C6: Водоканал холодная Тариф | G6: ='0. ГИРА'!G6 | J6: ='0. ГИРА'!J6 | M6: ='0. ГИРА'!M6 | P6: ='0. ГИРА'!P6 | S6: ='0. ГИРА'!S6 | V6: ='0. ГИРА'!V6 | Y6: ='0. ГИРА'!Y6 | AB6: ='0. ГИРА'!AB6 | AE6: ='0. ГИРА'!AE6 | AH6: ='0. ГИРА'!AH6 | AK6: ='0. ГИРА'!AK6 | AN6: ='0. ГИРА'!AN6 | AQ6: ='0. ГИРА'!AQ6 | AT6: ='0. ГИРА'!AT6 | AW6: ='0. ГИРА'!AW6 | AZ6: ='0. ГИРА'!AZ6 | BC6: ='0. ГИРА'!BC6 | BF6: ='0. ГИРА'!BF6 | BI6: ='0. ГИРА'!BI6 | BL6: ='0. ГИРА'!BL6 | BO6: ='0. ГИРА'!BO6 | BR6: ='0. ГИРА'!BR6 | BU6: ='0. ГИРА'!BU6 | BX6: ='0. ГИРА'!BX6 | CA6: ='0. ГИРА'!CA6 | CD6: ='0. ГИРА'!CD6
A7: Контакт 1 | B7: =Реестр!N6 | C7: Водоканал горячая вода | F7: =E7-D7 | G7: =G8*F7 | I7: =H7-E7 | J7: =J8*I7 | L7: =K7-H7 | M7: =M8*L7 | O7: =N7-K7 | P7: =P8*O7 | R7: =Q7-N7 | S7: =S8*R7 | U7: =T7-Q7 | V7: =V8*U7 | X7: =W7-T7 | Y7: =Y8*X7 | AA7: =Z7-W7 | AB7: =AB8*AA7 | AD7: =AC7-Z7 | AE7: =AE8*AD7 | AG7: =AF7-AC7 | AH7: =AH8*AG7 | AJ7: =AI7-AF7 | AK7: =AK8*AJ7 | AM7: =AL7-AI7 | AN7: =AN8*AM7 | AP7: =AO7-AL7 | AQ7: =AQ8*AP7 | AS7: =AR7-AO7 | AT7: =AT8*AS7 | AV7: =AU7-AR7 | AW7: =AW8*AV7 | AY7: =AX7-AU7 | AZ7: =AZ8*AY7 | BB7: =BA7-AX7 | BC7: =BC8*BB7 | BE7: =BD7-BA7 | BF7: =BF8*BE7 | BH7: =BG7-BD7 | BI7: =BI8*BH7 | BK7: =BJ7-BG7 | BL7: =BL8*BK7 | BN7: =BM7-BJ7 | BO7: =BO8*BN7 | BQ7: =BP7-BM7 | BR7: =BR8*BQ7 | BT7: =BS7-BP7 | BU7: =BU8*BT7 | BW7: =BV7-BS7 | BX7: =BX8*BW7 | BZ7: =BY7-BV7 | CA7: =CA8*BZ7 | CC7: =CB7-BY7 | CD7: =CD8*CC7
A8: Имя 2 | B8: =Реестр!O6 | C8: Водоканал горячая Тариф | G8: ='0. ГИРА'!G8 | J8: ='0. ГИРА'!J8 | M8: ='0. ГИРА'!M8 | P8: ='0. ГИРА'!P8 | S8: ='0. ГИРА'!S8 | V8: ='0. ГИРА'!V8 | Y8: ='0. ГИРА'!Y8 | AB8: ='0. ГИРА'!AB8 | AE8: ='0. ГИРА'!AE8 | AH8: ='0. ГИРА'!AH8 | AK8: ='0. ГИРА'!AK8 | AN8: ='0. ГИРА'!AN8 | AQ8: ='0. ГИРА'!AQ8 | AT8: ='0. ГИРА'!AT8 | AW8: ='0. ГИРА'!AW8 | AZ8: ='0. ГИРА'!AZ8 | BC8: ='0. ГИРА'!BC8 | BF8: ='0. ГИРА'!BF8 | BI8: ='0. ГИРА'!BI8 | BL8: ='0. ГИРА'!BL8 | BO8: ='0. ГИРА'!BO8 | BR8: ='0. ГИРА'!BR8 | BU8: ='0. ГИРА'!BU8 | BX8: ='0. ГИРА'!BX8 | CA8: ='0. ГИРА'!CA8 | CD8: ='0. ГИРА'!CD8
A9: Контакт 2 | B9: =Реестр!P6 | C9: Тепло | F9: =E9-D9 | G9: =G10*B3 | I9: =H9-E9 | J9: =J10*E3 | L9: =K9-H9 | M9: =M10*H3 | O9: =N9-K9 | P9: =P10*K3 | R9: =Q9-N9 | S9: =S10*N3 | U9: =T9-Q9 | V9: =V10*Q3 | X9: =W9-T9 | Y9: =Y10*T3 | AA9: =Z9-W9 | AB9: =AB10*W3 | AD9: =AC9-Z9 | AE9: =AE10*Z3 | AG9: =AF9-AC9 | AH9: =AH10*AC3 | AJ9: =AI9-AF9 | AK9: =AK10*AF3 | AM9: =AL9-AI9 | AN9: =AN10*AI3 | AP9: =AO9-AL9 | AQ9: =AQ10*AL3 | AS9: =AR9-AO9 | AT9: =AT10*AO3 | AV9: =AU9-AR9 | AW9: =AW10*AR3 | AY9: =AX9-AU9 | AZ9: =AZ10*AU3 | BB9: =BA9-AX9 | BC9: =BC10*AX3 | BE9: =BD9-BA9 | BF9: =BF10*BA3 | BH9: =BG9-BD9 | BI9: =BI10*BD3 | BK9: =BJ9-BG9 | BL9: =BL10*BG3 | BN9: =BM9-BJ9 | BO9: =BO10*BJ3 | BQ9: =BP9-BM9 | BR9: =BR10*BM3 | BT9: =BS9-BP9 | BU9: =BU10*BP3 | BW9: =BV9-BS9 | BX9: =BX10*BS3 | BZ9: =BY9-BV9 | CA9: =CA10*BV3 | CC9: =CB9-BY9 | CD9: =CD10*BY3
C10: Тепло тариф | G10: ='0. ГИРА'!G10 | J10: ='0. ГИРА'!J10 | M10: ='0. ГИРА'!M10 | P10: ='0. ГИРА'!P10 | S10: ='0. ГИРА'!S10 | V10: ='0. ГИРА'!V10 | Y10: ='0. ГИРА'!Y10 | AB10: ='0. ГИРА'!AB10 | AE10: ='0. ГИРА'!AE10 | AH10: ='0. ГИРА'!AH10 | AK10: ='0. ГИРА'!AK10 | AN10: ='0. ГИРА'!AN10 | AQ10: ='0. ГИРА'!AQ10 | AT10: ='0. ГИРА'!AT10 | AW10: ='0. ГИРА'!AW10 | AZ10: ='0. ГИРА'!AZ10 | BC10: ='0. ГИРА'!BC10 | BF10: ='0. ГИРА'!BF10 | BI10: ='0. ГИРА'!BI10 | BL10: ='0. ГИРА'!BL10 | BO10: ='0. ГИРА'!BO10 | BR10: ='0. ГИРА'!BR10 | BU10: ='0. ГИРА'!BU10 | BX10: ='0. ГИРА'!BX10 | CA10: ='0. ГИРА'!CA10 | CD10: ='0. ГИРА'!CD10
A11: Номер счетчика | B11: 111 000111,000788,000191, 11111111, 11111110 | C11: Экспл. Услуги от УК | F11: =E11-D11 | I11: =H11-E11 | J11: =J12*E3 | L11: =K11-H11 | M11: =M12*H3 | O11: =N11-K11 | P11: =P12*K3 | R11: =Q11-N11 | S11: =S12*N3 | U11: =T11-Q11 | V11: =V12*Q3 | X11: =W11-T11 | Y11: =Y12*T3 | AA11: =Z11-W11 | AB11: =AB12*W3 | AD11: =AC11-Z11 | AE11: =AE12*Z3 | AG11: =AF11-AC11 | AH11: =AH12*AC3 | AJ11: =AI11-AF11 | AK11: =AK12*AF3 | AM11: =AL11-AI11 | AN11: =AN12*AI3 | AP11: =AO11-AL11 | AQ11: =AQ12*AL3 | AS11: =AR11-AO11 | AT11: =AT12*AO3 | AV11: =AU11-AR11 | AW11: =AW12*AR3 | AY11: =AX11-AU11 | AZ11: =AZ12*AU3 | BB11: =BA11-AX11 | BC11: =BC12*AX3 | BE11: =BD11-BA11 | BF11: =BF12*BA3 | BH11: =BG11-BD11 | BI11: =BI12*BD3 | BK11: =BJ11-BG11 | BL11: =BL12*BG3 | BN11: =BM11-BJ11 | BO11: =BO12*BJ3 | BQ11: =BP11-BM11 | BR11: =BR12*BM3 | BT11: =BS11-BP11 | BU11: =BU12*BP3 | BW11: =BV11-BS11 | BX11: =BX12*BS3 | BZ11: =BY11-BV11 | CA11: =CA12*BV3 | CC11: =CB11-BY11 | CD11: =CD12*BY3
C12: Экспл. Услуги от УК тариф | G12: ='0. ГИРА'!G12 | J12: ='0. ГИРА'!J12 | M12: ='0. ГИРА'!M12 | P12: ='0. ГИРА'!P12 | S12: ='0. ГИРА'!S12 | V12: ='0. ГИРА'!V12 | Y12: ='0. ГИРА'!Y12 | AB12: ='0. ГИРА'!AB12 | AE12: ='0. ГИРА'!AE12 | AH12: ='0. ГИРА'!AH12 | AK12: ='0. ГИРА'!AK12 | AN12: ='0. ГИРА'!AN12 | AQ12: ='0. ГИРА'!AQ12 | AT12: ='0. ГИРА'!AT12 | AW12: ='0. ГИРА'!AW12 | AZ12: ='0. ГИРА'!AZ12 | BC12: ='0. ГИРА'!BC12 | BF12: ='0. ГИРА'!BF12 | BI12: ='0. ГИРА'!BI12 | BL12: ='0. ГИРА'!BL12 | BO12: ='0. ГИРА'!BO12 | BR12: ='0. ГИРА'!BR12 | BU12: ='0. ГИРА'!BU12 | BX12: ='0. ГИРА'!BX12 | CA12: ='0. ГИРА'!CA12 | CD12: ='0. ГИРА'!CD12

Sheet К28,35
A1: ИНН | B1: =Реестр!D7 | C1: Месяц | D1: 45962 | E1: 45992 | F1: Потребл. | G1: 45962 | H1: 46023 | I1: Потребл. | J1: 45992 | K1: 46054 | L1: Потребл. | M1: 46023 | N1: 46082 | O1: Потребл. | P1: 46054 | Q1: 46113 | R1: Потребл. | S1: 46082 | T1: 46143 | U1: Потребл. | V1: 46113 | W1: 46174 | X1: Потребл. | Y1: 46143 | Z1: 46204 | AA1: Потребл. | AB1: 46174 | AC1: 46235 | AD1: Потребл. | AE1: 46204 | AF1: 46266 | AG1: Потребл. | AH1: 46235 | AI1: 46296 | AJ1: Потребл. | AK1: 46266 | AL1: 46327 | AM1: Потребл. | AN1: 46296 | AO1: 46357 | AP1: Потребл. | AQ1: 46327 | AR1: 46388 | AS1: Потребл. | AT1: 46357 | AU1: 46419 | AV1: Потребл. | AW1: 46388 | AX1: 46447 | AY1: Потребл. | AZ1: 46419 | BA1: 46478 | BB1: Потребл. | BC1: 46447 | BD1: 46508 | BE1: Потребл. | BF1: 46478 | BG1: 46539 | BH1: Потребл. | BI1: 46508 | BJ1: 46569 | BK1: Потребл. | BL1: 46539 | BM1: 46600 | BN1: Потребл. | BO1: 46569 | BP1: 46631 | BQ1: Потребл. | BR1: 46600 | BS1: 46661 | BT1: Потребл. | BU1: 46631 | BV1: 46692 | BW1: Потребл. | BX1: 46661 | BY1: 46722 | BZ1: Потребл. | CA1: 46692 | CB1: 46753 | CC1: Потребл. | CD1: 46722
A2: Кадастр | B2: =Реестр!B7 | D2: знач. | E2: знач. | F2: знач. | G2: руб. | H2: знач. | I2: знач. | J2: руб. | K2: знач. | L2: знач. | M2: руб. | N2: знач. | O2: знач | P2: руб. | Q2: знач. | R2: знач. | S2: руб. | T2: знач. | U2: знач. | V2: руб. | W2: знач. | X2: знач. | Y2: руб. | Z2: знач. | AA2: знач. | AB2: руб. | AC2: знач. | AD2: знач. | AE2: руб. | AF2: знач. | AG2: знач. | AH2: руб. | AI2: знач. | AJ2: знач. | AK2: руб. | AL2: знач. | AM2: знач. | AN2: руб. | AO2: знач. | AP2: знач. | AQ2: руб. | AR2: знач. | AS2: знач. | AT2: руб. | AU2: знач. | AV2: знач. | AW2: руб. | AX2: знач. | AY2: знач. | AZ2: руб. | BA2: знач. | BB2: знач. | BC2: руб. | BD2: знач. | BE2: знач. | BF2: руб. | BG2: знач. | BH2: знач. | BI2: руб. | BJ2: знач. | BK2: знач. | BL2: руб. | BM2: знач. | BN2: знач. | BO2: руб. | BP2: знач. | BQ2: знач. | BR2: руб. | BS2: знач. | BT2: знач. | BU2: руб. | BV2: знач. | BW2: знач. | BX2: руб. | BY2: знач. | BZ2: знач. | CA2: руб. | CB2: знач. | CC2: знач. | CD2: руб.
A3: Арендатор | B3: =Реестр!F7 | C3: Электричество | F3: =E3-D3 | G3: =F3*G4 | I3: =H3-E3 | J3: =I3*J4 | L3: =K3-H3 | M3: =L3*M4 | O3: =N3-K3 | P3: =O3*P4 | R3: =Q3-N3 | S3: =R3*S4 | U3: =T3-Q3 | V3: =U3*V4 | X3: =W3-T3 | Y3: =X3*Y4 | AA3: =Z3-W3 | AB3: =AA3*AB4 | AD3: =AC3-Z3 | AE3: =AD3*AE4 | AG3: =AF3-AC3 | AH3: =AG3*AH4 | AJ3: =AI3-AF3 | AK3: =AJ3*AK4 | AM3: =AL3-AI3 | AN3: =AM3*AN4 | AP3: =AO3-AL3 | AQ3: =AP3*AQ4 | AS3: =AR3-AO3 | AT3: =AS3*AT4 | AV3: =AU3-AR3 | AW3: =AV3*AW4 | AY3: =AX3-AU3 | AZ3: =AY3*AZ4 | BB3: =BA3-AX3 | BC3: =BB3*BC4 | BE3: =BD3-BA3 | BF3: =BE3*BF4 | BH3: =BG3-BD3 | BI3: =BH3*BI4 | BK3: =BJ3-BG3 | BL3: =BK3*BL4 | BN3: =BM3-BJ3 | BO3: =BN3*BO4 | BQ3: =BP3-BM3 | BR3: =BQ3*BR4 | BT3: =BS3-BP3 | BU3: =BT3*BU4 | BW3: =BV3-BS3 | BX3: =BW3*BX4 | BZ3: =BY3-BV3 | CA3: =BZ3*CA4 | CC3: =CB3-BY3 | CD3: =CC3*CD4
A4: Площадь | B4: =Реестр!H7 | C4: Электричество тариф | G4: ='0. ГИРА'!G4 | J4: ='0. ГИРА'!J4 | M4: ='0. ГИРА'!M4 | P4: ='0. ГИРА'!P4 | S4: ='0. ГИРА'!S4 | V4: ='0. ГИРА'!V4 | Y4: ='0. ГИРА'!Y4 | AB4: ='0. ГИРА'!AB4 | AE4: ='0. ГИРА'!AE4 | AH4: ='0. ГИРА'!AH4 | AK4: ='0. ГИРА'!AK4 | AN4: ='0. ГИРА'!AN4 | AQ4: ='0. ГИРА'!AQ4 | AT4: ='0. ГИРА'!AT4 | AW4: ='0. ГИРА'!AW4 | AZ4: ='0. ГИРА'!AZ4 | BC4: ='0. ГИРА'!BC4 | BF4: ='0. ГИРА'!BF4 | BI4: ='0. ГИРА'!BI4 | BL4: ='0. ГИРА'!BL4 | BO4: ='0. ГИРА'!BO4 | BR4: ='0. ГИРА'!BR4 | BU4: ='0. ГИРА'!BU4 | BX4: ='0. ГИРА'!BX4 | CA4: ='0. ГИРА'!CA4 | CD4: ='0. ГИРА'!CD4
C5: Водоканал холодная вода | F5: =E5-D5 | I5: =H5-E5 | L5: =K5-H5 | O5: =N5-K5 | R5: =Q5-N5 | U5: =T5-Q5 | X5: =W5-T5 | AA5: =Z5-W5 | AD5: =AC5-Z5 | AG5: =AF5-AC5 | AJ5: =AI5-AF5 | AM5: =AL5-AI5 | AP5: =AO5-AL5 | AS5: =AR5-AO5 | AV5: =AU5-AR5 | AY5: =AX5-AU5 | BB5: =BA5-AX5 | BE5: =BD5-BA5 | BH5: =BG5-BD5 | BK5: =BJ5-BG5 | BN5: =BM5-BJ5 | BQ5: =BP5-BM5 | BT5: =BS5-BP5 | BW5: =BV5-BS5 | BZ5: =BY5-BV5 | CC5: =CB5-BY5
A6: Имя 1 | B6: =Реестр!M7 | C6: Водоканал холодная Тариф | G6: ='0. ГИРА'!G6 | J6: ='0. ГИРА'!J6 | M6: ='0. ГИРА'!M6 | P6: ='0. ГИРА'!P6 | S6: ='0. ГИРА'!S6 | V6: ='0. ГИРА'!V6 | Y6: ='0. ГИРА'!Y6 | AB6: ='0. ГИРА'!AB6 | AE6: ='0. ГИРА'!AE6 | AH6: ='0. ГИРА'!AH6 | AK6: ='0. ГИРА'!AK6 | AN6: ='0. ГИРА'!AN6 | AQ6: ='0. ГИРА'!AQ6 | AT6: ='0. ГИРА'!AT6 | AW6: ='0. ГИРА'!AW6 | AZ6: ='0. ГИРА'!AZ6 | BC6: ='0. ГИРА'!BC6 | BF6: ='0. ГИРА'!BF6 | BI6: ='0. ГИРА'!BI6 | BL6: ='0. ГИРА'!BL6 | BO6: ='0. ГИРА'!BO6 | BR6: ='0. ГИРА'!BR6 | BU6: ='0. ГИРА'!BU6 | BX6: ='0. ГИРА'!BX6 | CA6: ='0. ГИРА'!CA6 | CD6: ='0. ГИРА'!CD6
A7: Контакт 1 | B7: =Реестр!N7 | C7: Водоканал горячая вода | F7: =E7-D7 | G7: =G8*F7 | I7: =H7-E7 | J7: =J8*I7 | L7: =K7-H7 | M7: =M8*L7 | O7: =N7-K7 | P7: =P8*O7 | R7: =Q7-N7 | S7: =S8*R7 | U7: =T7-Q7 | V7: =V8*U7 | X7: =W7-T7 | Y7: =Y8*X7 | AA7: =Z7-W7 | AB7: =AB8*AA7 | AD7: =AC7-Z7 | AE7: =AE8*AD7 | AG7: =AF7-AC7 | AH7: =AH8*AG7 | AJ7: =AI7-AF7 | AK7: =AK8*AJ7 | AM7: =AL7-AI7 | AN7: =AN8*AM7 | AP7: =AO7-AL7 | AQ7: =AQ8*AP7 | AS7: =AR7-AO7 | AT7: =AT8*AS7 | AV7: =AU7-AR7 | AW7: =AW8*AV7 | AY7: =AX7-AU7 | AZ7: =AZ8*AY7 | BB7: =BA7-AX7 | BC7: =BC8*BB7 | BE7: =BD7-BA7 | BF7: =BF8*BE7 | BH7: =BG7-BD7 | BI7: =BI8*BH7 | BK7: =BJ7-BG7 | BL7: =BL8*BK7 | BN7: =BM7-BJ7 | BO7: =BO8*BN7 | BQ7: =BP7-BM7 | BR7: =BR8*BQ7 | BT7: =BS7-BP7 | BU7: =BU8*BT7 | BW7: =BV7-BS7 | BX7: =BX8*BW7 | BZ7: =BY7-BV7 | CA7: =CA8*BZ7 | CC7: =CB7-BY7 | CD7: =CD8*CC7
A8: Имя 2 | B8: =Реестр!O7 | C8: Водоканал горячая Тариф | G8: ='0. ГИРА'!G8 | J8: ='0. ГИРА'!J8 | M8: ='0. ГИРА'!M8 | P8: ='0. ГИРА'!P8 | S8: ='0. ГИРА'!S8 | V8: ='0. ГИРА'!V8 | Y8: ='0. ГИРА'!Y8 | AB8: ='0. ГИРА'!AB8 | AE8: ='0. ГИРА'!AE8 | AH8: ='0. ГИРА'!AH8 | AK8: ='0. ГИРА'!AK8 | AN8: ='0. ГИРА'!AN8 | AQ8: ='0. ГИРА'!AQ8 | AT8: ='0. ГИРА'!AT8 | AW8: ='0. ГИРА'!AW8 | AZ8: ='0. ГИРА'!AZ8 | BC8: ='0. ГИРА'!BC8 | BF8: ='0. ГИРА'!BF8 | BI8: ='0. ГИРА'!BI8 | BL8: ='0. ГИРА'!BL8 | BO8: ='0. ГИРА'!BO8 | BR8: ='0. ГИРА'!BR8 | BU8: ='0. ГИРА'!BU8 | BX8: ='0. ГИРА'!BX8 | CA8: ='0. ГИРА'!CA8 | CD8: ='0. ГИРА'!CD8
A9: Контакт 2 | B9: =Реестр!P7 | C9: Тепло | F9: =E9-D9 | G9: =G10*B3 | I9: =H9-E9 | J9: =J10*E3 | L9: =K9-H9 | M9: =M10*H3 | O9: =N9-K9 | P9: =P10*K3 | R9: =Q9-N9 | S9: =S10*N3 | U9: =T9-Q9 | V9: =V10*Q3 | X9: =W9-T9 | Y9: =Y10*T3 | AA9: =Z9-W9 | AB9: =AB10*W3 | AD9: =AC9-Z9 | AE9: =AE10*Z3 | AG9: =AF9-AC9 | AH9: =AH10*AC3 | AJ9: =AI9-AF9 | AK9: =AK10*AF3 | AM9: =AL9-AI9 | AN9: =AN10*AI3 | AP9: =AO9-AL9 | AQ9: =AQ10*AL3 | AS9: =AR9-AO9 | AT9: =AT10*AO3 | AV9: =AU9-AR9 | AW9: =AW10*AR3 | AY9: =AX9-AU9 | AZ9: =AZ10*AU3 | BB9: =BA9-AX9 | BC9: =BC10*AX3 | BE9: =BD9-BA9 | BF9: =BF10*BA3 | BH9: =BG9-BD9 | BI9: =BI10*BD3 | BK9: =BJ9-BG9 | BL9: =BL10*BG3 | BN9: =BM9-BJ9 | BO9: =BO10*BJ3 | BQ9: =BP9-BM9 | BR9: =BR10*BM3 | BT9: =BS9-BP9 | BU9: =BU10*BP3 | BW9: =BV9-BS9 | BX9: =BX10*BS3 | BZ9: =BY9-BV9 | CA9: =CA10*BV3 | CC9: =CB9-BY9 | CD9: =CD10*BY3
C10: Тепло тариф | G10: ='0. ГИРА'!G10 | J10: ='0. ГИРА'!J10 | M10: ='0. ГИРА'!M10 | P10: ='0. ГИРА'!P10 | S10: ='0. ГИРА'!S10 | V10: ='0. ГИРА'!V10 | Y10: ='0. ГИРА'!Y10 | AB10: ='0. ГИРА'!AB10 | AE10: ='0. ГИРА'!AE10 | AH10: ='0. ГИРА'!AH10 | AK10: ='0. ГИРА'!AK10 | AN10: ='0. ГИРА'!AN10 | AQ10: ='0. ГИРА'!AQ10 | AT10: ='0. ГИРА'!AT10 | AW10: ='0. ГИРА'!AW10 | AZ10: ='0. ГИРА'!AZ10 | BC10: ='0. ГИРА'!BC10 | BF10: ='0. ГИРА'!BF10 | BI10: ='0. ГИРА'!BI10 | BL10: ='0. ГИРА'!BL10 | BO10: ='0. ГИРА'!BO10 | BR10: ='0. ГИРА'!BR10 | BU10: ='0. ГИРА'!BU10 | BX10: ='0. ГИРА'!BX10 | CA10: ='0. ГИРА'!CA10 | CD10: ='0. ГИРА'!CD10
