Workbook

Sheet 0. ГИРА
A1: Кадастр | B1: 1006 | C1: Месяц | D1: 45962 | E1: 45992 | F1: Потребл. | G1: 45962 | H1: 46023 | I1: Потребл. | J1: 45992 | K1: 46054 | L1: Потребл. | M1: 46023 | N1: 46082 | O1: Потребл. | P1: 46054 | Q1: 46113 | R1: Потребл. | S1: 46082 | T1: 46143 | U1: Потребл. | V1: 46113 | W1: 46174 | X1: Потребл. | Y1: 46143 | Z1: 46204 | AA1: Потребл. | AB1: 46174 | AC1: 46235 | AD1: Потребл. | AE1: 46204 | AF1: 46266 | AG1: Потребл. | AH1: 46235 | AI1: 46296 | AJ1: Потребл. | AK1: 46266 | AL1: 46327 | AM1: Потребл. | AN1: 46296 | AO1: 46357 | AP1: Потребл. | AQ1: 46327 | AR1: 46388 | AS1: Потребл. | AT1: 46357 | AU1: 46419 | AV1: Потребл. | AW1: 46388 | AX1: 46447 | AY1: Потребл. | AZ1: 46419 | BA1: 46478 | BB1: Потребл. | BC1: 46447 | BD1: 46508 | BE1: Потребл. | BF1: 46478 | BG1: 46539 | BH1: Потребл. | BI1: 46508 | BJ1: 46569 | BK1: Потребл. | BL1: 46539 | BM1: 46600 | BN1: Потребл. | BO1: 46569 | BP1: 46631 | BQ1: Потребл. | BR1: 46600 | BS1: 46661 | BT1: Потребл. | BU1: 46631 | BV1: 46692 | BW1: Потребл. | BX1: 46661 | BY1: 46722 | BZ1: Потребл. | CA1: 46692
A2: Потребитель | B2: ГИРА | D2: знач. | E2: знач. | F2: знач. | G2: руб. | H2: знач. | I2: знач. | J2: руб. | K2: знач. | L2: знач. | M2: руб. | N2: знач. | O2: знач. | P2: руб. | Q2: знач. | R2: знач. | S2: руб. | T2: знач. | U2: знач. | V2: руб. | W2: знач. | X2: знач. | Y2: руб. | Z2: знач. | AA2: знач. | AB2: руб. | AC2: знач. | AD2: знач. | AE2: руб. | AF2: знач. | AG2: знач. | AH2: руб. | AI2: знач. | AJ2: знач. | AK2: руб. | AL2: знач. | AM2: знач. | AN2: руб. | AO2: знач. | AP2: знач. | AQ2: руб. | AR2: знач. | AS2: знач. | AT2: руб. | AU2: знач. | AV2: знач. | AW2: руб. | AX2: знач. | AY2: знач. | AZ2: руб. | BA2: знач. | BB2: знач. | BC2: руб. | BD2: знач. | BE2: знач. | BF2: руб. | BG2: знач. | BH2: знач. | BI2: руб. | BJ2: знач. | BK2: знач. | BL2: руб. | BM2: знач. | BN2: знач. | BO2: руб. | BP2: знач. | BQ2: знач. | BR2: руб. | BS2: знач. | BT2: знач. | BU2: руб. | BV2: знач. | BW2: знач. | BX2: руб. | BY2: знач. | BZ2: знач. | CA2: руб.
A3: Площадь | B3: 487.45 | C3: Электричество | D3: 115000 | E3: 120000 | F3: 222222 | G3: 10000 | H3: 222222 | I3: =H3-E3 -> 102222 | J3: 20000 | K3: 245112 | L3: =K3-H3 -> 22890 | M3: 210 | O3: =N3-K3 -> -245112 | R3: =Q3-N3 -> 0 | U3: =T3-Q3 -> 0 | X3: =W3-T3 -> 0 | AA3: =Z3-W3 -> 0 | AD3: =AC3-Z3 -> 0 | AG3: =AF3-AC3 -> 0 | AJ3: =AI3-AF3 -> 0 | AM3: =AL3-AI3 -> 0 | AP3: =AO3-AL3 -> 0 | AS3: =AR3-AO3 -> 0 | AV3: =AU3-AR3 -> 0 | AY3: =AX3-AU3 -> 0 | BB3: =BA3-AX3 -> 0 | BE3: =BD3-BA3 -> 0 | BH3: =BG3-BD3 -> 0 | BK3: =BJ3-BG3 -> 0 | BN3: =BM3-BJ3 -> 0 | BQ3: =BP3-BM3 -> 0 | BT3: =BS3-BP3 -> 0 | BW3: =BV3-BS3 -> 0 | BZ3: =BY3-BV3 -> 0
A4: ИНН | C4: Электричество тариф | G4: =G3/F3 -> 0.045000045 | J4: =J3/I3 -> 0.1956526 | M4: =M3/L3 -> 0.0091743119 | P4: =P3/O3 -> 0 | S4: =S3/R3 -> #DIV/0! | V4: =V3/U3 -> #DIV/0! | Y4: =Y3/X3 -> #DIV/0! | AB4: =AB3/AA3 -> #DIV/0! | AE4: =AE3/AD3 -> #DIV/0! | AH4: =AH3/AG3 -> #DIV/0! | AK4: =AK3/AJ3 -> #DIV/0! | AN4: =AN3/AM3 -> #DIV/0! | AQ4: =AQ3/AP3 -> #DIV/0! | AT4: =AT3/AS3 -> #DIV/0! | AW4: =AW3/AV3 -> #DIV/0! | AZ4: =AZ3/AY3 -> #DIV/0! | BC4: =BC3/BB3 -> #DIV/0! | BF4: =BF3/BE3 -> #DIV/0! | BI4: =BI3/BH3 -> #DIV/0! | BL4: =BL3/BK3 -> #DIV/0! | BO4: =BO3/BN3 -> #DIV/0! | BR4: =BR3/BQ3 -> #DIV/0! | BU4: =BU3/BT3 -> #DIV/0! | BX4: =BX3/BW3 -> #DIV/0! | CA4: =CA3/BZ3 -> #DIV/0!
A5: Кол-во помещ | B5: 7 | C5: Водоканал холодная вода | D5: 115000 | E5: 120000 | F5: 222222 | G5: 15000 | H5: 222222 | I5: =H5-E5 -> 102222 | J5: 15000 | K5: 32512 | L5: =K5-H5 -> -189710 | M5: 2100 | O5: =N5-K5 -> -32512 | R5: =Q5-N5 -> 0 | U5: =T5-Q5 -> 0 | X5: =W5-T5 -> 0 | AA5: =Z5-W5 -> 0 | AD5: =AC5-Z5 -> 0 | AG5: =AF5-AC5 -> 0 | AJ5: =AI5-AF5 -> 0 | AM5: =AL5-AI5 -> 0 | AP5: =AO5-AL5 -> 0 | AS5: =AR5-AO5 -> 0 | AV5: =AU5-AR5 -> 0 | AY5: =AX5-AU5 -> 0 | BB5: =BA5-AX5 -> 0 | BE5: =BD5-BA5 -> 0 | BH5: =BG5-BD5 -> 0 | BK5: =BJ5-BG5 -> 0 | BN5: =BM5-BJ5 -> 0 | BQ5: =BP5-BM5 -> 0 | BT5: =BS5-BP5 -> 0 | BW5: =BV5-BS5 -> 0 | BZ5: =BY5-BV5 -> 0
C6: Водоканал холодная Тариф | G6: =G5/F5 -> 0.067500068 | J6: =J5/I5 -> 0.14673945 | M6: =M5/L5 -> -0.011069527 | P6: =P5/O5 -> 0 | S6: =S5/R5 -> #DIV/0! | V6: =V5/U5 -> #DIV/0! | Y6: =Y5/X5 -> #DIV/0! | AB6: =AB5/AA5 -> #DIV/0! | AE6: =AE5/AD5 -> #DIV/0! | AH6: =AH5/AG5 -> #DIV/0! | AK6: =AK5/AJ5 -> #DIV/0! | AN6: =AN5/AM5 -> #DIV/0! | AQ6: =AQ5/AP5 -> #DIV/0! | AT6: =AT5/AS5 -> #DIV/0! | AW6: =AW5/AV5 -> #DIV/0! | AZ6: =AZ5/AY5 -> #DIV/0! | BC6: =BC5/BB5 -> #DIV/0! | BF6: =BF5/BE5 -> #DIV/0! | BI6: =BI5/BH5 -> #DIV/0! | BL6: =BL5/BK5 -> #DIV/0! | BO6: =BO5/BN5 -> #DIV/0! | BR6: =BR5/BQ5 -> #DIV/0! | BU6: =BU5/BT5 -> #DIV/0! | BX6: =BX5/BW5 -> #DIV/0! | CA6: =CA5/BZ5 -> #DIV/0!
C7: Водоканал горячая вода | D7: 115000 | E7: 120000 | F7: 222222 | G7: 20000 | H7: 222222 | I7: =H7-E7 -> 102222 | J7: 20000 | K7: 17912 | L7: =K7-H7 -> -204310 | M7: 10500 | O7: =N7-K7 -> -17912 | R7: =Q7-N7 -> 0 | U7: =T7-Q7 -> 0 | X7: =W7-T7 -> 0 | AA7: =Z7-W7 -> 0 | AD7: =AC7-Z7 -> 0 | AG7: =AF7-AC7 -> 0 | AJ7: =AI7-AF7 -> 0 | AM7: =AL7-AI7 -> 0 | AP7: =AO7-AL7 -> 0 | AS7: =AR7-AO7 -> 0 | AV7: =AU7-AR7 -> 0 | AY7: =AX7-AU7 -> 0 | BB7: =BA7-AX7 -> 0 | BE7: =BD7-BA7 -> 0 | BH7: =BG7-BD7 -> 0 | BK7: =BJ7-BG7 -> 0 | BN7: =BM7-BJ7 -> 0 | BQ7: =BP7-BM7 -> 0 | BT7: =BS7-BP7 -> 0 | BW7: =BV7-BS7 -> 0 | BZ7: =BY7-BV7 -> 0
C8: Водоканал горячая Тариф | G8: =G7/F7 -> 0.09000009 | J8: =J7/I7 -> 0.1956526 | M8: =M7/L7 -> -0.051392492 | P8: =P7/O7 -> 0 | S8: =S7/R7 -> #DIV/0! | V8: =V7/U7 -> #DIV/0! | Y8: =Y7/X7 -> #DIV/0! | AB8: =AB7/AA7 -> #DIV/0! | AE8: =AE7/AD7 -> #DIV/0! | AH8: =AH7/AG7 -> #DIV/0! | AK8: =AK7/AJ7 -> #DIV/0! | AN8: =AN7/AM7 -> #DIV/0! | AQ8: =AQ7/AP7 -> #DIV/0! | AT8: =AT7/AS7 -> #DIV/0! | AW8: =AW7/AV7 -> #DIV/0! | AZ8: =AZ7/AY7 -> #DIV/0! | BC8: =BC7/BB7 -> #DIV/0! | BF8: =BF7/BE7 -> #DIV/0! | BI8: =BI7/BH7 -> #DIV/0! | BL8: =BL7/BK7 -> #DIV/0! | BO8: =BO7/BN7 -> #DIV/0! | BR8: =BR7/BQ7 -> #DIV/0! | BU8: =BU7/BT7 -> #DIV/0! | BX8: =BX7/BW7 -> #DIV/0! | CA8: =CA7/BZ7 -> #DIV/0!
C9: Тепло | F9: 222222 | G9: 12000 | H9: 222222 | I9: 1000 | J9: 12000 | K9: 2000 | M9: 10000
C10: Тепло тариф | G10: =G9/$B3 -> 24.61791 | J10: =J9/$B3 -> 24.61791 | M10: =M9/$B3 -> 20.514925 | P10: =P9/$B3 -> 0 | S10: =S9/$B3 -> 0 | V10: =V9/$B3 -> 0 | Y10: =Y9/$B3 -> 0 | AB10: =AB9/$B3 -> 0 | AE10: =AE9/$B3 -> 0 | AH10: =AH9/$B3 -> 0 | AK10: =AK9/$B3 -> 0 | AN10: =AN9/$B3 -> 0 | AQ10: =AQ9/$B3 -> 0 | AT10: =AT9/$B3 -> 0 | AW10: =AW9/$B3 -> 0 | AZ10: =AZ9/$B3 -> 0 | BC10: =BC9/$B3 -> 0 | BF10: =BF9/$B3 -> 0 | BI10: =BI9/$B3 -> 0 | BL10: =BL9/$B3 -> 0 | BO10: =BO9/$B3 -> 0 | BR10: =BR9/$B3 -> 0 | BU10: =BU9/$B3 -> 0 | BX10: =BX9/$B3 -> 0 | CA10: =CA9/$B3 -> 0
C11: Экспл. Услуги от УК | G11: 85000 | H11: 222222 | I11: =J11/(Реестр!A20) -> #DIV/0! | J11: 85000 | L11: =M11/(Реестр!$A20) -> #DIV/0! | M11: 50000 | O11: =P11/(Реестр!$A20) -> #DIV/0! | R11: =S11/(Реестр!$A20) -> #DIV/0! | U11: =V11/(Реестр!$A20) -> #DIV/0! | X11: =Y11/(Реестр!$A20) -> #DIV/0! | AA11: =AB11/(Реестр!$A20) -> #DIV/0! | AD11: =AE11/(Реестр!$A20) -> #DIV/0! | AG11: =AH11/(Реестр!$A20) -> #DIV/0!
C12: Экспл. Услуги от УК тариф | G12: =G11/B5 -> 12142.857 | J12: =J11/$B3 -> 174.37686 | M12: =M11/$B3 -> 102.57462 | P12: =P11/$B3 -> 0 | S12: =S11/$B3 -> 0 | V12: =V11/$B3 -> 0 | Y12: =Y11/$B3 -> 0 | AB12: =AB11/$B3 -> 0 | AE12: =AE11/$B3 -> 0 | AH12: =AH11/$B3 -> 0 | AK12: =AK11/$B3 -> 0 | AN12: =AN11/$B3 -> 0 | AQ12: =AQ11/$B3 -> 0 | AT12: =AT11/$B3 -> 0 | AW12: =AW11/$B3 -> 0 | AZ12: =AZ11/$B3 -> 0 | BC12: =BC11/$B3 -> 0 | BF12: =BF11/$B3 -> 0 | BI12: =BI11/$B3 -> 0 | BL12: =BL11/$B3 -> 0 | BO12: =BO11/$B3 -> 0 | BR12: =BR11/$B3 -> 0 | BU12: =BU11/$B3 -> 0 | BX12: =BX11/$B3 -> 0 | CA12: =CA11/$B3 -> 0
B14: Физическое снятие показаний
B15: Из счёт фактуры должно подгятиваться
B16: Расчётные ячейки

Sheet К123,40
A1: ИНН | B1: =Реестр!D2 -> 444 | C1: Месяц | D1: 45962 | E1: 45992 | F1: Потребл. | G1: 45962 | H1: 46023 | I1: Потребл. | J1: 45992 | K1: 46054 | L1: Потребл. | M1: 46023 | N1: 46082 | O1: Потребл. | P1: 46054 | Q1: 46113 | R1: Потребл. | S1: 46082 | T1: 46143 | U1: Потребл. | V1: 46113 | W1: 46174 | X1: Потребл. | Y1: 46143 | Z1: 46204 | AA1: Потребл. | AB1: 46174 | AC1: 46235 | AD1: Потребл. | AE1: 46204 | AF1: 46266 | AG1: Потребл. | AH1: 46235 | AI1: 46296 | AJ1: Потребл. | AK1: 46266 | AL1: 46327 | AM1: Потребл. | AN1: 46296 | AO1: 46357 | AP1: Потребл. | AQ1: 46327 | AR1: 46388 | AS1: Потребл. | AT1: 46357 | AU1: 46419 | AV1: Потребл. | AW1: 46388 | AX1: 46447 | AY1: Потребл. | AZ1: 46419 | BA1: 46478 | BB1: Потребл. | BC1: 46447 | BD1: 46508 | BE1: Потребл. | BF1: 46478 | BG1: 46539 | BH1: Потребл. | BI1: 46508 | BJ1: 46569 | BK1: Потребл. | BL1: 46539 | BM1: 46600 | BN1: Потребл. | BO1: 46569 | BP1: 46631 | BQ1: Потребл. | BR1: 46600 | BS1: 46661 | BT1: Потребл. | BU1: 46631 | BV1: 46692 | BW1: Потребл. | BX1: 46661 | BY1: 46722 | BZ1: Потребл. | CA1: 46692 | CB1: 46753 | CC1: Потребл. | CD1: 46722
A2: Кадастр | B2: =Реестр!B2 -> 1006:3090 | D2: знач. | E2: знач. | F2: знач. | G2: руб. | H2: знач. | I2: знач. | J2: руб. | K2: знач. | L2: знач. | M2: руб. | N2: знач. | O2: знач | P2: руб. | Q2: знач. | R2: знач. | S2: руб. | T2: знач. | U2: знач. | V2: руб. | W2: знач. | X2: знач. | Y2: руб. | Z2: знач. | AA2: знач. | AB2: руб. | AC2: знач. | AD2: знач. | AE2: руб. | AF2: знач. | AG2: знач. | AH2: руб. | AI2: знач. | AJ2: знач. | AK2: руб. | AL2: знач. | AM2: знач. | AN2: руб. | AO2: знач. | AP2: знач. | AQ2: руб. | AR2: знач. | AS2: знач. | AT2: руб. | AU2: знач. | AV2: знач. | AW2: руб. | AX2: знач. | AY2: знач. | AZ2: руб. | BA2: знач. | BB2: знач. | BC2: руб. | BD2: знач. | BE2: знач. | BF2: руб. | BG2: знач. | BH2: знач. | BI2: руб. | BJ2: знач. | BK2: знач. | BL2: руб. | BM2: знач. | BN2: знач. | BO2: руб. | BP2: знач. | BQ2: знач. | BR2: руб. | BS2: знач. | BT2: знач. | BU2: руб. | BV2: знач. | BW2: знач. | BX2: руб. | BY2: знач. | BZ2: знач. | CA2: руб. | CB2: знач. | CC2: знач. | CD2: руб.
A3: Арендатор | B3: =Реестр!F2 -> Гареева А.В. | C3: Электричество | F3: =E3-D3 -> 0 | G3: =F3*G4 -> 0 | I3: =H3-E3 -> 0 | J3: =I3*J4 -> 0 | K3: 333333 | L3: =K3-H3 -> 333333 | M3: =L3*M4 -> 3058.1009 | O3: =N3-K3 -> -333333 | P3: =O3*P4 -> 0 | R3: =Q3-N3 -> 0 | S3: =R3*S4 -> #DIV/0! | U3: =T3-Q3 -> 0 | V3: =U3*V4 -> #DIV/0! | X3: =W3-T3 -> 0 | Y3: =X3*Y4 -> #DIV/0! | AA3: =Z3-W3 -> 0 | AB3: =AA3*AB4 -> #DIV/0! | AD3: =AC3-Z3 -> 0 | AE3: =AD3*AE4 -> #DIV/0! | AG3: =AF3-AC3 -> 0 | AH3: =AG3*AH4 -> #DIV/0! | AJ3: =AI3-AF3 -> 0 | AK3: =AJ3*AK4 -> #DIV/0! | AM3: =AL3-AI3 -> 0 | AN3: =AM3*AN4 -> #DIV/0! | AP3: =AO3-AL3 -> 0 | AQ3: =AP3*AQ4 -> #DIV/0! | AS3: =AR3-AO3 -> 0 | AT3: =AS3*AT4 -> #DIV/0! | AV3: =AU3-AR3 -> 0 | AW3: =AV3*AW4 -> #DIV/0! | AY3: =AX3-AU3 -> 0 | AZ3: =AY3*AZ4 -> #DIV/0! | BB3: =BA3-AX3 -> 0 | BC3: =BB3*BC4 -> #DIV/0! | BE3: =BD3-BA3 -> 0 | BF3: =BE3*BF4 -> #DIV/0! | BH3: =BG3-BD3 -> 0 | BI3: =BH3*BI4 -> #DIV/0! | BK3: =BJ3-BG3 -> 0 | BL3: =BK3*BL4 -> #DIV/0! | BN3: =BM3-BJ3 -> 0 | BO3: =BN3*BO4 -> #DIV/0! | BQ3: =BP3-BM3 -> 0 | BR3: =BQ3*BR4 -> #DIV/0! | BT3: =BS3-BP3 -> 0 | BU3: =BT3*BU4 -> #DIV/0! | BW3: =BV3-BS3 -> 0 | BX3: =BW3*BX4 -> #DIV/0! | BZ3: =BY3-BV3 -> 0 | CA3: =BZ3*CA4 -> #DIV/0! | CC3: =CB3-BY3 -> 0 | CD3: =CC3*CD4 -> 0
A4: Площадь | B4: =Реестр!H2 -> 123.4 | C4: Электричество тариф | G4: ='0. ГИРА'!G4 -> 0.045000045 | J4: ='0. ГИРА'!J4 -> 0.1956526 | M4: ='0. ГИРА'!M4 -> 0.0091743119 | P4: ='0. ГИРА'!P4 -> 0 | S4: ='0. ГИРА'!S4 -> #DIV/0! | V4: ='0. ГИРА'!V4 -> #DIV/0! | Y4: ='0. ГИРА'!Y4 -> #DIV/0! | AB4: ='0. ГИРА'!AB4 -> #DIV/0! | AE4: ='0. ГИРА'!AE4 -> #DIV/0! | AH4: ='0. ГИРА'!AH4 -> #DIV/0! | AK4: ='0. ГИРА'!AK4 -> #DIV/0! | AN4: ='0. ГИРА'!AN4 -> #DIV/0! | AQ4: ='0. ГИРА'!AQ4 -> #DIV/0! | AT4: ='0. ГИРА'!AT4 -> #DIV/0! | AW4: ='0. ГИРА'!AW4 -> #DIV/0! | AZ4: ='0. ГИРА'!AZ4 -> #DIV/0! | BC4: ='0. ГИРА'!BC4 -> #DIV/0! | BF4: ='0. ГИРА'!BF4 -> #DIV/0! | BI4: ='0. ГИРА'!BI4 -> #DIV/0! | BL4: ='0. ГИРА'!BL4 -> #DIV/0! | BO4: ='0. ГИРА'!BO4 -> #DIV/0! | BR4: ='0. ГИРА'!BR4 -> #DIV/0! | BU4: ='0. ГИРА'!BU4 -> #DIV/0! | BX4: ='0. ГИРА'!BX4 -> #DIV/0! | CA4: ='0. ГИРА'!CA4 -> #DIV/0! | CD4: ='0. ГИРА'!CD4 -> 0
C5: Водоканал холодная вода | F5: =E5-D5 -> 0 | I5: =H5-E5 -> 0 | K5: 11111 | L5: =K5-H5 -> 11111 | O5: =N5-K5 -> -11111 | R5: =Q5-N5 -> 0 | U5: =T5-Q5 -> 0 | X5: =W5-T5 -> 0 | AA5: =Z5-W5 -> 0 | AD5: =AC5-Z5 -> 0 | AG5: =AF5-AC5 -> 0 | AJ5: =AI5-AF5 -> 0 | AM5: =AL5-AI5 -> 0 | AP5: =AO5-AL5 -> 0 | AS5: =AR5-AO5 -> 0 | AV5: =AU5-AR5 -> 0 | AY5: =AX5-AU5 -> 0 | BB5: =BA5-AX5 -> 0 | BE5: =BD5-BA5 -> 0 | BH5: =BG5-BD5 -> 0 | BK5: =BJ5-BG5 -> 0 | BN5: =BM5-BJ5 -> 0 | BQ5: =BP5-BM5 -> 0 | BT5: =BS5-BP5 -> 0 | BW5: =BV5-BS5 -> 0 | BZ5: =BY5-BV5 -> 0 | CC5: =CB5-BY5 -> 0
A6: Имя 1 | B6: =Реестр!M2 -> Альфия | C6: Водоканал холодная Тариф | G6: ='0. ГИРА'!G6 -> 0.067500068 | J6: ='0. ГИРА'!J6 -> 0.14673945 | M6: ='0. ГИРА'!M6 -> -0.011069527 | P6: ='0. ГИРА'!P6 -> 0 | S6: ='0. ГИРА'!S6 -> #DIV/0! | V6: ='0. ГИРА'!V6 -> #DIV/0! | Y6: ='0. ГИРА'!Y6 -> #DIV/0! | AB6: ='0. ГИРА'!AB6 -> #DIV/0! | AE6: ='0. ГИРА'!AE6 -> #DIV/0! | AH6: ='0. ГИРА'!AH6 -> #DIV/0! | AK6: ='0. ГИРА'!AK6 -> #DIV/0! | AN6: ='0. ГИРА'!AN6 -> #DIV/0! | AQ6: ='0. ГИРА'!AQ6 -> #DIV/0! | AT6: ='0. ГИРА'!AT6 -> #DIV/0! | AW6: ='0. ГИРА'!AW6 -> #DIV/0! | AZ6: ='0. ГИРА'!AZ6 -> #DIV/0! | BC6: ='0. ГИРА'!BC6 -> #DIV/0! | BF6: ='0. ГИРА'!BF6 -> #DIV/0! | BI6: ='0. ГИРА'!BI6 -> #DIV/0! | BL6: ='0. ГИРА'!BL6 -> #DIV/0! | BO6: ='0. ГИРА'!BO6 -> #DIV/0! | BR6: ='0. ГИРА'!BR6 -> #DIV/0! | BU6: ='0. ГИРА'!BU6 -> #DIV/0! | BX6: ='0. ГИРА'!BX6 -> #DIV/0! | CA6: ='0. ГИРА'!CA6 -> #DIV/0! | CD6: ='0. ГИРА'!CD6 -> 0
A7: Контакт 1 | B7: =Реестр!N2 -> 89503228511 | C7: Водоканал горячая вода | F7: =E7-D7 -> 0 | G7: =G8*F7 -> 0 | I7: =H7-E7 -> 0 | J7: =J8*I7 -> 0 | K7: 22222 | L7: =K7-H7 -> 22222 | M7: =M8*L7 -> -1142.044 | O7: =N7-K7 -> -22222 | P7: =P8*O7 -> 0 | R7: =Q7-N7 -> 0 | S7: =S8*R7 -> #DIV/0! | U7: =T7-Q7 -> 0 | V7: =V8*U7 -> #DIV/0! | X7: =W7-T7 -> 0 | Y7: =Y8*X7 -> #DIV/0! | AA7: =Z7-W7 -> 0 | AB7: =AB8*AA7 -> #DIV/0! | AD7: =AC7-Z7 -> 0 | AE7: =AE8*AD7 -> #DIV/0! | AG7: =AF7-AC7 -> 0 | AH7: =AH8*AG7 -> #DIV/0! | AJ7: =AI7-AF7 -> 0 | AK7: =AK8*AJ7 -> #DIV/0! | AM7: =AL7-AI7 -> 0 | AN7: =AN8*AM7 -> #DIV/0! | AP7: =AO7-AL7 -> 0 | AQ7: =AQ8*AP7 -> #DIV/0! | AS7: =AR7-AO7 -> 0 | AT7: =AT8*AS7 -> #DIV/0! | AV7: =AU7-AR7 -> 0 | AW7: =AW8*AV7 -> #DIV/0! | AY7: =AX7-AU7 -> 0 | AZ7: =AZ8*AY7 -> #DIV/0! | BB7: =BA7-AX7 -> 0 | BC7: =BC8*BB7 -> #DIV/0! | BE7: =BD7-BA7 -> 0 | BF7: =BF8*BE7 -> #DIV/0! | BH7: =BG7-BD7 -> 0 | BI7: =BI8*BH7 -> #DIV/0! | BK7: =BJ7-BG7 -> 0 | BL7: =BL8*BK7 -> #DIV/0! | BN7: =BM7-BJ7 -> 0 | BO7: =BO8*BN7 -> #DIV/0! | BQ7: =BP7-BM7 -> 0 | BR7: =BR8*BQ7 -> #DIV/0! | BT7: =BS7-BP7 -> 0 | BU7: =BU8*BT7 -> #DIV/0! | BW7: =BV7-BS7 -> 0 | BX7: =BX8*BW7 -> #DIV/0! | BZ7: =BY7-BV7 -> 0 | CA7: =CA8*BZ7 -> #DIV/0! | CC7: =CB7-BY7 -> 0 | CD7: =CD8*CC7 -> 0
A8: Имя 2 | B8: =Реестр!O2 -> Карина | C8: Водоканал горячая Тариф | G8: ='0. ГИРА'!G8 -> 0.09000009 | J8: ='0. ГИРА'!J8 -> 0.1956526 | M8: ='0. ГИРА'!M8 -> -0.051392492 | P8: ='0. ГИРА'!P8 -> 0 | S8: ='0. ГИРА'!S8 -> #DIV/0! | V8: ='0. ГИРА'!V8 -> #DIV/0! | Y8: ='0. ГИРА'!Y8 -> #DIV/0! | AB8: ='0. ГИРА'!AB8 -> #DIV/0! | AE8: ='0. ГИРА'!AE8 -> #DIV/0! | AH8: ='0. ГИРА'!AH8 -> #DIV/0! | AK8: ='0. ГИРА'!AK8 -> #DIV/0! | AN8: ='0. ГИРА'!AN8 -> #DIV/0! | AQ8: ='0. ГИРА'!AQ8 -> #DIV/0! | AT8: ='0. ГИРА'!AT8 -> #DIV/0! | AW8: ='0. ГИРА'!AW8 -> #DIV/0! | AZ8: ='0. ГИРА'!AZ8 -> #DIV/0! | BC8: ='0. ГИРА'!BC8 -> #DIV/0! | BF8: ='0. ГИРА'!BF8 -> #DIV/0! | BI8: ='0. ГИРА'!BI8 -> #DIV/0! | BL8: ='0. ГИРА'!BL8 -> #DIV/0! | BO8: ='0. ГИРА'!BO8 -> #DIV/0! | BR8: ='0. ГИРА'!BR8 -> #DIV/0! | BU8: ='0. ГИРА'!BU8 -> #DIV/0! | BX8: ='0. ГИРА'!BX8 -> #DIV/0! | CA8: ='0. ГИРА'!CA8 -> #DIV/0! | CD8: ='0. ГИРА'!CD8 -> 0
A9: Контакт 2 | B9: =Реестр!P2 -> 89372840305 | C9: Тепло | F9: =E9-D9 -> 0 | G9: =G10*B4 -> 3037.85 | I9: =H9-E9 -> 0 | J9: =J10*E3 -> 0 | L9: =K9-H9 -> 0 | M9: =M10*H3 -> 0 | O9: =N9-K9 -> 0 | P9: =P10*K3 -> 0 | R9: =Q9-N9 -> 0 | S9: =S10*N3 -> 0 | U9: =T9-Q9 -> 0 | V9: =V10*Q3 -> 0 | X9: =W9-T9 -> 0 | Y9: =Y10*T3 -> 0 | AA9: =Z9-W9 -> 0 | AB9: =AB10*W3 -> 0 | AD9: =AC9-Z9 -> 0 | AE9: =AE10*Z3 -> 0 | AG9: =AF9-AC9 -> 0 | AH9: =AH10*AC3 -> 0 | AJ9: =AI9-AF9 -> 0 | AK9: =AK10*AF3 -> 0 | AM9: =AL9-AI9 -> 0 | AN9: =AN10*AI3 -> 0 | AP9: =AO9-AL9 -> 0 | AQ9: =AQ10*AL3 -> 0 | AS9: =AR9-AO9 -> 0 | AT9: =AT10*AO3 -> 0 | AV9: =AU9-AR9 -> 0 | AW9: =AW10*AR3 -> 0 | AY9: =AX9-AU9 -> 0 | AZ9: =AZ10*AU3 -> 0 | BB9: =BA9-AX9 -> 0 | BC9: =BC10*AX3 -> 0 | BE9: =BD9-BA9 -> 0 | BF9: =BF10*BA3 -> 0 | BH9: =BG9-BD9 -> 0 | BI9: =BI10*BD3 -> 0 | BK9: =BJ9-BG9 -> 0 | BL9: =BL10*BG3 -> 0 | BN9: =BM9-BJ9 -> 0 | BO9: =BO10*BJ3 -> 0 | BQ9: =BP9-BM9 -> 0 | BR9: =BR10*BM3 -> 0 | BT9: =BS9-BP9 -> 0 | BU9: =BU10*BP3 -> 0 | BW9: =BV9-BS9 -> 0 | BX9: =BX10*BS3 -> 0 | BZ9: =BY9-BV9 -> 0 | CA9: =CA10*BV3 -> 0 | CC9: =CB9-BY9 -> 0 | CD9: =CD10*BY3 -> 0
C10: Тепло тариф | G10: ='0. ГИРА'!G10 -> 24.61791 | J10: ='0. ГИРА'!J10 -> 24.61791 | M10: ='0. ГИРА'!M10 -> 20.514925 | P10: ='0. ГИРА'!P10 -> 0 | S10: ='0. ГИРА'!S10 -> 0 | V10: ='0. ГИРА'!V10 -> 0 | Y10: ='0. ГИРА'!Y10 -> 0 | AB10: ='0. ГИРА'!AB10 -> 0 | AE10: ='0. ГИРА'!AE10 -> 0 | AH10: ='0. ГИРА'!AH10 -> 0 | AK10: ='0. ГИРА'!AK10 -> 0 | AN10: ='0. ГИРА'!AN10 -> 0 | AQ10: ='0. ГИРА'!AQ10 -> 0 | AT10: ='0. ГИРА'!AT10 -> 0 | AW10: ='0. ГИРА'!AW10 -> 0 | AZ10: ='0. ГИРА'!AZ10 -> 0 | BC10: ='0. ГИРА'!BC10 -> 0 | BF10: ='0. ГИРА'!BF10 -> 0 | BI10: ='0. ГИРА'!BI10 -> 0 | BL10: ='0. ГИРА'!BL10 -> 0 | BO10: ='0. ГИРА'!BO10 -> 0 | BR10: ='0. ГИРА'!BR10 -> 0 | BU10: ='0. ГИРА'!BU10 -> 0 | BX10: ='0. ГИРА'!BX10 -> 0 | CA10: ='0. ГИРА'!CA10 -> 0 | CD10: ='0. ГИРА'!CD10 -> 0
A11: Номер счетчика | C11: Экспл. Услуги от УК | F11: =E11-D11 -> 0 | I11: =H11-E11 -> 0 | J11: =J12*E3 -> 0 | L11: =K11-H11 -> 0 | M11: =M12*H3 -> 0 | O11: =N11-K11 -> 0 | P11: =P12*K3 -> 0 | R11: =Q11-N11 -> 0 | S11: =S12*N3 -> 0 | U11: =T11-Q11 -> 0 | V11: =V12*Q3 -> 0 | X11: =W11-T11 -> 0 | Y11: =Y12*T3 -> 0 | AA11: =Z11-W11 -> 0 | AB11: =AB12*W3 -> 0 | AD11: =AC11-Z11 -> 0 | AE11: =AE12*Z3 -> 0 | AG11: =AF11-AC11 -> 0 | AH11: =AH12*AC3 -> 0 | AJ11: =AI11-AF11 -> 0 | AK11: =AK12*AF3 -> 0 | AM11: =AL11-AI11 -> 0 | AN11: =AN12*AI3 -> 0 | AP11: =AO11-AL11 -> 0 | AQ11: =AQ12*AL3 -> 0 | AS11: =AR11-AO11 -> 0 | AT11: =AT12*AO3 -> 0 | AV11: =AU11-AR11 -> 0 | AW11: =AW12*AR3 -> 0 | AY11: =AX11-AU11 -> 0 | AZ11: =AZ12*AU3 -> 0 | BB11: =BA11-AX11 -> 0 | BC11: =BC12*AX3 -> 0 | BE11: =BD11-BA11 -> 0 | BF11: =BF12*BA3 -> 0 | BH11: =BG11-BD11 -> 0 | BI11: =BI12*BD3 -> 0 | BK11: =BJ11-BG11 -> 0 | BL11: =BL12*BG3 -> 0 | BN11: =BM11-BJ11 -> 0 | BO11: =BO12*BJ3 -> 0 | BQ11: =BP11-BM11 -> 0 | BR11: =BR12*BM3 -> 0 | BT11: =BS11-BP11 -> 0 | BU11: =BU12*BP3 -> 0 | BW11: =BV11-BS11 -> 0 | BX11: =BX12*BS3 -> 0 | BZ11: =BY11-BV11 -> 0 | CA11: =CA12*BV3 -> 0 | CC11: =CB11-BY11 -> 0 | CD11: =CD12*BY3 -> 0
C12: Экспл. Услуги от УК тариф | G12: ='0. ГИРА'!G12 -> 12142.857 | J12: ='0. ГИРА'!J12 -> 174.37686 | M12: ='0. ГИРА'!M12 -> 102.57462 | P12: ='0. ГИРА'!P12 -> 0 | S12: ='0. ГИРА'!S12 -> 0 | V12: ='0. ГИРА'!V12 -> 0 | Y12: ='0. ГИРА'!Y12 -> 0 | AB12: ='0. ГИРА'!AB12 -> 0 | AE12: ='0. ГИРА'!AE12 -> 0 | AH12: ='0. ГИРА'!AH12 -> 0 | AK12: ='0. ГИРА'!AK12 -> 0 | AN12: ='0. ГИРА'!AN12 -> 0 | AQ12: ='0. ГИРА'!AQ12 -> 0 | AT12: ='0. ГИРА'!AT12 -> 0 | AW12: ='0. ГИРА'!AW12 -> 0 | AZ12: ='0. ГИРА'!AZ12 -> 0 | BC12: ='0. ГИРА'!BC12 -> 0 | BF12: ='0. ГИРА'!BF12 -> 0 | BI12: ='0. ГИРА'!BI12 -> 0 | BL12: ='0. ГИРА'!BL12 -> 0 | BO12: ='0. ГИРА'!BO12 -> 0 | BR12: ='0. ГИРА'!BR12 -> 0 | BU12: ='0. ГИРА'!BU12 -> 0 | BX12: ='0. ГИРА'!BX12 -> 0 | CA12: ='0. ГИРА'!CA12 -> 0 | CD12: ='0. ГИРА'!CD12 -> 0

Sheet К102,60
A1: ИНН | B1: =Реестр!D3 -> 111 | C1: Месяц | D1: 45962 | E1: 45992 | F1: Потребл. | G1: 45962 | H1: 46023 | I1: Потребл. | J1: 45992 | K1: 46054 | L1: Потребл. | M1: 46023 | N1: 46082 | O1: Потребл. | P1: 46054 | Q1: 46113 | R1: Потребл. | S1: 46082 | T1: 46143 | U1: Потребл. | V1: 46113 | W1: 46174 | X1: Потребл. | Y1: 46143 | Z1: 46204 | AA1: Потребл. | AB1: 46174 | AC1: 46235 | AD1: Потребл. | AE1: 46204 | AF1: 46266 | AG1: Потребл. | AH1: 46235 | AI1: 46296 | AJ1: Потребл. | AK1: 46266 | AL1: 46327 | AM1: Потребл. | AN1: 46296 | AO1: 46357 | AP1: Потребл. | AQ1: 46327 | AR1: 46388 | AS1: Потребл. | AT1: 46357 | AU1: 46419 | AV1: Потребл. | AW1: 46388 | AX1: 46447 | AY1: Потребл. | AZ1: 46419 | BA1: 46478 | BB1: Потребл. | BC1: 46447 | BD1: 46508 | BE1: Потребл. | BF1: 46478 | BG1: 46539 | BH1: Потребл. | BI1: 46508 | BJ1: 46569 | BK1: Потребл. | BL1: 46539 | BM1: 46600 | BN1: Потребл. | BO1: 46569 | BP1: 46631 | BQ1: Потребл. | BR1: 46600 | BS1: 46661 | BT1: Потребл. | BU1: 46631 | BV1: 46692 | BW1: Потребл. | BX1: 46661 | BY1: 46722 | BZ1: Потребл. | CA1: 46692 | CB1: 46753 | CC1: Потребл. | CD1: 46722
A2: Кадастр | B2: =Реестр!B3 -> 1006:3090 | D2: знач. | E2: знач. | F2: знач. | G2: руб. | H2: знач. | I2: знач. | J2: руб. | K2: знач. | L2: знач. | M2: руб. | N2: знач. | O2: знач | P2: руб. | Q2: знач. | R2: знач. | S2: руб. | T2: знач. | U2: знач. | V2: руб. | W2: знач. | X2: знач. | Y2: руб. | Z2: знач. | AA2: знач. | AB2: руб. | AC2: знач. | AD2: знач. | AE2: руб. | AF2: знач. | AG2: знач. | AH2: руб. | AI2: знач. | AJ2: знач. | AK2: руб. | AL2: знач. | AM2: знач. | AN2: руб. | AO2: знач. | AP2: знач. | AQ2: руб. | AR2: знач. | AS2: знач. | AT2: руб. | AU2: знач. | AV2: знач. | AW2: руб. | AX2: знач. | AY2: знач. | AZ2: руб. | BA2: знач. | BB2: знач. | BC2: руб. | BD2: знач. | BE2: знач. | BF2: руб. | BG2: знач. | BH2: знач. | BI2: руб. | BJ2: знач. | BK2: знач. | BL2: руб. | BM2: знач. | BN2: знач. | BO2: руб. | BP2: знач. | BQ2: знач. | BR2: руб. | BS2: знач. | BT2: знач. | BU2: руб. | BV2: знач. | BW2: знач. | BX2: руб. | BY2: знач. | BZ2: знач. | CA2: руб. | CB2: знач. | CC2: знач. | CD2: руб.
A3: Арендатор | B3: =Реестр!F3 -> Гарипов И.К. | C3: Электричество | F3: =E3-D3 -> 0 | G3: =F3*G4 -> 0 | H3: 200000 | I3: =H3-E3 -> 200000 | J3: =I3*J4 -> 39130.52 | K3: 678766 | L3: =K3-H3 -> 478766 | M3: =L3*M4 -> 4392.3486 | O3: =N3-K3 -> -678766 | P3: =O3*P4 -> 0 | R3: =Q3-N3 -> 0 | S3: =R3*S4 -> #DIV/0! | U3: =T3-Q3 -> 0 | V3: =U3*V4 -> #DIV/0! | X3: =W3-T3 -> 0 | Y3: =X3*Y4 -> #DIV/0! | AA3: =Z3-W3 -> 0 | AB3: =AA3*AB4 -> #DIV/0! | AD3: =AC3-Z3 -> 0 | AE3: =AD3*AE4 -> #DIV/0! | AG3: =AF3-AC3 -> 0 | AH3: =AG3*AH4 -> #DIV/0! | AJ3: =AI3-AF3 -> 0 | AK3: =AJ3*AK4 -> #DIV/0! | AM3: =AL3-AI3 -> 0 | AN3: =AM3*AN4 -> #DIV/0! | AP3: =AO3-AL3 -> 0 | AQ3: =AP3*AQ4 -> #DIV/0! | AS3: =AR3-AO3 -> 0 | AT3: =AS3*AT4 -> #DIV/0! | AV3: =AU3-AR3 -> 0 | AW3: =AV3*AW4 -> #DIV/0! | AY3: =AX3-AU3 -> 0 | AZ3: =AY3*AZ4 -> #DIV/0! | BB3: =BA3-AX3 -> 0 | BC3: =BB3*BC4 -> #DIV/0! | BE3: =BD3-BA3 -> 0 | BF3: =BE3*BF4 -> #DIV/0! | BH3: =BG3-BD3 -> 0 | BI3: =BH3*BI4 -> #DIV/0! | BK3: =BJ3-BG3 -> 0 | BL3: =BK3*BL4 -> #DIV/0! | BN3: =BM3-BJ3 -> 0 | BO3: =BN3*BO4 -> #DIV/0! | BQ3: =BP3-BM3 -> 0 | BR3: =BQ3*BR4 -> #DIV/0! | BT3: =BS3-BP3 -> 0 | BU3: =BT3*BU4 -> #DIV/0! | BW3: =BV3-BS3 -> 0 | BX3: =BW3*BX4 -> #DIV/0! | BZ3: =BY3-BV3 -> 0 | CA3: =BZ3*CA4 -> #DIV/0! | CC3: =CB3-BY3 -> 0 | CD3: =CC3*CD4 -> 0
A4: Площадь | B4: =Реестр!H3 -> 102.6 | C4: Электричество тариф | G4: ='0. ГИРА'!G4 -> 0.045000045 | J4: ='0. ГИРА'!J4 -> 0.1956526 | M4: ='0. ГИРА'!M4 -> 0.0091743119 | P4: ='0. ГИРА'!P4 -> 0 | S4: ='0. ГИРА'!S4 -> #DIV/0! | V4: ='0. ГИРА'!V4 -> #DIV/0! | Y4: ='0. ГИРА'!Y4 -> #DIV/0! | AB4: ='0. ГИРА'!AB4 -> #DIV/0! | AE4: ='0. ГИРА'!AE4 -> #DIV/0! | AH4: ='0. ГИРА'!AH4 -> #DIV/0! | AK4: ='0. ГИРА'!AK4 -> #DIV/0! | AN4: ='0. ГИРА'!AN4 -> #DIV/0! | AQ4: ='0. ГИРА'!AQ4 -> #DIV/0! | AT4: ='0. ГИРА'!AT4 -> #DIV/0! | AW4: ='0. ГИРА'!AW4 -> #DIV/0! | AZ4: ='0. ГИРА'!AZ4 -> #DIV/0! | BC4: ='0. ГИРА'!BC4 -> #DIV/0! | BF4: ='0. ГИРА'!BF4 -> #DIV/0! | BI4: ='0. ГИРА'!BI4 -> #DIV/0! | BL4: ='0. ГИРА'!BL4 -> #DIV/0! | BO4: ='0. ГИРА'!BO4 -> #DIV/0! | BR4: ='0. ГИРА'!BR4 -> #DIV/0! | BU4: ='0. ГИРА'!BU4 -> #DIV/0! | BX4: ='0. ГИРА'!BX4 -> #DIV/0! | CA4: ='0. ГИРА'!CA4 -> #DIV/0! | CD4: ='0. ГИРА'!CD4 -> 0
C5: Водоканал холодная вода | F5: =E5-D5 -> 0 | H5: 20000 | I5: =H5-E5 -> 20000 | J5: =I5*J6 -> 2934.789 | K5: 11111 | L5: =K5-H5 -> -8889 | M5: =L5*M6 -> 98.397027 | O5: =N5-K5 -> -11111 | R5: =Q5-N5 -> 0 | U5: =T5-Q5 -> 0 | X5: =W5-T5 -> 0 | AA5: =Z5-W5 -> 0 | AD5: =AC5-Z5 -> 0 | AG5: =AF5-AC5 -> 0 | AJ5: =AI5-AF5 -> 0 | AM5: =AL5-AI5 -> 0 | AP5: =AO5-AL5 -> 0 | AS5: =AR5-AO5 -> 0 | AV5: =AU5-AR5 -> 0 | AY5: =AX5-AU5 -> 0 | BB5: =BA5-AX5 -> 0 | BE5: =BD5-BA5 -> 0 | BH5: =BG5-BD5 -> 0 | BK5: =BJ5-BG5 -> 0 | BN5: =BM5-BJ5 -> 0 | BQ5: =BP5-BM5 -> 0 | BT5: =BS5-BP5 -> 0 | BW5: =BV5-BS5 -> 0 | BZ5: =BY5-BV5 -> 0 | CC5: =CB5-BY5 -> 0
A6: Имя 1 | B6: =Реестр!M3 -> Ильнар | C6: Водоканал холодная Тариф | G6: ='0. ГИРА'!G6 -> 0.067500068 | J6: ='0. ГИРА'!J6 -> 0.14673945 | M6: ='0. ГИРА'!M6 -> -0.011069527 | P6: ='0. ГИРА'!P6 -> 0 | S6: ='0. ГИРА'!S6 -> #DIV/0! | V6: ='0. ГИРА'!V6 -> #DIV/0! | Y6: ='0. ГИРА'!Y6 -> #DIV/0! | AB6: ='0. ГИРА'!AB6 -> #DIV/0! | AE6: ='0. ГИРА'!AE6 -> #DIV/0! | AH6: ='0. ГИРА'!AH6 -> #DIV/0! | AK6: ='0. ГИРА'!AK6 -> #DIV/0! | AN6: ='0. ГИРА'!AN6 -> #DIV/0! | AQ6: ='0. ГИРА'!AQ6 -> #DIV/0! | AT6: ='0. ГИРА'!AT6 -> #DIV/0! | AW6: ='0. ГИРА'!AW6 -> #DIV/0! | AZ6: ='0. ГИРА'!AZ6 -> #DIV/0! | BC6: ='0. ГИРА'!BC6 -> #DIV/0! | BF6: ='0. ГИРА'!BF6 -> #DIV/0! | BI6: ='0. ГИРА'!BI6 -> #DIV/0! | BL6: ='0. ГИРА'!BL6 -> #DIV/0! | BO6: ='0. ГИРА'!BO6 -> #DIV/0! | BR6: ='0. ГИРА'!BR6 -> #DIV/0! | BU6: ='0. ГИРА'!BU6 -> #DIV/0! | BX6: ='0. ГИРА'!BX6 -> #DIV/0! | CA6: ='0. ГИРА'!CA6 -> #DIV/0! | CD6: ='0. ГИРА'!CD6 -> 0
A7: Контакт 1 | B7: =Реестр!N3 -> 89053164414 | C7: Водоканал горячая вода | F7: =E7-D7 -> 0 | G7: =G8*F7 -> 0 | H7: 20000 | I7: =H7-E7 -> 20000 | J7: =J8*I7 -> 3913.052 | K7: 67656 | L7: =K7-H7 -> 47656 | M7: =M8*L7 -> -2449.1606 | O7: =N7-K7 -> -67656 | P7: =P8*O7 -> 0 | R7: =Q7-N7 -> 0 | S7: =S8*R7 -> #DIV/0! | U7: =T7-Q7 -> 0 | V7: =V8*U7 -> #DIV/0! | X7: =W7-T7 -> 0 | Y7: =Y8*X7 -> #DIV/0! | AA7: =Z7-W7 -> 0 | AB7: =AB8*AA7 -> #DIV/0! | AD7: =AC7-Z7 -> 0 | AE7: =AE8*AD7 -> #DIV/0! | AG7: =AF7-AC7 -> 0 | AH7: =AH8*AG7 -> #DIV/0! | AJ7: =AI7-AF7 -> 0 | AK7: =AK8*AJ7 -> #DIV/0! | AM7: =AL7-AI7 -> 0 | AN7: =AN8*AM7 -> #DIV/0! | AP7: =AO7-AL7 -> 0 | AQ7: =AQ8*AP7 -> #DIV/0! | AS7: =AR7-AO7 -> 0 | AT7: =AT8*AS7 -> #DIV/0! | AV7: =AU7-AR7 -> 0 | AW7: =AW8*AV7 -> #DIV/0! | AY7: =AX7-AU7 -> 0 | AZ7: =AZ8*AY7 -> #DIV/0! | BB7: =BA7-AX7 -> 0 | BC7: =BC8*BB7 -> #DIV/0! | BE7: =BD7-BA7 -> 0 | BF7: =BF8*BE7 -> #DIV/0! | BH7: =BG7-BD7 -> 0 | BI7: =BI8*BH7 -> #DIV/0! | BK7: =BJ7-BG7 -> 0 | BL7: =BL8*BK7 -> #DIV/0! | BN7: =BM7-BJ7 -> 0 | BO7: =BO8*BN7 -> #DIV/0! | BQ7: =BP7-BM7 -> 0 | BR7: =BR8*BQ7 -> #DIV/0! | BT7: =BS7-BP7 -> 0 | BU7: =BU8*BT7 -> #DIV/0! | BW7: =BV7-BS7 -> 0 | BX7: =BX8*BW7 -> #DIV/0! | BZ7: =BY7-BV7 -> 0 | CA7: =CA8*BZ7 -> #DIV/0! | CC7: =CB7-BY7 -> 0 | CD7: =CD8*CC7 -> 0
A8: Имя 2 | B8: =Реестр!O3 -> - | C8: Водоканал горячая Тариф | G8: ='0. ГИРА'!G8 -> 0.09000009 | J8: ='0. ГИРА'!J8 -> 0.1956526 | M8: ='0. ГИРА'!M8 -> -0.051392492 | P8: ='0. ГИРА'!P8 -> 0 | S8: ='0. ГИРА'!S8 -> #DIV/0! | V8: ='0. ГИРА'!V8 -> #DIV/0! | Y8: ='0. ГИРА'!Y8 -> #DIV/0! | AB8: ='0. ГИРА'!AB8 -> #DIV/0! | AE8: ='0. ГИРА'!AE8 -> #DIV/0! | AH8: ='0. ГИРА'!AH8 -> #DIV/0! | AK8: ='0. ГИРА'!AK8 -> #DIV/0! | AN8: ='0. ГИРА'!AN8 -> #DIV/0! | AQ8: ='0. ГИРА'!AQ8 -> #DIV/0! | AT8: ='0. ГИРА'!AT8 -> #DIV/0! | AW8: ='0. ГИРА'!AW8 -> #DIV/0! | AZ8: ='0. ГИРА'!AZ8 -> #DIV/0! | BC8: ='0. ГИРА'!BC8 -> #DIV/0! | BF8: ='0. ГИРА'!BF8 -> #DIV/0! | BI8: ='0. ГИРА'!BI8 -> #DIV/0! | BL8: ='0. ГИРА'!BL8 -> #DIV/0! | BO8: ='0. ГИРА'!BO8 -> #DIV/0! | BR8: ='0. ГИРА'!BR8 -> #DIV/0! | BU8: ='0. ГИРА'!BU8 -> #DIV/0! | BX8: ='0. ГИРА'!BX8 -> #DIV/0! | CA8: ='0. ГИРА'!CA8 -> #DIV/0! | CD8: ='0. ГИРА'!CD8 -> 0
A9: Контакт 2 | B9: =Реестр!P3 -> - | C9: Тепло | F9: =E9-D9 -> 0 | G9: =G10*B3 -> #VALUE! | I9: =H9-E9 -> 0 | J9: =J10*E3 -> 0 | K9: 1234 | L9: =K9-H9 -> 1234 | M9: 12 | O9: =N9-K9 -> -1234 | P9: =P10*K3 -> 0 | R9: =Q9-N9 -> 0 | S9: =S10*N3 -> 0 | U9: =T9-Q9 -> 0 | V9: =V10*Q3 -> 0 | X9: =W9-T9 -> 0 | Y9: =Y10*T3 -> 0 | AA9: =Z9-W9 -> 0 | AB9: =AB10*W3 -> 0 | AD9: =AC9-Z9 -> 0 | AE9: =AE10*Z3 -> 0 | AG9: =AF9-AC9 -> 0 | AH9: =AH10*AC3 -> 0 | AJ9: =AI9-AF9 -> 0 | AK9: =AK10*AF3 -> 0 | AM9: =AL9-AI9 -> 0 | AN9: =AN10*AI3 -> 0 | AP9: =AO9-AL9 -> 0 | AQ9: =AQ10*AL3 -> 0 | AS9: =AR9-AO9 -> 0 | AT9: =AT10*AO3 -> 0 | AV9: =AU9-AR9 -> 0 | AW9: =AW10*AR3 -> 0 | AY9: =AX9-AU9 -> 0 | AZ9: =AZ10*AU3 -> 0 | BB9: =BA9-AX9 -> 0 | BC9: =BC10*AX3 -> 0 | BE9: =BD9-BA9 -> 0 | BF9: =BF10*BA3 -> 0 | BH9: =BG9-BD9 -> 0 | BI9: =BI10*BD3 -> 0 | BK9: =BJ9-BG9 -> 0 | BL9: =BL10*BG3 -> 0 | BN9: =BM9-BJ9 -> 0 | BO9: =BO10*BJ3 -> 0 | BQ9: =BP9-BM9 -> 0 | BR9: =BR10*BM3 -> 0 | BT9: =BS9-BP9 -> 0 | BU9: =BU10*BP3 -> 0 | BW9: =BV9-BS9 -> 0 | BX9: =BX10*BS3 -> 0 | BZ9: =BY9-BV9 -> 0 | CA9: =CA10*BV3 -> 0 | CC9: =CB9-BY9 -> 0 | CD9: =CD10*BY3 -> 0
C10: Тепло тариф | G10: ='0. ГИРА'!G10 -> 24.61791 | J10: ='0. ГИРА'!J10 -> 24.61791 | M10: ='0. ГИРА'!M10 -> 20.514925 | P10: ='0. ГИРА'!P10 -> 0 | S10: ='0. ГИРА'!S10 -> 0 | V10: ='0. ГИРА'!V10 -> 0 | Y10: ='0. ГИРА'!Y10 -> 0 | AB10: ='0. ГИРА'!AB10 -> 0 | AE10: ='0. ГИРА'!AE10 -> 0 | AH10: ='0. ГИРА'!AH10 -> 0 | AK10: ='0. ГИРА'!AK10 -> 0 | AN10: ='0. ГИРА'!AN10 -> 0 | AQ10: ='0. ГИРА'!AQ10 -> 0 | AT10: ='0. ГИРА'!AT10 -> 0 | AW10: ='0. ГИРА'!AW10 -> 0 | AZ10: ='0. ГИРА'!AZ10 -> 0 | BC10: ='0. ГИРА'!BC10 -> 0 | BF10: ='0. ГИРА'!BF10 -> 0 | BI10: ='0. ГИРА'!BI10 -> 0 | BL10: ='0. ГИРА'!BL10 -> 0 | BO10: ='0. ГИРА'!BO10 -> 0 | BR10: ='0. ГИРА'!BR10 -> 0 | BU10: ='0. ГИРА'!BU10 -> 0 | BX10: ='0. ГИРА'!BX10 -> 0 | CA10: ='0. ГИРА'!CA10 -> 0 | CD10: ='0. ГИРА'!CD10 -> 0
A11: Номер счетчика | B11: 43432,34343 | C11: Экспл. Услуги от УК | F11: =E11-D11 -> 0 | G11: ='0. ГИРА'!G12 -> 12142.857 | I11: =H11-G11 -> -12142.857 | J11: ='0. ГИРА'!J12 -> 174.37686 | L11: =K11-J11 -> -174.37686 | M11: ='0. ГИРА'!M12 -> 102.57462 | O11: =N11-M11 -> -102.57462 | P11: ='0. ГИРА'!P12 -> 0 | R11: =Q11-P11 -> 0 | S11: ='0. ГИРА'!S12 -> 0 | U11: =T11-S11 -> 0 | V11: ='0. ГИРА'!V12 -> 0 | X11: =W11-T11 -> 0 | Y11: =Y12*T3 -> 0 | AA11: =Z11-W11 -> 0 | AB11: =AB12*W3 -> 0 | AD11: =AC11-Z11 -> 0 | AE11: =AE12*Z3 -> 0 | AG11: =AF11-AC11 -> 0 | AH11: =AH12*AC3 -> 0 | AJ11: =AI11-AF11 -> 0 | AK11: =AK12*AF3 -> 0 | AM11: =AL11-AI11 -> 0 | AN11: =AN12*AI3 -> 0 | AP11: =AO11-AL11 -> 0 | AQ11: =AQ12*AL3 -> 0 | AS11: =AR11-AO11 -> 0 | AT11: =AT12*AO3 -> 0 | AV11: =AU11-AR11 -> 0 | AW11: =AW12*AR3 -> 0 | AY11: =AX11-AU11 -> 0 | AZ11: =AZ12*AU3 -> 0 | BB11: =BA11-AX11 -> 0 | BC11: =BC12*AX3 -> 0 | BE11: =BD11-BA11 -> 0 | BF11: =BF12*BA3 -> 0 | BH11: =BG11-BD11 -> 0 | BI11: =BI12*BD3 -> 0 | BK11: =BJ11-BG11 -> 0 | BL11: =BL12*BG3 -> 0 | BN11: =BM11-BJ11 -> 0 | BO11: =BO12*BJ3 -> 0 | BQ11: =BP11-BM11 -> 0 | BR11: =BR12*BM3 -> 0 | BT11: =BS11-BP11 -> 0 | BU11: =BU12*BP3 -> 0 | BW11: =BV11-BS11 -> 0 | BX11: =BX12*BS3 -> 0 | BZ11: =BY11-BV11 -> 0 | CA11: =CA12*BV3 -> 0 | CC11: =CB11-BY11 -> 0 | CD11: =CD12*BY3 -> 0
C12: Экспл. Услуги от УК тариф | G12: ='0. ГИРА'!G12 -> 12142.857 | J12: ='0. ГИРА'!J12 -> 174.37686 | M12: ='0. ГИРА'!M12 -> 102.57462 | P12: ='0. ГИРА'!P12 -> 0 | S12: ='0. ГИРА'!S12 -> 0 | V12: ='0. ГИРА'!V12 -> 0 | Y12: ='0. ГИРА'!Y12 -> 0 | AB12: ='0. ГИРА'!AB12 -> 0 | AE12: ='0. ГИРА'!AE12 -> 0 | AH12: ='0. ГИРА'!AH12 -> 0 | AK12: ='0. ГИРА'!AK12 -> 0 | AN12: ='0. ГИРА'!AN12 -> 0 | AQ12: ='0. ГИРА'!AQ12 -> 0 | AT12: ='0. ГИРА'!AT12 -> 0 | AW12: ='0. ГИРА'!AW12 -> 0 | AZ12: ='0. ГИРА'!AZ12 -> 0 | BC12: ='0. ГИРА'!BC12 -> 0 | BF12: ='0. ГИРА'!BF12 -> 0 | BI12: ='0. ГИРА'!BI12 -> 0 | BL12: ='0. ГИРА'!BL12 -> 0 | BO12: ='0. ГИРА'!BO12 -> 0 | BR12: ='0. ГИРА'!BR12 -> 0 | BU12: ='0. ГИРА'!BU12 -> 0 | BX12: ='0. ГИРА'!BX12 -> 0 | CA12: ='0. ГИРА'!CA12 -> 0 | CD12: ='0. ГИРА'!CD12 -> 0

Sheet К45,20
A1: ИНН | B1: =Реестр!D4 -> 333 | C1: Месяц | D1: 45962 | E1: 45992 | F1: Потребл. | G1: 45962 | H1: 46023 | I1: Потребл. | J1: 45992 | K1: 46054 | L1: Потребл. | M1: 46023 | N1: 46082 | O1: Потребл. | P1: 46054 | Q1: 46113 | R1: Потребл. | S1: 46082 | T1: 46143 | U1: Потребл. | V1: 46113 | W1: 46174 | X1: Потребл. | Y1: 46143 | Z1: 46204 | AA1: Потребл. | AB1: 46174 | AC1: 46235 | AD1: Потребл. | AE1: 46204 | AF1: 46266 | AG1: Потребл. | AH1: 46235 | AI1: 46296 | AJ1: Потребл. | AK1: 46266 | AL1: 46327 | AM1: Потребл. | AN1: 46296 | AO1: 46357 | AP1: Потребл. | AQ1: 46327 | AR1: 46388 | AS1: Потребл. | AT1: 46357 | AU1: 46419 | AV1: Потребл. | AW1: 46388 | AX1: 46447 | AY1: Потребл. | AZ1: 46419 | BA1: 46478 | BB1: Потребл. | BC1: 46447 | BD1: 46508 | BE1: Потребл. | BF1: 46478 | BG1: 46539 | BH1: Потребл. | BI1: 46508 | BJ1: 46569 | BK1: Потребл. | BL1: 46539 | BM1: 46600 | BN1: Потребл. | BO1: 46569 | BP1: 46631 | BQ1: Потребл. | BR1: 46600 | BS1: 46661 | BT1: Потребл. | BU1: 46631 | BV1: 46692 | BW1: Потребл. | BX1: 46661 | BY1: 46722 | BZ1: Потребл. | CA1: 46692 | CB1: 46753 | CC1: Потребл. | CD1: 46722
A2: Кадастр | B2: =Реестр!B4 -> 1006:3090 | D2: знач. | E2: знач. | F2: знач. | G2: руб. | H2: знач. | I2: знач. | J2: руб. | K2: знач. | L2: знач. | M2: руб. | N2: знач. | O2: знач | P2: руб. | Q2: знач. | R2: знач. | S2: руб. | T2: знач. | U2: знач. | V2: руб. | W2: знач. | X2: знач. | Y2: руб. | Z2: знач. | AA2: знач. | AB2: руб. | AC2: знач. | AD2: знач. | AE2: руб. | AF2: знач. | AG2: знач. | AH2: руб. | AI2: знач. | AJ2: знач. | AK2: руб. | AL2: знач. | AM2: знач. | AN2: руб. | AO2: знач. | AP2: знач. | AQ2: руб. | AR2: знач. | AS2: знач. | AT2: руб. | AU2: знач. | AV2: знач. | AW2: руб. | AX2: знач. | AY2: знач. | AZ2: руб. | BA2: знач. | BB2: знач. | BC2: руб. | BD2: знач. | BE2: знач. | BF2: руб. | BG2: знач. | BH2: знач. | BI2: руб. | BJ2: знач. | BK2: знач. | BL2: руб. | BM2: знач. | BN2: знач. | BO2: руб. | BP2: знач. | BQ2: знач. | BR2: руб. | BS2: знач. | BT2: знач. | BU2: руб. | BV2: знач. | BW2: знач. | BX2: руб. | BY2: знач. | BZ2: знач. | CA2: руб. | CB2: знач. | CC2: знач. | CD2: руб.
A3: Арендатор | B3: =Реестр!F4 -> Нал | C3: Электричество | F3: =E3-D3 -> 0 | G3: =F3*G4 -> 0 | I3: =H3-E3 -> 0 | J3: =I3*J4 -> 0 | K3: 345678 | L3: =K3-H3 -> 345678 | M3: =L3*M4 -> 3171.3578 | O3: =N3-K3 -> -345678 | P3: =O3*P4 -> 0 | R3: =Q3-N3 -> 0 | S3: =R3*S4 -> #DIV/0! | U3: =T3-Q3 -> 0 | V3: =U3*V4 -> #DIV/0! | X3: =W3-T3 -> 0 | Y3: =X3*Y4 -> #DIV/0! | AA3: =Z3-W3 -> 0 | AB3: =AA3*AB4 -> #DIV/0! | AD3: =AC3-Z3 -> 0 | AE3: =AD3*AE4 -> #DIV/0! | AG3: =AF3-AC3 -> 0 | AH3: =AG3*AH4 -> #DIV/0! | AJ3: =AI3-AF3 -> 0 | AK3: =AJ3*AK4 -> #DIV/0! | AM3: =AL3-AI3 -> 0 | AN3: =AM3*AN4 -> #DIV/0! | AP3: =AO3-AL3 -> 0 | AQ3: =AP3*AQ4 -> #DIV/0! | AS3: =AR3-AO3 -> 0 | AT3: =AS3*AT4 -> #DIV/0! | AV3: =AU3-AR3 -> 0 | AW3: =AV3*AW4 -> #DIV/0! | AY3: =AX3-AU3 -> 0 | AZ3: =AY3*AZ4 -> #DIV/0! | BB3: =BA3-AX3 -> 0 | BC3: =BB3*BC4 -> #DIV/0! | BE3: =BD3-BA3 -> 0 | BF3: =BE3*BF4 -> #DIV/0! | BH3: =BG3-BD3 -> 0 | BI3: =BH3*BI4 -> #DIV/0! | BK3: =BJ3-BG3 -> 0 | BL3: =BK3*BL4 -> #DIV/0! | BN3: =BM3-BJ3 -> 0 | BO3: =BN3*BO4 -> #DIV/0! | BQ3: =BP3-BM3 -> 0 | BR3: =BQ3*BR4 -> #DIV/0! | BT3: =BS3-BP3 -> 0 | BU3: =BT3*BU4 -> #DIV/0! | BW3: =BV3-BS3 -> 0 | BX3: =BW3*BX4 -> #DIV/0! | BZ3: =BY3-BV3 -> 0 | CA3: =BZ3*CA4 -> #DIV/0! | CC3: =CB3-BY3 -> 0 | CD3: =CC3*CD4 -> 0
A4: Площадь | B4: =Реестр!H4 -> 45.2 | C4: Электричество тариф | G4: ='0. ГИРА'!G4 -> 0.045000045 | J4: ='0. ГИРА'!J4 -> 0.1956526 | M4: ='0. ГИРА'!M4 -> 0.0091743119 | P4: ='0. ГИРА'!P4 -> 0 | S4: ='0. ГИРА'!S4 -> #DIV/0! | V4: ='0. ГИРА'!V4 -> #DIV/0! | Y4: ='0. ГИРА'!Y4 -> #DIV/0! | AB4: ='0. ГИРА'!AB4 -> #DIV/0! | AE4: ='0. ГИРА'!AE4 -> #DIV/0! | AH4: ='0. ГИРА'!AH4 -> #DIV/0! | AK4: ='0. ГИРА'!AK4 -> #DIV/0! | AN4: ='0. ГИРА'!AN4 -> #DIV/0! | AQ4: ='0. ГИРА'!AQ4 -> #DIV/0! | AT4: ='0. ГИРА'!AT4 -> #DIV/0! | AW4: ='0. ГИРА'!AW4 -> #DIV/0! | AZ4: ='0. ГИРА'!AZ4 -> #DIV/0! | BC4: ='0. ГИРА'!BC4 -> #DIV/0! | BF4: ='0. ГИРА'!BF4 -> #DIV/0! | BI4: ='0. ГИРА'!BI4 -> #DIV/0! | BL4: ='0. ГИРА'!BL4 -> #DIV/0! | BO4: ='0. ГИРА'!BO4 -> #DIV/0! | BR4: ='0. ГИРА'!BR4 -> #DIV/0! | BU4: ='0. ГИРА'!BU4 -> #DIV/0! | BX4: ='0. ГИРА'!BX4 -> #DIV/0! | CA4: ='0. ГИРА'!CA4 -> #DIV/0! | CD4: ='0. ГИРА'!CD4 -> 0
C5: Водоканал холодная вода | F5: =E5-D5 -> 0 | I5: =H5-E5 -> 0 | K5: 579 | L5: =K5-H5 -> 579 | O5: =N5-K5 -> -579 | R5: =Q5-N5 -> 0 | U5: =T5-Q5 -> 0 | X5: =W5-T5 -> 0 | AA5: =Z5-W5 -> 0 | AD5: =AC5-Z5 -> 0 | AG5: =AF5-AC5 -> 0 | AJ5: =AI5-AF5 -> 0 | AM5: =AL5-AI5 -> 0 | AP5: =AO5-AL5 -> 0 | AS5: =AR5-AO5 -> 0 | AV5: =AU5-AR5 -> 0 | AY5: =AX5-AU5 -> 0 | BB5: =BA5-AX5 -> 0 | BE5: =BD5-BA5 -> 0 | BH5: =BG5-BD5 -> 0 | BK5: =BJ5-BG5 -> 0 | BN5: =BM5-BJ5 -> 0 | BQ5: =BP5-BM5 -> 0 | BT5: =BS5-BP5 -> 0 | BW5: =BV5-BS5 -> 0 | BZ5: =BY5-BV5 -> 0 | CC5: =CB5-BY5 -> 0
A6: Имя 1 | B6: =Реестр!M4 -> - | C6: Водоканал холодная Тариф | G6: ='0. ГИРА'!G6 -> 0.067500068 | J6: ='0. ГИРА'!J6 -> 0.14673945 | M6: ='0. ГИРА'!M6 -> -0.011069527 | P6: ='0. ГИРА'!P6 -> 0 | S6: ='0. ГИРА'!S6 -> #DIV/0! | V6: ='0. ГИРА'!V6 -> #DIV/0! | Y6: ='0. ГИРА'!Y6 -> #DIV/0! | AB6: ='0. ГИРА'!AB6 -> #DIV/0! | AE6: ='0. ГИРА'!AE6 -> #DIV/0! | AH6: ='0. ГИРА'!AH6 -> #DIV/0! | AK6: ='0. ГИРА'!AK6 -> #DIV/0! | AN6: ='0. ГИРА'!AN6 -> #DIV/0! | AQ6: ='0. ГИРА'!AQ6 -> #DIV/0! | AT6: ='0. ГИРА'!AT6 -> #DIV/0! | AW6: ='0. ГИРА'!AW6 -> #DIV/0! | AZ6: ='0. ГИРА'!AZ6 -> #DIV/0! | BC6: ='0. ГИРА'!BC6 -> #DIV/0! | BF6: ='0. ГИРА'!BF6 -> #DIV/0! | BI6: ='0. ГИРА'!BI6 -> #DIV/0! | BL6: ='0. ГИРА'!BL6 -> #DIV/0! | BO6: ='0. ГИРА'!BO6 -> #DIV/0! | BR6: ='0. ГИРА'!BR6 -> #DIV/0! | BU6: ='0. ГИРА'!BU6 -> #DIV/0! | BX6: ='0. ГИРА'!BX6 -> #DIV/0! | CA6: ='0. ГИРА'!CA6 -> #DIV/0! | CD6: ='0. ГИРА'!CD6 -> 0
A7: Контакт 1 | B7: =Реестр!N4 -> - | C7: Водоканал горячая вода | F7: =E7-D7 -> 0 | G7: =G8*F7 -> 0 | I7: =H7-E7 -> 0 | J7: =J8*I7 -> 0 | L7: =K7-H7 -> 0 | M7: =M8*L7 -> 0 | O7: =N7-K7 -> 0 | P7: =P8*O7 -> 0 | R7: =Q7-N7 -> 0 | S7: =S8*R7 -> #DIV/0! | U7: =T7-Q7 -> 0 | V7: =V8*U7 -> #DIV/0! | X7: =W7-T7 -> 0 | Y7: =Y8*X7 -> #DIV/0! | AA7: =Z7-W7 -> 0 | AB7: =AB8*AA7 -> #DIV/0! | AD7: =AC7-Z7 -> 0 | AE7: =AE8*AD7 -> #DIV/0! | AG7: =AF7-AC7 -> 0 | AH7: =AH8*AG7 -> #DIV/0! | AJ7: =AI7-AF7 -> 0 | AK7: =AK8*AJ7 -> #DIV/0! | AM7: =AL7-AI7 -> 0 | AN7: =AN8*AM7 -> #DIV/0! | AP7: =AO7-AL7 -> 0 | AQ7: =AQ8*AP7 -> #DIV/0! | AS7: =AR7-AO7 -> 0 | AT7: =AT8*AS7 -> #DIV/0! | AV7: =AU7-AR7 -> 0 | AW7: =AW8*AV7 -> #DIV/0! | AY7: =AX7-AU7 -> 0 | AZ7: =AZ8*AY7 -> #DIV/0! | BB7: =BA7-AX7 -> 0 | BC7: =BC8*BB7 -> #DIV/0! | BE7: =BD7-BA7 -> 0 | BF7: =BF8*BE7 -> #DIV/0! | BH7: =BG7-BD7 -> 0 | BI7: =BI8*BH7 -> #DIV/0! | BK7: =BJ7-BG7 -> 0 | BL7: =BL8*BK7 -> #DIV/0! | BN7: =BM7-BJ7 -> 0 | BO7: =BO8*BN7 -> #DIV/0! | BQ7: =BP7-BM7 -> 0 | BR7: =BR8*BQ7 -> #DIV/0! | BT7: =BS7-BP7 -> 0 | BU7: =BU8*BT7 -> #DIV/0! | BW7: =BV7-BS7 -> 0 | BX7: =BX8*BW7 -> #DIV/0! | BZ7: =BY7-BV7 -> 0 | CA7: =CA8*BZ7 -> #DIV/0! | CC7: =CB7-BY7 -> 0 | CD7: =CD8*CC7 -> 0
A8: Имя 2 | B8: =Реестр!O4 -> - | C8: Водоканал горячая Тариф | G8: ='0. ГИРА'!G8 -> 0.09000009 | J8: ='0. ГИРА'!J8 -> 0.1956526 | M8: ='0. ГИРА'!M8 -> -0.051392492 | P8: ='0. ГИРА'!P8 -> 0 | S8: ='0. ГИРА'!S8 -> #DIV/0! | V8: ='0. ГИРА'!V8 -> #DIV/0! | Y8: ='0. ГИРА'!Y8 -> #DIV/0! | AB8: ='0. ГИРА'!AB8 -> #DIV/0! | AE8: ='0. ГИРА'!AE8 -> #DIV/0! | AH8: ='0. ГИРА'!AH8 -> #DIV/0! | AK8: ='0. ГИРА'!AK8 -> #DIV/0! | AN8: ='0. ГИРА'!AN8 -> #DIV/0! | AQ8: ='0. ГИРА'!AQ8 -> #DIV/0! | AT8: ='0. ГИРА'!AT8 -> #DIV/0! | AW8: ='0. ГИРА'!AW8 -> #DIV/0! | AZ8: ='0. ГИРА'!AZ8 -> #DIV/0! | BC8: ='0. ГИРА'!BC8 -> #DIV/0! | BF8: ='0. ГИРА'!BF8 -> #DIV/0! | BI8: ='0. ГИРА'!BI8 -> #DIV/0! | BL8: ='0. ГИРА'!BL8 -> #DIV/0! | BO8: ='0. ГИРА'!BO8 -> #DIV/0! | BR8: ='0. ГИРА'!BR8 -> #DIV/0! | BU8: ='0. ГИРА'!BU8 -> #DIV/0! | BX8: ='0. ГИРА'!BX8 -> #DIV/0! | CA8: ='0. ГИРА'!CA8 -> #DIV/0! | CD8: ='0. ГИРА'!CD8 -> 0
A9: Контакт 2 | B9: =Реестр!P4 -> - | C9: Тепло | F9: =E9-D9 -> 0 | G9: =G10*B3 -> #VALUE! | I9: =H9-E9 -> 0 | J9: =J10*E3 -> 0 | K9: 123 | L9: =K9-H9 -> 123 | M9: 12 | O9: =N9-K9 -> -123 | P9: =P10*K3 -> 0 | R9: =Q9-N9 -> 0 | S9: =S10*N3 -> 0 | U9: =T9-Q9 -> 0 | V9: =V10*Q3 -> 0 | X9: =W9-T9 -> 0 | Y9: =Y10*T3 -> 0 | AA9: =Z9-W9 -> 0 | AB9: =AB10*W3 -> 0 | AD9: =AC9-Z9 -> 0 | AE9: =AE10*Z3 -> 0 | AG9: =AF9-AC9 -> 0 | AH9: =AH10*AC3 -> 0 | AJ9: =AI9-AF9 -> 0 | AK9: =AK10*AF3 -> 0 | AM9: =AL9-AI9 -> 0 | AN9: =AN10*AI3 -> 0 | AP9: =AO9-AL9 -> 0 | AQ9: =AQ10*AL3 -> 0 | AS9: =AR9-AO9 -> 0 | AT9: =AT10*AO3 -> 0 | AV9: =AU9-AR9 -> 0 | AW9: =AW10*AR3 -> 0 | AY9: =AX9-AU9 -> 0 | AZ9: =AZ10*AU3 -> 0 | BB9: =BA9-AX9 -> 0 | BC9: =BC10*AX3 -> 0 | BE9: =BD9-BA9 -> 0 | BF9: =BF10*BA3 -> 0 | BH9: =BG9-BD9 -> 0 | BI9: =BI10*BD3 -> 0 | BK9: =BJ9-BG9 -> 0 | BL9: =BL10*BG3 -> 0 | BN9: =BM9-BJ9 -> 0 | BO9: =BO10*BJ3 -> 0 | BQ9: =BP9-BM9 -> 0 | BR9: =BR10*BM3 -> 0 | BT9: =BS9-BP9 -> 0 | BU9: =BU10*BP3 -> 0 | BW9: =BV9-BS9 -> 0 | BX9: =BX10*BS3 -> 0 | BZ9: =BY9-BV9 -> 0 | CA9: =CA10*BV3 -> 0 | CC9: =CB9-BY9 -> 0 | CD9: =CD10*BY3 -> 0
C10: Тепло тариф | G10: ='0. ГИРА'!G10 -> 24.61791 | J10: ='0. ГИРА'!J10 -> 24.61791 | M10: ='0. ГИРА'!M10 -> 20.514925 | P10: ='0. ГИРА'!P10 -> 0 | S10: ='0. ГИРА'!S10 -> 0 | V10: ='0. ГИРА'!V10 -> 0 | Y10: ='0. ГИРА'!Y10 -> 0 | AB10: ='0. ГИРА'!AB10 -> 0 | AE10: ='0. ГИРА'!AE10 -> 0 | AH10: ='0. ГИРА'!AH10 -> 0 | AK10: ='0. ГИРА'!AK10 -> 0 | AN10: ='0. ГИРА'!AN10 -> 0 | AQ10: ='0. ГИРА'!AQ10 -> 0 | AT10: ='0. ГИРА'!AT10 -> 0 | AW10: ='0. ГИРА'!AW10 -> 0 | AZ10: ='0. ГИРА'!AZ10 -> 0 | BC10: ='0. ГИРА'!BC10 -> 0 | BF10: ='0. ГИРА'!BF10 -> 0 | BI10: ='0. ГИРА'!BI10 -> 0 | BL10: ='0. ГИРА'!BL10 -> 0 | BO10: ='0. ГИРА'!BO10 -> 0 | BR10: ='0. ГИРА'!BR10 -> 0 | BU10: ='0. ГИРА'!BU10 -> 0 | BX10: ='0. ГИРА'!BX10 -> 0 | CA10: ='0. ГИРА'!CA10 -> 0 | CD10: ='0. ГИРА'!CD10 -> 0
A11: Номер счетчика | C11: Экспл. Услуги от УК | F11: =E11-D11 -> 0 | I11: =H11-E11 -> 0 | J11: =J12*E3 -> 0 | L11: =K11-H11 -> 0 | M11: =M12*H3 -> 0 | O11: =N11-K11 -> 0 | P11: =P12*K3 -> 0 | R11: =Q11-N11 -> 0 | S11: =S12*N3 -> 0 | U11: =T11-Q11 -> 0 | V11: =V12*Q3 -> 0 | X11: =W11-T11 -> 0 | Y11: =Y12*T3 -> 0 | AA11: =Z11-W11 -> 0 | AB11: =AB12*W3 -> 0 | AD11: =AC11-Z11 -> 0 | AE11: =AE12*Z3 -> 0 | AG11: =AF11-AC11 -> 0 | AH11: =AH12*AC3 -> 0 | AJ11: =AI11-AF11 -> 0 | AK11: =AK12*AF3 -> 0 | AM11: =AL11-AI11 -> 0 | AN11: =AN12*AI3 -> 0 | AP11: =AO11-AL11 -> 0 | AQ11: =AQ12*AL3 -> 0 | AS11: =AR11-AO11 -> 0 | AT11: =AT12*AO3 -> 0 | AV11: =AU11-AR11 -> 0 | AW11: =AW12*AR3 -> 0 | AY11: =AX11-AU11 -> 0 | AZ11: =AZ12*AU3 -> 0 | BB11: =BA11-AX11 -> 0 | BC11: =BC12*AX3 -> 0 | BE11: =BD11-BA11 -> 0 | BF11: =BF12*BA3 -> 0 | BH11: =BG11-BD11 -> 0 | BI11: =BI12*BD3 -> 0 | BK11: =BJ11-BG11 -> 0 | BL11: =BL12*BG3 -> 0 | BN11: =BM11-BJ11 -> 0 | BO11: =BO12*BJ3 -> 0 | BQ11: =BP11-BM11 -> 0 | BR11: =BR12*BM3 -> 0 | BT11: =BS11-BP11 -> 0 | BU11: =BU12*BP3 -> 0 | BW11: =BV11-BS11 -> 0 | BX11: =BX12*BS3 -> 0 | BZ11: =BY11-BV11 -> 0 | CA11: =CA12*BV3 -> 0 | CC11: =CB11-BY11 -> 0 | CD11: =CD12*BY3 -> 0
C12: Экспл. Услуги от УК тариф | G12: ='0. ГИРА'!G12 -> 12142.857 | J12: ='0. ГИРА'!J12 -> 174.37686 | M12: ='0. ГИРА'!M12 -> 102.57462 | P12: ='0. ГИРА'!P12 -> 0 | S12: ='0. ГИРА'!S12 -> 0 | V12: ='0. ГИРА'!V12 -> 0 | Y12: ='0. ГИРА'!Y12 -> 0 | AB12: ='0. ГИРА'!AB12 -> 0 | AE12: ='0. ГИРА'!AE12 -> 0 | AH12: ='0. ГИРА'!AH12 -> 0 | AK12: ='0. ГИРА'!AK12 -> 0 | AN12: ='0. ГИРА'!AN12 -> 0 | AQ12: ='0. ГИРА'!AQ12 -> 0 | AT12: ='0. ГИРА'!AT12 -> 0 | AW12: ='0. ГИРА'!AW12 -> 0 | AZ12: ='0. ГИРА'!AZ12 -> 0 | BC12: ='0. ГИРА'!BC12 -> 0 | BF12: ='0. ГИРА'!BF12 -> 0 | BI12: ='0. ГИРА'!BI12 -> 0 | BL12: ='0. ГИРА'!BL12 -> 0 | BO12: ='0. ГИРА'!BO12 -> 0 | BR12: ='0. ГИРА'!BR12 -> 0 | BU12: ='0. ГИРА'!BU12 -> 0 | BX12: ='0. ГИРА'!BX12 -> 0 | CA12: ='0. ГИРА'!CA12 -> 0 | CD12: ='0. ГИРА'!CD12 -> 0

Sheet К43,30
A1: ИНН | B1: =Реестр!D5 -> 555 | C1: Месяц | D1: 45962 | E1: 45992 | F1: Потребл. | G1: 45962 | H1: 46023 | I1: Потребл. | J1: 45992 | K1: 46054 | L1: Потребл. | M1: 46023 | N1: 46082 | O1: Потребл. | P1: 46054 | Q1: 46113 | R1: Потребл. | S1: 46082 | T1: 46143 | U1: Потребл. | V1: 46113 | W1: 46174 | X1: Потребл. | Y1: 46143 | Z1: 46204 | AA1: Потребл. | AB1: 46174 | AC1: 46235 | AD1: Потребл. | AE1: 46204 | AF1: 46266 | AG1: Потребл. | AH1: 46235 | AI1: 46296 | AJ1: Потребл. | AK1: 46266 | AL1: 46327 | AM1: Потребл. | AN1: 46296 | AO1: 46357 | AP1: Потребл. | AQ1: 46327 | AR1: 46388 | AS1: Потребл. | AT1: 46357 | AU1: 46419 | AV1: Потребл. | AW1: 46388 | AX1: 46447 | AY1: Потребл. | AZ1: 46419 | BA1: 46478 | BB1: Потребл. | BC1: 46447 | BD1: 46508 | BE1: Потребл. | BF1: 46478 | BG1: 46539 | BH1: Потребл. | BI1: 46508 | BJ1: 46569 | BK1: Потребл. | BL1: 46539 | BM1: 46600 | BN1: Потребл. | BO1: 46569 | BP1: 46631 | BQ1: Потребл. | BR1: 46600 | BS1: 46661 | BT1: Потребл. | BU1: 46631 | BV1: 46692 | BW1: Потребл. | BX1: 46661 | BY1: 46722 | BZ1: Потребл. | CA1: 46692 | CB1: 46753 | CC1: Потребл. | CD1: 46722
A2: Кадастр | B2: =Реестр!B5 -> 1006:3090 | D2: знач. | E2: знач. | F2: знач. | G2: руб. | H2: знач. | I2: знач. | J2: руб. | K2: знач. | L2: знач. | M2: руб. | N2: знач. | O2: знач | P2: руб. | Q2: знач. | R2: знач. | S2: руб. | T2: знач. | U2: знач. | V2: руб. | W2: знач. | X2: знач. | Y2: руб. | Z2: знач. | AA2: знач. | AB2: руб. | AC2: знач. | AD2: знач. | AE2: руб. | AF2: знач. | AG2: знач. | AH2: руб. | AI2: знач. | AJ2: знач. | AK2: руб. | AL2: знач. | AM2: знач. | AN2: руб. | AO2: знач. | AP2: знач. | AQ2: руб. | AR2: знач. | AS2: знач. | AT2: руб. | AU2: знач. | AV2: знач. | AW2: руб. | AX2: знач. | AY2: знач. | AZ2: руб. | BA2: знач. | BB2: знач. | BC2: руб. | BD2: знач. | BE2: знач. | BF2: руб. | BG2: знач. | BH2: знач. | BI2: руб. | BJ2: знач. | BK2: знач. | BL2: руб. | BM2: знач. | BN2: знач. | BO2: руб. | BP2: знач. | BQ2: знач. | BR2: руб. | BS2: знач. | BT2: знач. | BU2: руб. | BV2: знач. | BW2: знач. | BX2: руб. | BY2: знач. | BZ2: знач. | CA2: руб. | CB2: знач. | CC2: знач. | CD2: руб.
A3: Арендатор | B3: =Реестр!F5 -> Мясоо | C3: Электричество | F3: =E3-D3 -> 0 | G3: =F3*G4 -> 0 | I3: =H3-E3 -> 0 | J3: =I3*J4 -> 0 | L3: =K3-H3 -> 0 | M3: =L3*M4 -> 0 | O3: =N3-K3 -> 0 | P3: =O3*P4 -> 0 | R3: =Q3-N3 -> 0 | S3: =R3*S4 -> #DIV/0! | U3: =T3-Q3 -> 0 | V3: =U3*V4 -> #DIV/0! | X3: =W3-T3 -> 0 | Y3: =X3*Y4 -> #DIV/0! | AA3: =Z3-W3 -> 0 | AB3: =AA3*AB4 -> #DIV/0! | AD3: =AC3-Z3 -> 0 | AE3: =AD3*AE4 -> #DIV/0! | AG3: =AF3-AC3 -> 0 | AH3: =AG3*AH4 -> #DIV/0! | AJ3: =AI3-AF3 -> 0 | AK3: =AJ3*AK4 -> #DIV/0! | AM3: =AL3-AI3 -> 0 | AN3: =AM3*AN4 -> #DIV/0! | AP3: =AO3-AL3 -> 0 | AQ3: =AP3*AQ4 -> #DIV/0! | AS3: =AR3-AO3 -> 0 | AT3: =AS3*AT4 -> #DIV/0! | AV3: =AU3-AR3 -> 0 | AW3: =AV3*AW4 -> #DIV/0! | AY3: =AX3-AU3 -> 0 | AZ3: =AY3*AZ4 -> #DIV/0! | BB3: =BA3-AX3 -> 0 | BC3: =BB3*BC4 -> #DIV/0! | BE3: =BD3-BA3 -> 0 | BF3: =BE3*BF4 -> #DIV/0! | BH3: =BG3-BD3 -> 0 | BI3: =BH3*BI4 -> #DIV/0! | BK3: =BJ3-BG3 -> 0 | BL3: =BK3*BL4 -> #DIV/0! | BN3: =BM3-BJ3 -> 0 | BO3: =BN3*BO4 -> #DIV/0! | BQ3: =BP3-BM3 -> 0 | BR3: =BQ3*BR4 -> #DIV/0! | BT3: =BS3-BP3 -> 0 | BU3: =BT3*BU4 -> #DIV/0! | BW3: =BV3-BS3 -> 0 | BX3: =BW3*BX4 -> #DIV/0! | BZ3: =BY3-BV3 -> 0 | CA3: =BZ3*CA4 -> #DIV/0! | CC3: =CB3-BY3 -> 0 | CD3: =CC3*CD4 -> 0
A4: Площадь | B4: =Реестр!H5 -> 43.3 | C4: Электричество тариф | G4: ='0. ГИРА'!G4 -> 0.045000045 | J4: ='0. ГИРА'!J4 -> 0.1956526 | M4: ='0. ГИРА'!M4 -> 0.0091743119 | P4: ='0. ГИРА'!P4 -> 0 | S4: ='0. ГИРА'!S4 -> #DIV/0! | V4: ='0. ГИРА'!V4 -> #DIV/0! | Y4: ='0. ГИРА'!Y4 -> #DIV/0! | AB4: ='0. ГИРА'!AB4 -> #DIV/0! | AE4: ='0. ГИРА'!AE4 -> #DIV/0! | AH4: ='0. ГИРА'!AH4 -> #DIV/0! | AK4: ='0. ГИРА'!AK4 -> #DIV/0! | AN4: ='0. ГИРА'!AN4 -> #DIV/0! | AQ4: ='0. ГИРА'!AQ4 -> #DIV/0! | AT4: ='0. ГИРА'!AT4 -> #DIV/0! | AW4: ='0. ГИРА'!AW4 -> #DIV/0! | AZ4: ='0. ГИРА'!AZ4 -> #DIV/0! | BC4: ='0. ГИРА'!BC4 -> #DIV/0! | BF4: ='0. ГИРА'!BF4 -> #DIV/0! | BI4: ='0. ГИРА'!BI4 -> #DIV/0! | BL4: ='0. ГИРА'!BL4 -> #DIV/0! | BO4: ='0. ГИРА'!BO4 -> #DIV/0! | BR4: ='0. ГИРА'!BR4 -> #DIV/0! | BU4: ='0. ГИРА'!BU4 -> #DIV/0! | BX4: ='0. ГИРА'!BX4 -> #DIV/0! | CA4: ='0. ГИРА'!CA4 -> #DIV/0! | CD4: ='0. ГИРА'!CD4 -> 0
C5: Водоканал холодная вода | F5: =E5-D5 -> 0 | I5: =H5-E5 -> 0 | L5: =K5-H5 -> 0 | O5: =N5-K5 -> 0 | R5: =Q5-N5 -> 0 | U5: =T5-Q5 -> 0 | X5: =W5-T5 -> 0 | AA5: =Z5-W5 -> 0 | AD5: =AC5-Z5 -> 0 | AG5: =AF5-AC5 -> 0 | AJ5: =AI5-AF5 -> 0 | AM5: =AL5-AI5 -> 0 | AP5: =AO5-AL5 -> 0 | AS5: =AR5-AO5 -> 0 | AV5: =AU5-AR5 -> 0 | AY5: =AX5-AU5 -> 0 | BB5: =BA5-AX5 -> 0 | BE5: =BD5-BA5 -> 0 | BH5: =BG5-BD5 -> 0 | BK5: =BJ5-BG5 -> 0 | BN5: =BM5-BJ5 -> 0 | BQ5: =BP5-BM5 -> 0 | BT5: =BS5-BP5 -> 0 | BW5: =BV5-BS5 -> 0 | BZ5: =BY5-BV5 -> 0 | CC5: =CB5-BY5 -> 0
A6: Имя 1 | B6: =Реестр!M5 -> - | C6: Водоканал холодная Тариф | G6: ='0. ГИРА'!G6 -> 0.067500068 | J6: ='0. ГИРА'!J6 -> 0.14673945 | M6: ='0. ГИРА'!M6 -> -0.011069527 | P6: ='0. ГИРА'!P6 -> 0 | S6: ='0. ГИРА'!S6 -> #DIV/0! | V6: ='0. ГИРА'!V6 -> #DIV/0! | Y6: ='0. ГИРА'!Y6 -> #DIV/0! | AB6: ='0. ГИРА'!AB6 -> #DIV/0! | AE6: ='0. ГИРА'!AE6 -> #DIV/0! | AH6: ='0. ГИРА'!AH6 -> #DIV/0! | AK6: ='0. ГИРА'!AK6 -> #DIV/0! | AN6: ='0. ГИРА'!AN6 -> #DIV/0! | AQ6: ='0. ГИРА'!AQ6 -> #DIV/0! | AT6: ='0. ГИРА'!AT6 -> #DIV/0! | AW6: ='0. ГИРА'!AW6 -> #DIV/0! | AZ6: ='0. ГИРА'!AZ6 -> #DIV/0! | BC6: ='0. ГИРА'!BC6 -> #DIV/0! | BF6: ='0. ГИРА'!BF6 -> #DIV/0! | BI6: ='0. ГИРА'!BI6 -> #DIV/0! | BL6: ='0. ГИРА'!BL6 -> #DIV/0! | BO6: ='0. ГИРА'!BO6 -> #DIV/0! | BR6: ='0. ГИРА'!BR6 -> #DIV/0! | BU6: ='0. ГИРА'!BU6 -> #DIV/0! | BX6: ='0. ГИРА'!BX6 -> #DIV/0! | CA6: ='0. ГИРА'!CA6 -> #DIV/0! | CD6: ='0. ГИРА'!CD6 -> 0
A7: Контакт 1 | B7: =Реестр!N5 -> - | C7: Водоканал горячая вода | F7: =E7-D7 -> 0 | G7: =G8*F7 -> 0 | I7: =H7-E7 -> 0 | J7: =J8*I7 -> 0 | L7: =K7-H7 -> 0 | M7: =M8*L7 -> 0 | O7: =N7-K7 -> 0 | P7: =P8*O7 -> 0 | R7: =Q7-N7 -> 0 | S7: =S8*R7 -> #DIV/0! | U7: =T7-Q7 -> 0 | V7: =V8*U7 -> #DIV/0! | X7: =W7-T7 -> 0 | Y7: =Y8*X7 -> #DIV/0! | AA7: =Z7-W7 -> 0 | AB7: =AB8*AA7 -> #DIV/0! | AD7: =AC7-Z7 -> 0 | AE7: =AE8*AD7 -> #DIV/0! | AG7: =AF7-AC7 -> 0 | AH7: =AH8*AG7 -> #DIV/0! | AJ7: =AI7-AF7 -> 0 | AK7: =AK8*AJ7 -> #DIV/0! | AM7: =AL7-AI7 -> 0 | AN7: =AN8*AM7 -> #DIV/0! | AP7: =AO7-AL7 -> 0 | AQ7: =AQ8*AP7 -> #DIV/0! | AS7: =AR7-AO7 -> 0 | AT7: =AT8*AS7 -> #DIV/0! | AV7: =AU7-AR7 -> 0 | AW7: =AW8*AV7 -> #DIV/0! | AY7: =AX7-AU7 -> 0 | AZ7: =AZ8*AY7 -> #DIV/0! | BB7: =BA7-AX7 -> 0 | BC7: =BC8*BB7 -> #DIV/0! | BE7: =BD7-BA7 -> 0 | BF7: =BF8*BE7 -> #DIV/0! | BH7: =BG7-BD7 -> 0 | BI7: =BI8*BH7 -> #DIV/0! | BK7: =BJ7-BG7 -> 0 | BL7: =BL8*BK7 -> #DIV/0! | BN7: =BM7-BJ7 -> 0 | BO7: =BO8*BN7 -> #DIV/0! | BQ7: =BP7-BM7 -> 0 | BR7: =BR8*BQ7 -> #DIV/0! | BT7: =BS7-BP7 -> 0 | BU7: =BU8*BT7 -> #DIV/0! | BW7: =BV7-BS7 -> 0 | BX7: =BX8*BW7 -> #DIV/0! | BZ7: =BY7-BV7 -> 0 | CA7: =CA8*BZ7 -> #DIV/0! | CC7: =CB7-BY7 -> 0 | CD7: =CD8*CC7 -> 0
A8: Имя 2 | B8: =Реестр!O5 -> - | C8: Водоканал горячая Тариф | G8: ='0. ГИРА'!G8 -> 0.09000009 | J8: ='0. ГИРА'!J8 -> 0.1956526 | M8: ='0. ГИРА'!M8 -> -0.051392492 | P8: ='0. ГИРА'!P8 -> 0 | S8: ='0. ГИРА'!S8 -> #DIV/0! | V8: ='0. ГИРА'!V8 -> #DIV/0! | Y8: ='0. ГИРА'!Y8 -> #DIV/0! | AB8: ='0. ГИРА'!AB8 -> #DIV/0! | AE8: ='0. ГИРА'!AE8 -> #DIV/0! | AH8: ='0. ГИРА'!AH8 -> #DIV/0! | AK8: ='0. ГИРА'!AK8 -> #DIV/0! | AN8: ='0. ГИРА'!AN8 -> #DIV/0! | AQ8: ='0. ГИРА'!AQ8 -> #DIV/0! | AT8: ='0. ГИРА'!AT8 -> #DIV/0! | AW8: ='0. ГИРА'!AW8 -> #DIV/0! | AZ8: ='0. ГИРА'!AZ8 -> #DIV/0! | BC8: ='0. ГИРА'!BC8 -> #DIV/0! | BF8: ='0. ГИРА'!BF8 -> #DIV/0! | BI8: ='0. ГИРА'!BI8 -> #DIV/0! | BL8: ='0. ГИРА'!BL8 -> #DIV/0! | BO8: ='0. ГИРА'!BO8 -> #DIV/0! | BR8: ='0. ГИРА'!BR8 -> #DIV/0! | BU8: ='0. ГИРА'!BU8 -> #DIV/0! | BX8: ='0. ГИРА'!BX8 -> #DIV/0! | CA8: ='0. ГИРА'!CA8 -> #DIV/0! | CD8: ='0. ГИРА'!CD8 -> 0
A9: Контакт 2 | B9: =Реестр!P5 -> - | C9: Тепло | F9: =E9-D9 -> 0 | G9: =G10*B3 -> #VALUE! | I9: =H9-E9 -> 0 | J9: =J10*E3 -> 0 | K9: 1234 | L9: =K9-H9 -> 1234 | M9: 12 | O9: =N9-K9 -> -1234 | P9: =P10*K3 -> 0 | R9: =Q9-N9 -> 0 | S9: =S10*N3 -> 0 | U9: =T9-Q9 -> 0 | V9: =V10*Q3 -> 0 | X9: =W9-T9 -> 0 | Y9: =Y10*T3 -> 0 | AA9: =Z9-W9 -> 0 | AB9: =AB10*W3 -> 0 | AD9: =AC9-Z9 -> 0 | AE9: =AE10*Z3 -> 0 | AG9: =AF9-AC9 -> 0 | AH9: =AH10*AC3 -> 0 | AJ9: =AI9-AF9 -> 0 | AK9: =AK10*AF3 -> 0 | AM9: =AL9-AI9 -> 0 | AN9: =AN10*AI3 -> 0 | AP9: =AO9-AL9 -> 0 | AQ9: =AQ10*AL3 -> 0 | AS9: =AR9-AO9 -> 0 | AT9: =AT10*AO3 -> 0 | AV9: =AU9-AR9 -> 0 | AW9: =AW10*AR3 -> 0 | AY9: =AX9-AU9 -> 0 | AZ9: =AZ10*AU3 -> 0 | BB9: =BA9-AX9 -> 0 | BC9: =BC10*AX3 -> 0 | BE9: =BD9-BA9 -> 0 | BF9: =BF10*BA3 -> 0 | BH9: =BG9-BD9 -> 0 | BI9: =BI10*BD3 -> 0 | BK9: =BJ9-BG9 -> 0 | BL9: =BL10*BG3 -> 0 | BN9: =BM9-BJ9 -> 0 | BO9: =BO10*BJ3 -> 0 | BQ9: =BP9-BM9 -> 0 | BR9: =BR10*BM3 -> 0 | BT9: =BS9-BP9 -> 0 | BU9: =BU10*BP3 -> 0 | BW9: =BV9-BS9 -> 0 | BX9: =BX10*BS3 -> 0 | BZ9: =BY9-BV9 -> 0 | CA9: =CA10*BV3 -> 0 | CC9: =CB9-BY9 -> 0 | CD9: =CD10*BY3 -> 0
C10: Тепло тариф | G10: ='0. ГИРА'!G10 -> 24.61791 | J10: ='0. ГИРА'!J10 -> 24.61791 | M10: ='0. ГИРА'!M10 -> 20.514925 | P10: ='0. ГИРА'!P10 -> 0 | S10: ='0. ГИРА'!S10 -> 0 | V10: ='0. ГИРА'!V10 -> 0 | Y10: ='0. ГИРА'!Y10 -> 0 | AB10: ='0. ГИРА'!AB10 -> 0 | AE10: ='0. ГИРА'!AE10 -> 0 | AH10: ='0. ГИРА'!AH10 -> 0 | AK10: ='0. ГИРА'!AK10 -> 0 | AN10: ='0. ГИРА'!AN10 -> 0 | AQ10: ='0. ГИРА'!AQ10 -> 0 | AT10: ='0. ГИРА'!AT10 -> 0 | AW10: ='0. ГИРА'!AW10 -> 0 | AZ10: ='0. ГИРА'!AZ10 -> 0 | BC10: ='0. ГИРА'!BC10 -> 0 | BF10: ='0. ГИРА'!BF10 -> 0 | BI10: ='0. ГИРА'!BI10 -> 0 | BL10: ='0. ГИРА'!BL10 -> 0 | BO10: ='0. ГИРА'!BO10 -> 0 | BR10: ='0. ГИРА'!BR10 -> 0 | BU10: ='0. ГИРА'!BU10 -> 0 | BX10: ='0. ГИРА'!BX10 -> 0 | CA10: ='0. ГИРА'!CA10 -> 0 | CD10: ='0. ГИРА'!CD10 -> 0
A11: Номер счетчика | B11: =Реестр!J5 -> 0 | C11: Экспл. Услуги от УК | F11: =E11-D11 -> 0 | I11: =H11-E11 -> 0 | J11: =J12*E3 -> 0 | L11: =K11-H11 -> 0 | M11: =M12*H3 -> 0 | O11: =N11-K11 -> 0 | P11: =P12*K3 -> 0 | R11: =Q11-N11 -> 0 | S11: =S12*N3 -> 0 | U11: =T11-Q11 -> 0 | V11: =V12*Q3 -> 0 | X11: =W11-T11 -> 0 | Y11: =Y12*T3 -> 0 | AA11: =Z11-W11 -> 0 | AB11: =AB12*W3 -> 0 | AD11: =AC11-Z11 -> 0 | AE11: =AE12*Z3 -> 0 | AG11: =AF11-AC11 -> 0 | AH11: =AH12*AC3 -> 0 | AJ11: =AI11-AF11 -> 0 | AK11: =AK12*AF3 -> 0 | AM11: =AL11-AI11 -> 0 | AN11: =AN12*AI3 -> 0 | AP11: =AO11-AL11 -> 0 | AQ11: =AQ12*AL3 -> 0 | AS11: =AR11-AO11 -> 0 | AT11: =AT12*AO3 -> 0 | AV11: =AU11-AR11 -> 0 | AW11: =AW12*AR3 -> 0 | AY11: =AX11-AU11 -> 0 | AZ11: =AZ12*AU3 -> 0 | BB11: =BA11-AX11 -> 0 | BC11: =BC12*AX3 -> 0 | BE11: =BD11-BA11 -> 0 | BF11: =BF12*BA3 -> 0 | BH11: =BG11-BD11 -> 0 | BI11: =BI12*BD3 -> 0 | BK11: =BJ11-BG11 -> 0 | BL11: =BL12*BG3 -> 0 | BN11: =BM11-BJ11 -> 0 | BO11: =BO12*BJ3 -> 0 | BQ11: =BP11-BM11 -> 0 | BR11: =BR12*BM3 -> 0 | BT11: =BS11-BP11 -> 0 | BU11: =BU12*BP3 -> 0 | BW11: =BV11-BS11 -> 0 | BX11: =BX12*BS3 -> 0 | BZ11: =BY11-BV11 -> 0 | CA11: =CA12*BV3 -> 0 | CC11: =CB11-BY11 -> 0 | CD11: =CD12*BY3 -> 0
C12: Экспл. Услуги от УК тариф | G12: ='0. ГИРА'!G12 -> 12142.857 | J12: ='0. ГИРА'!J12 -> 174.37686 | M12: ='0. ГИРА'!M12 -> 102.57462 | P12: ='0. ГИРА'!P12 -> 0 | S12: ='0. ГИРА'!S12 -> 0 | V12: ='0. ГИРА'!V12 -> 0 | Y12: ='0. ГИРА'!Y12 -> 0 | AB12: ='0. ГИРА'!AB12 -> 0 | AE12: ='0. ГИРА'!AE12 -> 0 | AH12: ='0. ГИРА'!AH12 -> 0 | AK12: ='0. ГИРА'!AK12 -> 0 | AN12: ='0. ГИРА'!AN12 -> 0 | AQ12: ='0. ГИРА'!AQ12 -> 0 | AT12: ='0. ГИРА'!AT12 -> 0 | AW12: ='0. ГИРА'!AW12 -> 0 | AZ12: ='0. ГИРА'!AZ12 -> 0 | BC12: ='0. ГИРА'!BC12 -> 0 | BF12: ='0. ГИРА'!BF12 -> 0 | BI12: ='0. ГИРА'!BI12 -> 0 | BL12: ='0. ГИРА'!BL12 -> 0 | BO12: ='0. ГИРА'!BO12 -> 0 | BR12: ='0. ГИРА'!BR12 -> 0 | BU12: ='0. ГИРА'!BU12 -> 0 | BX12: ='0. ГИРА'!BX12 -> 0 | CA12: ='0. ГИРА'!CA12 -> 0 | CD12: ='0. ГИРА'!CD12 -> 0

Sheet К36,00
A1: ИНН | B1: =Реестр!D6 -> 222 | C1: Месяц | D1: 45962 | E1: 45992 | F1: Потребл. | G1: 45962 | H1: 46023 | I1: Потребл. | J1: 45992 | K1: 46054 | L1: Потребл. | M1: 46023 | N1: 46082 | O1: Потребл. | P1: 46054 | Q1: 46113 | R1: Потребл. | S1: 46082 | T1: 46143 | U1: Потребл. | V1: 46113 | W1: 46174 | X1: Потребл. | Y1: 46143 | Z1: 46204 | AA1: Потребл. | AB1: 46174 | AC1: 46235 | AD1: Потребл. | AE1: 46204 | AF1: 46266 | AG1: Потребл. | AH1: 46235 | AI1: 46296 | AJ1: Потребл. | AK1: 46266 | AL1: 46327 | AM1: Потребл. | AN1: 46296 | AO1: 46357 | AP1: Потребл. | AQ1: 46327 | AR1: 46388 | AS1: Потребл. | AT1: 46357 | AU1: 46419 | AV1: Потребл. | AW1: 46388 | AX1: 46447 | AY1: Потребл. | AZ1: 46419 | BA1: 46478 | BB1: Потребл. | BC1: 46447 | BD1: 46508 | BE1: Потребл. | BF1: 46478 | BG1: 46539 | BH1: Потребл. | BI1: 46508 | BJ1: 46569 | BK1: Потребл. | BL1: 46539 | BM1: 46600 | BN1: Потребл. | BO1: 46569 | BP1: 46631 | BQ1: Потребл. | BR1: 46600 | BS1: 46661 | BT1: Потребл. | BU1: 46631 | BV1: 46692 | BW1: Потребл. | BX1: 46661 | BY1: 46722 | BZ1: Потребл. | CA1: 46692 | CB1: 46753 | CC1: Потребл. | CD1: 46722
A2: Кадастр | B2: =Реестр!B6 -> 1006:3090 | D2: знач. | E2: знач. | F2: знач. | G2: руб. | H2: знач. | I2: знач. | J2: руб. | K2: знач. | L2: знач. | M2: руб. | N2: знач. | O2: знач | P2: руб. | Q2: знач. | R2: знач. | S2: руб. | T2: знач. | U2: знач. | V2: руб. | W2: знач. | X2: знач. | Y2: руб. | Z2: знач. | AA2: знач. | AB2: руб. | AC2: знач. | AD2: знач. | AE2: руб. | AF2: знач. | AG2: знач. | AH2: руб. | AI2: знач. | AJ2: знач. | AK2: руб. | AL2: знач. | AM2: знач. | AN2: руб. | AO2: знач. | AP2: знач. | AQ2: руб. | AR2: знач. | AS2: знач. | AT2: руб. | AU2: знач. | AV2: знач. | AW2: руб. | AX2: знач. | AY2: знач. | AZ2: руб. | BA2: знач. | BB2: знач. | BC2: руб. | BD2: знач. | BE2: знач. | BF2: руб. | BG2: знач. | BH2: знач. | BI2: руб. | BJ2: знач. | BK2: знач. | BL2: руб. | BM2: знач. | BN2: знач. | BO2: руб. | BP2: знач. | BQ2: знач. | BR2: руб. | BS2: знач. | BT2: знач. | BU2: руб. | BV2: знач. | BW2: знач. | BX2: руб. | BY2: знач. | BZ2: знач. | CA2: руб. | CB2: знач. | CC2: знач. | CD2: руб.
A3: Арендатор | B3: =Реестр!F6 -> Галяутдинова Н.А. | C3: Электричество | F3: =E3-D3 -> 0 | G3: =F3*G4 -> 0 | I3: =H3-E3 -> 0 | J3: =I3*J4 -> 0 | L3: =K3-H3 -> 0 | M3: =L3*M4 -> 0 | O3: =N3-K3 -> 0 | P3: =O3*P4 -> 0 | R3: =Q3-N3 -> 0 | S3: =R3*S4 -> #DIV/0! | U3: =T3-Q3 -> 0 | V3: =U3*V4 -> #DIV/0! | X3: =W3-T3 -> 0 | Y3: =X3*Y4 -> #DIV/0! | AA3: =Z3-W3 -> 0 | AB3: =AA3*AB4 -> #DIV/0! | AD3: =AC3-Z3 -> 0 | AE3: =AD3*AE4 -> #DIV/0! | AG3: =AF3-AC3 -> 0 | AH3: =AG3*AH4 -> #DIV/0! | AJ3: =AI3-AF3 -> 0 | AK3: =AJ3*AK4 -> #DIV/0! | AM3: =AL3-AI3 -> 0 | AN3: =AM3*AN4 -> #DIV/0! | AP3: =AO3-AL3 -> 0 | AQ3: =AP3*AQ4 -> #DIV/0! | AS3: =AR3-AO3 -> 0 | AT3: =AS3*AT4 -> #DIV/0! | AV3: =AU3-AR3 -> 0 | AW3: =AV3*AW4 -> #DIV/0! | AY3: =AX3-AU3 -> 0 | AZ3: =AY3*AZ4 -> #DIV/0! | BB3: =BA3-AX3 -> 0 | BC3: =BB3*BC4 -> #DIV/0! | BE3: =BD3-BA3 -> 0 | BF3: =BE3*BF4 -> #DIV/0! | BH3: =BG3-BD3 -> 0 | BI3: =BH3*BI4 -> #DIV/0! | BK3: =BJ3-BG3 -> 0 | BL3: =BK3*BL4 -> #DIV/0! | BN3: =BM3-BJ3 -> 0 | BO3: =BN3*BO4 -> #DIV/0! | BQ3: =BP3-BM3 -> 0 | BR3: =BQ3*BR4 -> #DIV/0! | BT3: =BS3-BP3 -> 0 | BU3: =BT3*BU4 -> #DIV/0! | BW3: =BV3-BS3 -> 0 | BX3: =BW3*BX4 -> #DIV/0! | BZ3: =BY3-BV3 -> 0 | CA3: =BZ3*CA4 -> #DIV/0! | CC3: =CB3-BY3 -> 0 | CD3: =CC3*CD4 -> 0
A4: Площадь | B4: =Реестр!H6 -> 36 | C4: Электричество тариф | G4: ='0. ГИРА'!G4 -> 0.045000045 | J4: ='0. ГИРА'!J4 -> 0.1956526 | M4: ='0. ГИРА'!M4 -> 0.0091743119 | P4: ='0. ГИРА'!P4 -> 0 | S4: ='0. ГИРА'!S4 -> #DIV/0! | V4: ='0. ГИРА'!V4 -> #DIV/0! | Y4: ='0. ГИРА'!Y4 -> #DIV/0! | AB4: ='0. ГИРА'!AB4 -> #DIV/0! | AE4: ='0. ГИРА'!AE4 -> #DIV/0! | AH4: ='0. ГИРА'!AH4 -> #DIV/0! | AK4: ='0. ГИРА'!AK4 -> #DIV/0! | AN4: ='0. ГИРА'!AN4 -> #DIV/0! | AQ4: ='0. ГИРА'!AQ4 -> #DIV/0! | AT4: ='0. ГИРА'!AT4 -> #DIV/0! | AW4: ='0. ГИРА'!AW4 -> #DIV/0! | AZ4: ='0. ГИРА'!AZ4 -> #DIV/0! | BC4: ='0. ГИРА'!BC4 -> #DIV/0! | BF4: ='0. ГИРА'!BF4 -> #DIV/0! | BI4: ='0. ГИРА'!BI4 -> #DIV/0! | BL4: ='0. ГИРА'!BL4 -> #DIV/0! | BO4: ='0. ГИРА'!BO4 -> #DIV/0! | BR4: ='0. ГИРА'!BR4 -> #DIV/0! | BU4: ='0. ГИРА'!BU4 -> #DIV/0! | BX4: ='0. ГИРА'!BX4 -> #DIV/0! | CA4: ='0. ГИРА'!CA4 -> #DIV/0! | CD4: ='0. ГИРА'!CD4 -> 0
